Workbook

Sheet 4D CONTROL
D1: 4D PARAMETER AUDIT
B2: TRADE COMPANY | C2: CODE | D2: BIM COMPANY | E2: CODE | F2: ACC VERSION (R22) - META DO DIA 17/07 | G2: ACC FILE DATE (R22) - META DO DIA 17/07 | H2: ACC VERSION (R24) - META DO DIA 17/07 | I2: ACC FILE DATE (R24) - META DO DIA 17/07 | J2: VERSION | K2: VERSION DATE | L2: FILE NAME (R22) | M2: FILE NAME (R24) | N2: SHARED PARAMETER | O2: PARAMETER INFORMATION FILLED - TABLE | P2: ROUND 1 | Q2: ROUND 2 | R2: ROUND 3 | S2: ISSUES (ROUND 3) | T2: ROUND 4 | U2: ISSUES (ROUND 4) | V2: ROUND 5 | W2: ISSUES (ROUND 5) | X2: ROUND 6 | Y2: ISSUES (ROUND 6) | Z2: ROUND 7 | AA2: ISSUES (ROUND 7) | AB2: ROUND 8 | AC2: ISSUES (ROUND 8) | AD2: ROUND 9 | AE2: ISSUES (ROUND 9) | AF2: ROUND 10 | AG2: ISSUES (ROUND 10) | AH2: ROUND 11 | AI2: ISSUES (ROUND 11) | AJ2: ROUND 12 | AK2: ISSUES (ROUND 12) | AL2: ROUND 13 | AM2: ISSUES (ROUND 13) | AN2: ROUND 14 | AO2: ISSUES (ROUND 14) | AP2: ROUND 15 | AQ2: ISSUES (ROUND 15) | AR2: ROUND 16 | AS2: ISSUES (ROUND 16) | AT2: ROUND 17 | AU2: ISSUES (ROUND 17) | AV2: ROUND 18 | AW2: ISSUES (ROUND 18) | AX2: ROUND 19 | AY2: ISSUES (ROUND 19) | AZ2: ROUND 20 | BA2: ISSUES (ROUND 20) | BB2: ROUND 21 | BC2: ISSUES (ROUND 21) | BD2: ROUND 22 | BE2: ISSUES (ROUND 22) | BF2: ROUND 23 | BG2: ISSUES (ROUND 23) | BH2: ROUND 24 | BI2: ISSUES (ROUND 24) | BJ2: ROUND 25 | BK2: ISSUES (ROUND 25) | BL2: ROUND 26 | BM2: ISSUES (ROUND 26) | BN2: ROUND 27 | BO2: ISSUES (ROUND 27) | BP2: ROUND 28 | BQ2: ISSUES (ROUND 28) | BR2: ROUND 29 | BS2: ISSUES (ROUND 29) | BT2: ROUND 30 | BU2: ISSUES (ROUND 30) | BV2: ROUND 31 | BW2: ISSUES (ROUND 31) | BX2: ROUND 32 | BY2: ISSUES (ROUND 32) | BZ2: ROUND 33 | CA2: ISSUES (ROUND 33) | CB2: ROUND 34 | CC2: ISSUES (ROUND 34) | CD2: ROUND 35 | CE2: ISSUES (ROUND 35) | CF2: ROUND 36 | CG2: ISSUES (ROUND 36) | CH2: ROUND 37 | CI2: ISSUES (ROUND 37) | CJ2: ROUND 38 | CK2: ISSUES (ROUND 38) | CL2: ESTIMATED DELIVERY R38(DD/MM/AAAA) | CM2: RESUMO | CN2: RESPONSÁVEL DA ANÁLISE - R4 | CO2: HÁ ATUALIZAÇÃO NO ACC (ATUALIZADO XX/XX) | CP2: STATUS DAS ISSUES (ATUALIZADO) | CQ2: INTERAÇÃO NA ISSUE
A3: 28 | B3: BLACKBOX | C3: 1114 | D3: BLACKBOX | E3: 1114 | F3: =IFERROR(VLOOKUP(L3:L64,'R22 RELATÓRIO ACC'!B:F,5,FALSE),"NOT PUBLISHED") -> V15 | G3: =IFERROR(VLOOKUP(L3:L64,'R22 RELATÓRIO ACC'!B:P,15,FALSE),"NOT PUBLISHED") -> 27/04/2026 | H3: =IFERROR(VLOOKUP(M3:M64,'RELATÓRIO ACC'!B:F,5,FALSE),"NOT PUBLISHED") -> V3 | I3: =IFERROR(VLOOKUP(M3:M64,'RELATÓRIO ACC'!B:P,15,FALSE),"NOT PUBLISHED") -> 12/07/2026 | J3: V2 | K3: 29/06/2026 | L3: CPQ11-EPMS-DEVS-DATA-R22.rvt | M3: CPQ11-EPMS-DEVS-DATA-R24.rvt | N3: TRUE | O3: TRUE | P3: NOT FOUND | Q3: APPROVED | R3: APPROVED | S3: NO ISSUE | T3: APPROVED | U3: NO ISSUE | V3: PREVIOUSLY APPROVED | W3: NO ISSUE | X3: PREVIOUSLY APPROVED | Y3: NO ISSUE | Z3: PREVIOUSLY APPROVED | AA3: NO ISSUE | AB3: PREVIOUSLY APPROVED | AC3: NO ISSUE | AD3: PREVIOUSLY APPROVED | AE3: NO ISSUE | AF3: PREVIOUSLY APPROVED | AG3: NO ISSUE | AH3: PREVIOUSLY APPROVED | AI3: NO ISSUE | AJ3: PREVIOUSLY APPROVED | AK3: NO ISSUE | AL3: PREVIOUSLY APPROVED | AM3: NO ISSUE | AN3: PREVIOUSLY APPROVED | AO3: NO ISSUE | AP3: PREVIOUSLY APPROVED | AQ3: NO ISSUE | AR3: PREVIOUSLY APPROVED | AS3: NO ISSUE | AT3: PREVIOUSLY APPROVED | AU3: NO ISSUE | AV3: PREVIOUSLY APPROVED | AW3: NO ISSUE | AX3: PREVIOUSLY APPROVED | AY3: NO ISSUE | AZ3: PREVIOUSLY APPROVED | BA3: NO ISSUE | BB3: PREVIOUSLY APPROVED | BC3: NO ISSUE | BD3: PREVIOUSLY APPROVED | BE3: NO ISSUE | BF3: PREVIOUSLY APPROVED | BG3: NO ISSUE | BH3: PREVIOUSLY APPROVED | BI3: NO ISSUE | BJ3: PREVIOUSLY APPROVED | BK3: NO ISSUE | BL3: PREVIOUSLY APPROVED | BM3: NO ISSUE | BN3: PREVIOUSLY APPROVED | BO3: NO ISSUE | BP3: PREVIOUSLY APPROVED | BQ3: NO ISSUE | BR3: REPROVED | BS3: POSTED ISSUE | BT3: OUTDATED | BU3: OUTDATED | BV3: NEXT ROUND | BW3: NEXT ROUND | BX3: NEXT ROUND | BY3: NEXT ROUND | BZ3: REPROVED | CA3: POSTED ISSUE | CB3: OUTDATED | CC3: OUTDATED | CD3: OUTDATED | CE3: OUTDATED | CF3: NEXT ROUND | CG3: NEXT ROUND | CH3: REPROVED | CI3: POSTED ISSUE | CJ3: ANALYSING | CK3: ANALYSING | CL3: ANALYSING | CM3: =IF( OR(CL3="APPROVED", CL3="PREVIOUSLY APPROVED"), "APPROVED", "REPROVED" ) -> REPROVED | CP3: ABERTO | CQ3: COMENTÁRIO
A4: 31 | B4: MENDES HOLLER | C4: 1112 | D4: MENDES HOLLER | F4: =IFERROR(VLOOKUP(L4:L65,'R22 RELATÓRIO ACC'!B:F,5,FALSE),"NOT PUBLISHED") -> V11 | G4: =IFERROR(VLOOKUP(L4:L65,'R22 RELATÓRIO ACC'!B:P,15,FALSE),"NOT PUBLISHED") -> 08/05/2026 | H4: =IFERROR(VLOOKUP(M4:M65,'RELATÓRIO ACC'!B:F,5,FALSE),"NOT PUBLISHED") -> V3 | I4: =IFERROR(VLOOKUP(M4:M65,'RELATÓRIO ACC'!B:P,15,FALSE),"NOT PUBLISHED") -> 10/07/2026 | J4: V3 | K4: 10/07/2026 | L4: CPQ11-FALM-FALM-SITE-R22.rvt | M4: CPQ11-FALM-FALM-SITE-R24.rvt | N4: TRUE | O4: FALSE | P4: NOT FOUND | Q4: NOT FOUND | R4: REPROVED | S4: POSTED ISSUES | T4: OUTDATED | U4: OUTDATED | V4: OUTDATED | W4: OUTDATED | X4: OUTDATED | Y4: OUTDATED | Z4: OUTDATED | AA4: OUTDATED | AB4: OUTDATED | AC4: OUTDATED | AD4: OUTDATED | AE4: OUTDATED | AF4: OUTDATED | AG4: OUTDATED | AH4: OUTDATED | AI4: OUTDATED | AJ4: OUTDATED | AK4: OUTDATED | AL4: REPROVED | AM4: POSTED ISSUE | AN4: REPROVED | AO4: POSTED ISSUE | AP4: OUTDATED | AQ4: OUTDATED | AR4: REPROVED | AS4: POSTED ISSUE | AT4: REPROVED | AU4: POSTED ISSUE | AV4: OUTDATED | AW4: OUTDATED | AX4: OUTDATED | AY4: OUTDATED | AZ4: REPROVED | BA4: POSTED ISSUE | BB4: OUTDATED | BC4: OUTDATED | BD4: NEXT ROUND | BE4: NEXT ROUND | BF4: NEXT ROUND | BG4: NEXT ROUND | BH4: REPROVED | BI4: POSTED ISSUE | BJ4: REPROVED | BK4: POSTED ISSUE | BL4: OUTDATED | BM4: OUTDATED | BN4: OUTDATED | BO4: OUTDATED | BP4: OUTDATED | BQ4: OUTDATED | BR4: NEXT ROUND | BS4: NEXT ROUND | BT4: REPROVED | BU4: POSTED ISSUE | BV4: NEXT ROUND | BW4: NEXT ROUND | BX4: IMPROPER | BY4: IMPROPER | BZ4: OUTDATED | CA4: OUTDATED | CB4: OUTDATED | CC4: OUTDATED | CD4: NEXT ROUND | CE4: NEXT ROUND | CF4: REPROVED | CG4: POSTED ISSUE | CH4: OUTDATED | CI4: OUTDATED | CJ4: REPROVED | CK4: POSTED ISSUE | CL4: REPROVED | CM4: =IF( OR(CL4="APPROVED", CL4="PREVIOUSLY APPROVED"), "APPROVED", "REPROVED" ) -> REPROVED | CP4: ABERTO | CQ4: SEM INTERAÇÃO
A5: 30 | B5: MENDES HOLLER | C5: 1112 | D5: MENDES HOLLER | E5: 1112 | F5: =IFERROR(VLOOKUP(L5:L66,'R22 RELATÓRIO ACC'!B:F,5,FALSE),"NOT PUBLISHED") -> V24 | G5: =IFERROR(VLOOKUP(L5:L66,'R22 RELATÓRIO ACC'!B:P,15,FALSE),"NOT PUBLISHED") -> 15/05/2026 | H5: =IFERROR(VLOOKUP(M5:M66,'RELATÓRIO ACC'!B:F,5,FALSE),"NOT PUBLISHED") -> V2 | I5: =IFERROR(VLOOKUP(M5:M66,'RELATÓRIO ACC'!B:P,15,FALSE),"NOT PUBLISHED") -> 06/07/2026 | J5: V1 | K5: 46161 | L5: CPQ11-FALM-FALM-DATA-R22.rvt | M5: CPQ11-FALM-FALM-DATA-R24.rvt | N5: TRUE | O5: NON-RECIVED TABLE | P5: NOT FOUND | Q5: REPROVED | R5: REPROVED | S5: POSTED ISSUES | T5: REPROVED | U5: POSTED ISSUES | V5: OUTDATED | W5: OUTDATED | X5: OUTDATED | Y5: OUTDATED | Z5: OUTDATED | AA5: OUTDATED | AB5: OUTDATED | AC5: OUTDATED | AD5: OUTDATED | AE5: OUTDATED | AF5: OUTDATED | AG5: OUTDATED | AH5: REPROVED | AI5: POSTED ISSUE | AJ5: OUTDATED | AK5: OUTDATED | AL5: REPROVED | AM5: POSTED ISSUE | AN5: REPROVED | AO5: POSTED ISSUE | AP5: OUTDATED | AQ5: OUTDATED | AR5: OUTDATED | AS5: NO ISSUE | AT5: REPROVED | AU5: POSTED ISSUE | AV5: OUTDATED | AW5: OUTDATED | AX5: OUTDATED | AY5: OUTDATED | AZ5: REPROVED | BA5: POSTED ISSUE | BB5: OUTDATED | BC5: OUTDATED | BD5: NEXT ROUND | BE5: NEXT ROUND | BF5: REPROVED | BG5: POSTED ISSUE | BH5: OUTDATED | BI5: OUTDATED | BJ5: REPROVED | BK5: POSTED ISSUE | BL5: NEXT ROUND | BM5: NEXT ROUND | BN5: REPROVED | BO5: POSTED ISSUE | BP5: NEXT ROUND | BQ5: NEXT ROUND | BR5: REPROVED | BS5: POSTED ISSUE | BT5: REPROVED | BU5: POSTED ISSUE | BV5: OUTDATED | BW5: OUTDATED | BX5: OUTDATED | BY5: OUTDATED | BZ5: OUTDATED | CA5: OUTDATED | CB5: OUTDATED | CC5: OUTDATED | CD5: OUTDATED | CE5: OUTDATED | CF5: OUTDATED | CG5: OUTDATED | CH5: OUTDATED | CI5: OUTDATED | CJ5: ANALYSING | CK5: ANALYSING | CL5: ANALYSING | CM5: =IF( OR(CL5="APPROVED", CL5="PREVIOUSLY APPROVED"), "APPROVED", "REPROVED" ) -> REPROVED | CP5: ABERTO | CQ5: NA
A6: 10 | B6: IDEIA DRYWALL | D6: FCH | E6: 1126 | F6: =IFERROR(VLOOKUP(L6:L67,'R22 RELATÓRIO ACC'!B:F,5,FALSE),"NOT PUBLISHED") -> V24 | G6: =IFERROR(VLOOKUP(L6:L67,'R22 RELATÓRIO ACC'!B:P,15,FALSE),"NOT PUBLISHED") -> 07/04/2026 | H6: =IFERROR(VLOOKUP(M6:M67,'RELATÓRIO ACC'!B:F,5,FALSE),"NOT PUBLISHED") -> V2 | I6: =IFERROR(VLOOKUP(M6:M67,'RELATÓRIO ACC'!B:P,15,FALSE),"NOT PUBLISHED") -> 27/05/2026 | J6: V23 | K6: 46086 | L6: CPQ11-ARCH-PART-C12A-R22.rvt | M6: CPQ11-ARCH-PART-C12A-R24.rvt | N6: TRUE | O6: NON-RECIVED TABLE | P6: NOT FOUND | Q6: REPROVED | R6: REPROVED | S6: POSTED ISSUES | T6: REPROVED | U6: POSTED ISSUES | V6: OUTDATED | W6: OUTDATED | X6: REPROVED | Y6: POSTED ISSUES | Z6: OUTDATED | AA6: OUTDATED | AB6: REPROVED | AC6: POSTED ISSUES | AD6: OUTDATED | AE6: OUTDATED | AF6: REPROVED | AG6: POSTED ISSUES | AH6: REPROVED | AI6: POSTED ISSUE | AJ6: OUTDATED | AK6: OUTDATED | AL6: REPROVED | AM6: POSTED ISSUE | AN6: REPROVED | AO6: POSTED ISSUE | AP6: REPROVED | AQ6: POSTED ISSUE | AR6: REPROVED | AS6: POSTED ISSUE | AT6: REPROVED | AU6: POSTED ISSUE | AV6: REPROVED | AW6: POSTED ISSUE | AX6: APPROVED | AY6: NO ISSUE | AZ6: PREVIOUSLY APPROVED | BA6: NO ISSUE | BB6: PREVIOUSLY APPROVED | BC6: NO ISSUE | BD6: PREVIOUSLY APPROVED | BE6: NO ISSUE | BF6: PREVIOUSLY APPROVED | BG6: NO ISSUE | BH6: PREVIOUSLY APPROVED | BI6: NO ISSUE | BJ6: PREVIOUSLY APPROVED | BK6: NO ISSUE | BL6: PREVIOUSLY APPROVED | BM6: NO ISSUE | BN6: PREVIOUSLY APPROVED | BO6: NO ISSUE | BP6: PREVIOUSLY APPROVED | BQ6: NO ISSUE | BR6: PREVIOUSLY APPROVED | BS6: NO ISSUE | BT6: PREVIOUSLY APPROVED | BU6: NO ISSUE | BV6: PREVIOUSLY APPROVED | BW6: NO ISSUE | BX6: PREVIOUSLY APPROVED | BY6: NO ISSUE | BZ6: PREVIOUSLY APPROVED | CA6: NO ISSUE | CB6: PREVIOUSLY APPROVED | CC6: NO ISSUE | CD6: PREVIOUSLY APPROVED | CE6: NO ISSUE | CF6: PREVIOUSLY APPROVED | CG6: NO ISSUE | CH6: PREVIOUSLY APPROVED | CI6: NO ISSUE | CJ6: REPROVED | CK6: POSTED ISSUE | CL6: REPROVED | CM6: =IF( OR(CL6="APPROVED", CL6="PREVIOUSLY APPROVED"), "APPROVED", "REPROVED" ) -> REPROVED | CP6: FECHADO | CQ6: NA
A7: 26 | B7: MENDES HOLLER | D7: PGMAK | E7: 1129 | F7: =IFERROR(VLOOKUP(L7:L68,'R22 RELATÓRIO ACC'!B:F,5,FALSE),"NOT PUBLISHED") -> V52 | G7: =IFERROR(VLOOKUP(L7:L68,'R22 RELATÓRIO ACC'!B:P,15,FALSE),"NOT PUBLISHED") -> 30/04/2026 | H7: =IFERROR(VLOOKUP(M7:M68,'RELATÓRIO ACC'!B:F,5,FALSE),"NOT PUBLISHED") -> V4 | I7: =IFERROR(VLOOKUP(M7:M68,'RELATÓRIO ACC'!B:P,15,FALSE),"NOT PUBLISHED") -> 06/07/2026 | J7: V4 | K7: 06/07/2026 | L7: CPQ11-ELEC-ELEC-DATA-R22.rvt | M7: CPQ11-ELEC-ELEC-DATA-R24.rvt | N7: TRUE | O7: TRUE | P7: NOT FOUND | Q7: REPROVED | R7: REPROVED | S7: POSTED ISSUES | T7: REPROVED | U7: POSTED ISSUES | V7: REPROVED | W7: POSTED ISSUES | X7: OUTDATED | Y7: OUTDATED | Z7: REPROVED | AA7: POSTED ISSUES | AB7: OUTDATED | AC7: OUTDATED | AD7: REPROVED | AE7: POSTED ISSUES | AF7: REPROVED | AG7: POSTED ISSUES | AH7: NEXT ROUND | AI7: NEXT ROUND | AJ7: REPROVED | AK7: POSTED ISSUE | AL7: REPROVED | AM7: POSTED ISSUE | AN7: REPROVED | AO7: POSTED ISSUE | AP7: OUTDATED | AQ7: OUTDATED | AR7: OUTDATED | AS7: OUTDATED | AT7: REPROVED | AU7: POSTED ISSUE | AV7: REPROVED | AW7: POSTED ISSUE | AX7: OUTDATED | AY7: OUTDATED | AZ7: REPROVED | BA7: POSTED ISSUE | BB7: OUTDATED | BC7: OUTDATED | BD7: OUTDATED | BE7: OUTDATED | BF7: NEXT ROUND | BG7: NEXT ROUND | BH7: REPROVED | BI7: POSTED ISSUE | BJ7: REPROVED | BK7: POSTED ISSUE | BL7: OUTDATED | BM7: OUTDATED | BN7: OUTDATED | BO7: OUTDATED | BP7: NEXT ROUND | BQ7: NEXT ROUND | BR7: REPROVED | BS7: POSTED ISSUE | BT7: OUTDATED | BU7: OUTDATED | BV7: NEXT ROUND | BW7: NEXT ROUND | BX7: IMPROPER | BY7: IMPROPER | BZ7: OUTDATED | CA7: OUTDATED | CB7: REPROVED | CC7: POSTED ISSUE | CD7: OUTDATED | CE7: OUTDATED | CF7: OUTDATED | CG7: OUTDATED | CH7: NEXT ROUND | CI7: NEXT ROUND | CJ7: REPROVED | CK7: POSTED ISSUE | CL7: REPROVED | CM7: =IF( OR(CL7="APPROVED", CL7="PREVIOUSLY APPROVED"), "APPROVED", "REPROVED" ) -> REPROVED | CO7: FALSE | CP7: ABERTO | CQ7: COMENTÁRIO
A8: 66 | B8: MENDES HOLLER | C8: 1112 | D8: MENDES HOLLER | F8: =IFERROR(VLOOKUP(L8:L69,'R22 RELATÓRIO ACC'!B:F,5,FALSE),"NOT PUBLISHED") -> V13 | G8: =IFERROR(VLOOKUP(L8:L69,'R22 RELATÓRIO ACC'!B:P,15,FALSE),"NOT PUBLISHED") -> 12/05/2026 | H8: =IFERROR(VLOOKUP(M8:M69,'RELATÓRIO ACC'!B:F,5,FALSE),"NOT PUBLISHED") -> V5 | I8: =IFERROR(VLOOKUP(M8:M69,'RELATÓRIO ACC'!B:P,15,FALSE),"NOT PUBLISHED") -> 13/07/2026 | J8: V5 | K8: 46216 | L8: CPQ11-ELEC-SPDA-DATA-R22.rvt | M8: CPQ11-ELEC-SPDA-DATA-R24.rvt | N8: TRUE | O8: FALSE | P8: NOT FOUND | Q8: NOT FOUND | R8: NOT FOUND | S8: NOT FOUND | T8: NOT FOUND | U8: NOT FOUND | V8: NOT FOUND | W8: NOT FOUND | X8: NOT FOUND | Y8: NOT FOUND | Z8: NOT FOUND | AA8: NOT FOUND | AB8: REPROVED | AC8: POSTED ISSUES | AD8: REPROVED | AE8: POSTED ISSUES | AF8: REPROVED | AG8: POSTED ISSUES | AH8: OUTDATED | AI8: OUTDATED | AJ8: OUTDATED | AK8: OUTDATED | AL8: REPROVED | AM8: POSTED ISSUE | AN8: REPROVED | AO8: POSTED ISSUE | AP8: OUTDATED | AQ8: OUTDATED | AR8: REPROVED | AS8: POSTED ISSUE | AT8: OUTDATED | AU8: OUTDATED | AV8: REPROVED | AW8: POSTED ISSUE | AX8: OUTDATED | AY8: OUTDATED | AZ8: REPROVED | BA8: POSTED ISSUE | BB8: OUTDATED | BC8: OUTDATED | BD8: OUTDATED | BE8: OUTDATED | BF8: NEXT ROUND | BG8: NEXT ROUND | BH8: IMPROPER | BI8: POSTED ISSUE | BJ8: OUTDATED | BK8: OUTDATED | BL8: REPROVED | BM8: POSTED ISSUE | BN8: OUTDATED | BO8: OUTDATED | BP8: NEXT ROUND | BQ8: NEXT ROUND | BR8: REPROVED | BS8: POSTED ISSUE | BT8: OUTDATED | BU8: OUTDATED | BV8: NEXT ROUND | BW8: NEXT ROUND | BX8: REPROVED | BY8: POSTED ISSUE | BZ8: OUTDATED | CA8: OUTDATED | CB8: REPROVED | CC8: POSTED ISSUE | CD8: OUTDATED | CE8: OUTDATED | CF8: REPROVED | CG8: POSTED ISSUE | CH8: NEXT ROUND | CI8: NEXT ROUND | CJ8: REPROVED | CK8: POSTED ISSUE | CL8: REPROVED | CM8: =IF( OR(CL8="APPROVED", CL8="PREVIOUSLY APPROVED"), "APPROVED", "REPROVED" ) -> REPROVED | CP8: ABERTO | CQ8: COMENTÁRIO
A9: 3 | B9: SERCOP | D9: ARE ARQUITETURA | F9: =IFERROR(VLOOKUP(L9:L70,'R22 RELATÓRIO ACC'!B:F,5,FALSE),"NOT PUBLISHED") -> V12 | G9: =IFERROR(VLOOKUP(L9:L70,'R22 RELATÓRIO ACC'!B:P,15,FALSE),"NOT PUBLISHED") -> 05/05/2026 | H9: =IFERROR(VLOOKUP(M9:M70,'RELATÓRIO ACC'!B:F,5,FALSE),"NOT PUBLISHED") -> V5 | I9: =IFERROR(VLOOKUP(M9:M70,'RELATÓRIO ACC'!B:P,15,FALSE),"NOT PUBLISHED") -> 22/06/2026 | J9: V5 | K9: 22/06/2026 | L9: CPQ11-ARCH-METL-SITE-R22.rvt | M9: CPQ11-ARCH-METL-SITE-R24.rvt | N9: TRUE | O9: FALSE | P9: NOT FOUND | Q9: NOT FOUND | R9: NOT FOUND | S9: NOT FOUND | T9: NOT FOUND | U9: NOT FOUND | V9: NOT FOUND | W9: NOT FOUND | X9: APPROVED | Y9: NO ISSUE | Z9: PREVIOUSLY APPROVED | AA9: NO ISSUE | AB9: PREVIOUSLY APPROVED | AC9: NO ISSUE | AD9: PREVIOUSLY APPROVED | AE9: NO ISSUE | AF9: PREVIOUSLY APPROVED | AG9: NO ISSUE | AH9: PREVIOUSLY APPROVED | AI9: NO ISSUE | AJ9: PREVIOUSLY APPROVED | AK9: NO ISSUE | AL9: PREVIOUSLY APPROVED | AM9: NO ISSUE | AN9: PREVIOUSLY APPROVED | AO9: NO ISSUE | AP9: PREVIOUSLY APPROVED | AQ9: NO ISSUE | AR9: PREVIOUSLY APPROVED | AS9: NO ISSUE | AT9: PREVIOUSLY APPROVED | AU9: NO ISSUE | AV9: PREVIOUSLY APPROVED | AW9: NO ISSUE | AX9: PREVIOUSLY APPROVED | AY9: NO ISSUE | AZ9: PREVIOUSLY APPROVED | BA9: NO ISSUE | BB9: PREVIOUSLY APPROVED | BC9: NO ISSUE | BD9: PREVIOUSLY APPROVED | BE9: NO ISSUE | BF9: PREVIOUSLY APPROVED | BG9: NO ISSUE | BH9: PREVIOUSLY APPROVED | BI9: NO ISSUE | BJ9: PREVIOUSLY APPROVED | BK9: NO ISSUE | BL9: PREVIOUSLY APPROVED | BM9: NO ISSUE | BN9: PREVIOUSLY APPROVED | BO9: NO ISSUE | BP9: PREVIOUSLY APPROVED | BQ9: NO ISSUE | BR9: PREVIOUSLY APPROVED | BS9: NO ISSUE | BT9: PREVIOUSLY APPROVED | BU9: NO ISSUE | BV9: PREVIOUSLY APPROVED | BW9: NO ISSUE | BX9: PREVIOUSLY APPROVED | BY9: NO ISSUE | BZ9: PREVIOUSLY APPROVED | CA9: NO ISSUE | CB9: PREVIOUSLY APPROVED | CC9: NO ISSUE | CD9: PREVIOUSLY APPROVED | CE9: NO ISSUE | CF9: PREVIOUSLY APPROVED | CG9: NO ISSUE | CH9: PREVIOUSLY APPROVED | CI9: NO ISSUE | CJ9: REPROVED | CK9: POSTED ISSUE | CL9: REPROVED | CM9: =IF( OR(CL9="APPROVED", CL9="PREVIOUSLY APPROVED"), "APPROVED", "REPROVED" ) -> REPROVED | CP9: ABERTO | CQ9: SEM INTERAÇÃO, COMENTÁRIO
A10: 32 | B10: MENDES HOLLER | C10: 1112 | D10: MENDES HOLLER | E10: 1112 | F10: =IFERROR(VLOOKUP(L10:L71,'R22 RELATÓRIO ACC'!B:F,5,FALSE),"NOT PUBLISHED") -> V17 | G10: =IFERROR(VLOOKUP(L10:L71,'R22 RELATÓRIO ACC'!B:P,15,FALSE),"NOT PUBLISHED") -> 14/05/2026 | H10: =IFERROR(VLOOKUP(M10:M71,'RELATÓRIO ACC'!B:F,5,FALSE),"NOT PUBLISHED") -> V4 | I10: =IFERROR(VLOOKUP(M10:M71,'RELATÓRIO ACC'!B:P,15,FALSE),"NOT PUBLISHED") -> 25/06/2026 | J10: V4 | K10: 25/06/2026 | L10: CPQ11-FPRT-FPRT-DATA-R22.rvt | M10: CPQ11-FPRT-FPRT-DATA-R24.rvt | N10: TRUE | O10: TRUE | P10: NOT FOUND | Q10: REPROVED | R10: REPROVED | S10: POSTED ISSUES | T10: REPROVED | U10: POSTED ISSUES | V10: OUTDATED | W10: OUTDATED | X10: OUTDATED | Y10: OUTDATED | Z10: OUTDATED | AA10: OUTDATED | AB10: OUTDATED | AC10: OUTDATED | AD10: OUTDATED | AE10: OUTDATED | AF10: OUTDATED | AG10: OUTDATED | AH10: REPROVED | AI10: POSTED ISSUE | AJ10: OUTDATED | AK10: OUTDATED | AL10: REPROVED | AM10: POSTED ISSUE | AN10: REPROVED | AO10: POSTED ISSUE | AP10: OUTDATED | AQ10: OUTDATED | AR10: OUTDATED | AS10: NO ISSUE | AT10: REPROVED | AU10: POSTED ISSUE | AV10: OUTDATED | AW10: OUTDATED | AX10: REPROVED | AY10: POSTED ISSUE | AZ10: OUTDATED | BA10: OUTDATED | BB10: OUTDATED | BC10: OUTDATED | BD10: OUTDATED | BE10: OUTDATED | BF10: NEXT ROUND | BG10: NEXT ROUND | BH10: REPROVED | BI10: POSTED ISSUE | BJ10: OUTDATED | BK10: OUTDATED | BL10: NEXT ROUND | BM10: NEXT ROUND | BN10: REPROVED | BO10: POSTED ISSUE | BP10: IMPROPER | BQ10: IMPROPER | BR10: OUTDATED | BS10: OUTDATED | BT10: REPROVED | BU10: POSTED ISSUE | BV10: NEXT ROUND | BW10: NEXT ROUND | BX10: IMPROPER | BY10: IMPROPER | BZ10: OUTDATED | CA10: OUTDATED | CB10: OUTDATED | CC10: OUTDATED | CD10: REPROVED | CE10: POSTED ISSUE | CF10: IMPROPER | CG10: IMPROPER | CH10: OUTDATED | CI10: OUTDATED | CJ10: OUTDATED | CK10: OUTDATED | CL10: OUTDATED | CM10: =IF( OR(CL10="APPROVED", CL10="PREVIOUSLY APPROVED"), "APPROVED", "REPROVED" ) -> REPROVED | CO10: FALSE | CP10: ABERTO | CQ10: COMENTÁRIO
A11: 68 | B11: IDEIA DRYWALL | D11: T2B | F11: =IFERROR(VLOOKUP(L11:L72,'R22 RELATÓRIO ACC'!B:F,5,FALSE),"NOT PUBLISHED") -> V4 | G11: =IFERROR(VLOOKUP(L11:L72,'R22 RELATÓRIO ACC'!B:P,15,FALSE),"NOT PUBLISHED") -> 29/04/2026 | H11: =IFERROR(VLOOKUP(M11:M72,'RELATÓRIO ACC'!B:F,5,FALSE),"NOT PUBLISHED") -> V1 | I11: =IFERROR(VLOOKUP(M11:M72,'RELATÓRIO ACC'!B:P,15,FALSE),"NOT PUBLISHED") -> 04/06/2026 | J11: V1 | K11: 04/06/2026 | L11: CPQ11-ARCH-CEIL-DATA-R22.rvt | M11: CPQ11-ARCH-CEIL-DATA-R24.rvt | N11: TRUE | O11: TRUE | P11: NOT FOUND | Q11: NOT FOUND | R11: NOT FOUND | S11: NOT FOUND | T11: NOT FOUND | U11: NOT FOUND | V11: NOT FOUND | W11: NOT FOUND | X11: NOT FOUND | Y11: NOT FOUND | Z11: NOT FOUND | AA11: NOT FOUND | AB11: NOT FOUND | AC11: NOT FOUND | AD11: NOT FOUND | AE11: NOT FOUND | AF11: NOT FOUND | AG11: NOT FOUND | AH11: REPROVED | AI11: POSTED ISSUE | AJ11: OUTDATED | AK11: OUTDATED | AL11: OUTDATED | AM11: OUTDATED | AN11: OUTDATED | AO11: OUTDATED | AP11: OUTDATED | AQ11: OUTDATED | AR11: OUTDATED | AS11: OUTDATED | AT11: OUTDATED | AU11: OUTDATED | AV11: OUTDATED | AW11: OUTDATED | AX11: REPROVED | AY11: POSTED ISSUE | AZ11: OUTDATED | BA11: OUTDATED | BB11: OUTDATED | BC11: OUTDATED | BD11: OUTDATED | BE11: OUTDATED | BF11: NEXT ROUND | BG11: NEXT ROUND | BH11: IMPROPER | BI11: POSTED ISSUE | BJ11: OUTDATED | BK11: OUTDATED | BL11: OUTDATED | BM11: OUTDATED | BN11: OUTDATED | BO11: OUTDATED | BP11: REPROVED | BQ11: POSTED ISSUE | BR11: OUTDATED | BS11: OUTDATED | BT11: OUTDATED | BU11: OUTDATED | BV11: OUTDATED | BW11: OUTDATED | BX11: OUTDATED | BY11: OUTDATED | BZ11: IMPROPER | CA11: IMPROPER | CB11: OUTDATED | CC11: OUTDATED | CD11: OUTDATED | CE11: OUTDATED | CF11: OUTDATED | CG11: OUTDATED | CH11: OUTDATED | CI11: OUTDATED | CJ11: OUTDATED | CK11: OUTDATED | CL11: OUTDATED | CM11: =IF( OR(CL11="APPROVED", CL11="PREVIOUSLY APPROVED"), "APPROVED", "REPROVED" ) -> REPROVED | CP11: ABERTO | CQ11: COMENTÁRIO
A12: 70 | B12: IDEIA DRYWALL | D12: T2B | F12: =IFERROR(VLOOKUP(L12:L73,'R22 RELATÓRIO ACC'!B:F,5,FALSE),"NOT PUBLISHED") -> V2 | G12: =IFERROR(VLOOKUP(L12:L73,'R22 RELATÓRIO ACC'!B:P,15,FALSE),"NOT PUBLISHED") -> 29/04/2026 | H12: =IFERROR(VLOOKUP(M12:M73,'RELATÓRIO ACC'!B:F,5,FALSE),"NOT PUBLISHED") -> V1 | I12: =IFERROR(VLOOKUP(M12:M73,'RELATÓRIO ACC'!B:P,15,FALSE),"NOT PUBLISHED") -> 12/06/2026 | J12: V1 | K12: 46185 | L12: CPQ11-ARCH-CEIL-SITE-R22.rvt | M12: CPQ11-ARCH-CEIL-SITE-R24.rvt | N12: TRUE | O12: TRUE | P12: NOT FOUND | Q12: NOT FOUND | R12: NOT FOUND | S12: NOT FOUND | T12: NOT FOUND | U12: NOT FOUND | V12: NOT FOUND | W12: NOT FOUND | X12: NOT FOUND | Y12: NOT FOUND | Z12: NOT FOUND | AA12: NOT FOUND | AB12: NOT FOUND | AC12: NOT FOUND | AD12: NOT FOUND | AE12: NOT FOUND | AF12: NOT FOUND | AG12: NOT FOUND | AH12: APPROVED | AI12: APPROVED | AJ12: PREVIOUSLY APPROVED | AK12: PREVIOUSLY APPROVED | AL12: PREVIOUSLY APPROVED | AM12: PREVIOUSLY APPROVED | AN12: PREVIOUSLY APPROVED | AO12: NO ISSUE | AP12: PREVIOUSLY APPROVED | AQ12: NO ISSUE | AR12: PREVIOUSLY APPROVED | AS12: NO ISSUE | AT12: PREVIOUSLY APPROVED | AU12: NO ISSUE | AV12: PREVIOUSLY APPROVED | AW12: NO ISSUE | AX12: PREVIOUSLY APPROVED | AY12: NO ISSUE | AZ12: PREVIOUSLY APPROVED | BA12: NO ISSUE | BB12: PREVIOUSLY APPROVED | BC12: NO ISSUE | BD12: PREVIOUSLY APPROVED | BE12: NO ISSUE | BF12: PREVIOUSLY APPROVED | BG12: NO ISSUE | BH12: PREVIOUSLY APPROVED | BI12: NO ISSUE | BJ12: PREVIOUSLY APPROVED | BK12: NO ISSUE | BL12: PREVIOUSLY APPROVED | BM12: NO ISSUE | BN12: PREVIOUSLY APPROVED | BO12: NO ISSUE | BP12: REPROVED | BQ12: POSTED ISSUE | BR12: OUTDATED | BS12: OUTDATED | BT12: OUTDATED | BU12: OUTDATED | BV12: OUTDATED | BW12: OUTDATED | BX12: OUTDATED | BY12: OUTDATED | BZ12: IMPROPER | CA12: IMPROPER | CB12: OUTDATED | CC12: OUTDATED | CD12: OUTDATED | CE12: OUTDATED | CF12: OUTDATED | CG12: OUTDATED | CH12: OUTDATED | CI12: OUTDATED | CJ12: OUTDATED | CK12: OUTDATED | CL12: OUTDATED | CM12: =IF( OR(CL12="APPROVED", CL12="PREVIOUSLY APPROVED"), "APPROVED", "REPROVED" ) -> REPROVED | CP12: SEM ISSUE | CQ12: NA
A13: 72 | B13: FM SECURITY | D13: FM SECURITY | F13: =IFERROR(VLOOKUP(L13:L74,'R22 RELATÓRIO ACC'!B:F,5,FALSE),"NOT PUBLISHED") -> V2 | G13: =IFERROR(VLOOKUP(L13:L74,'R22 RELATÓRIO ACC'!B:P,15,FALSE),"NOT PUBLISHED") -> 07/05/2026 | H13: =IFERROR(VLOOKUP(M13:M74,'RELATÓRIO ACC'!B:F,5,FALSE),"NOT PUBLISHED") -> V5 | I13: =IFERROR(VLOOKUP(M13:M74,'RELATÓRIO ACC'!B:P,15,FALSE),"NOT PUBLISHED") -> 08/07/2026 | J13: V4 | K13: 02/07/2026 | L13: CPQ11-SCTY-GATE-SITE-R24.rvt | M13: CPQ11-SCTY-GATE-SITE-R24.rvt | N13: TRUE | O13: TRUE | P13: NOT FOUND | Q13: NOT FOUND | R13: NOT FOUND | S13: NOT FOUND | T13: NOT FOUND | U13: NOT FOUND | V13: NOT FOUND | W13: NOT FOUND | X13: NOT FOUND | Y13: NOT FOUND | Z13: NOT FOUND | AA13: NOT FOUND | AB13: NOT FOUND | AC13: NOT FOUND | AD13: NOT FOUND | AE13: NOT FOUND | AF13: NOT FOUND | AG13: NOT FOUND | AH13: NOT FOUND | AI13: NOT FOUND | AJ13: NOT FOUND | AK13: NOT FOUND | AL13: NOT FOUND | AM13: NOT FOUND | AN13: NOT FOUND | AO13: NOT FOUND | AP13: NOT FOUND | AQ13: NOT FOUND | AR13: NOT FOUND | AS13: NOT FOUND | AT13: NOT FOUND | AU13: NOT FOUND | AV13: NOT FOUND | AW13: NOT FOUND | AX13: NOT FOUND | AY13: NOT FOUND | AZ13: NOT FOUND | BA13: NOT FOUND | BB13: NOT FOUND | BC13: NOT FOUND | BD13: NOT FOUND | BE13: NOT FOUND | BF13: NOT FOUND | BG13: NOT FOUND | BH13: NOT FOUND | BI13: NOT FOUND | BJ13: NOT FOUND | BK13: NOT FOUND | BL13: REPROVED | BM13: POSTED ISSUE | BN13: OUTDATED | BO13: OUTDATED | BP13: OUTDATED | BQ13: OUTDATED | BR13: NEXT ROUND | BS13: NEXT ROUND | BT13: IMPROPER | BU13: IMPROPER | BV13: NEXT ROUND | BW13: NEXT ROUND | BX13: NEXT ROUND | BY13: NEXT ROUND | BZ13: NEXT ROUND | CA13: NEXT ROUND | CB13: REPROVED | CC13: POSTED ISSUE | CD13: REPROVED | CE13: POSTED ISSUE | CF13: NEXT ROUND | CG13: NEXT ROUND | CH13: APPROVED | CI13: NO ISSUE | CJ13: PREVIOUSLY APPROVED | CK13: NO ISSUE | CL13: PREVIOUSLY APPROVED | CM13: =IF( OR(CL13="APPROVED", CL13="PREVIOUSLY APPROVED"), "APPROVED", "REPROVED" ) -> APPROVED | CO13: FALSE
A14: 74 | B14: MODAX | D14: MODAX | F14: =IFERROR(VLOOKUP(L14:L75,'R22 RELATÓRIO ACC'!B:F,5,FALSE),"NOT PUBLISHED") -> V1 | G14: =IFERROR(VLOOKUP(L14:L75,'R22 RELATÓRIO ACC'!B:P,15,FALSE),"NOT PUBLISHED") -> 05/05/2026 | H14: =IFERROR(VLOOKUP(M14:M75,'RELATÓRIO ACC'!B:F,5,FALSE),"NOT PUBLISHED") -> V3 | I14: =IFERROR(VLOOKUP(M14:M75,'RELATÓRIO ACC'!B:P,15,FALSE),"NOT PUBLISHED") -> 20/06/2026 | J14: V2 | K14: 26/05/2026 | L14: CPQ11-STRC-FLOO-DATA-R22.rvt | M14: CPQ11-STRC-FLOO-DATA-R24.rvt | N14: TRUE | O14: FALSE | P14: NOT FOUND | Q14: NOT FOUND | R14: NOT FOUND | S14: NOT FOUND | T14: NOT FOUND | U14: NOT FOUND | V14: NOT FOUND | W14: NOT FOUND | X14: NOT FOUND | Y14: NOT FOUND | Z14: NOT FOUND | AA14: NOT FOUND | AB14: NOT FOUND | AC14: NOT FOUND | AD14: NOT FOUND | AE14: NOT FOUND | AF14: NOT FOUND | AG14: NOT FOUND | AH14: NOT FOUND | AI14: NOT FOUND | AJ14: NOT FOUND | AK14: NOT FOUND | AL14: NOT FOUND | AM14: NOT FOUND | AN14: NOT FOUND | AO14: NOT FOUND | AP14: NOT FOUND | AQ14: NOT FOUND | AR14: NOT FOUND | AS14: NOT FOUND | AT14: NOT FOUND | AU14: NOT FOUND | AV14: NOT FOUND | AW14: NOT FOUND | AX14: NOT FOUND | AY14: NOT FOUND | AZ14: NOT FOUND | BA14: NOT FOUND | BB14: NOT FOUND | BC14: NOT FOUND | BD14: NOT FOUND | BE14: NOT FOUND | BF14: NOT FOUND | BG14: NOT FOUND | BH14: NOT FOUND | BI14: NOT FOUND | BJ14: NOT FOUND | BK14: NOT FOUND | BL14: NOT FOUND | BM14: NOT FOUND | BN14: NOT FOUND | BO14: NOT FOUND | BP14: NOT FOUND | BQ14: NOT FOUND | BR14: NOT FOUND | BS14: NOT FOUND | BT14: REPROVED | BU14: POSTED ISSUE | BV14: OUTDATED | BW14: OUTDATED | BX14: APPROVED | BY14: NO ISSUE | BZ14: PREVIOUSLY APPROVED | CA14: NO ISSUE | CB14: PREVIOUSLY APPROVED | CC14: NO ISSUE | CD14: PREVIOUSLY APPROVED | CE14: NO ISSUE | CF14: PREVIOUSLY APPROVED | CG14: NO ISSUE | CH14: PREVIOUSLY APPROVED | CI14: NO ISSUE | CJ14: PREVIOUSLY APPROVED | CK14: NO ISSUE | CL14: PREVIOUSLY APPROVED | CM14: =IF( OR(CL14="APPROVED", CL14="PREVIOUSLY APPROVED"), "APPROVED", "REPROVED" ) -> APPROVED | CP14: SEM ISSUE | CQ14: NA
A15: 73 | B15: MODAX | D15: MODAX | F15: =IFERROR(VLOOKUP(L15:L76,'R22 RELATÓRIO ACC'!B:F,5,FALSE),"NOT PUBLISHED") -> V1 | G15: =IFERROR(VLOOKUP(L15:L76,'R22 RELATÓRIO ACC'!B:P,15,FALSE),"NOT PUBLISHED") -> 05/05/2026 | H15: =IFERROR(VLOOKUP(M15:M76,'RELATÓRIO ACC'!B:F,5,FALSE),"NOT PUBLISHED") -> V2 | I15: =IFERROR(VLOOKUP(M15:M76,'RELATÓRIO ACC'!B:P,15,FALSE),"NOT PUBLISHED") -> 26/05/2026 | J15: V1 | K15: 46160 | L15: CPQ11-STRC-FLOO-SITE-R22.rvt | M15: CPQ11-STRC-FLOO-SITE-R24.rvt | N15: FALSE | O15: FALSE | P15: NOT FOUND | Q15: NOT FOUND | R15: NOT FOUND | S15: NOT FOUND | T15: NOT FOUND | U15: NOT FOUND | V15: NOT FOUND | W15: NOT FOUND | X15: NOT FOUND | Y15: NOT FOUND | Z15: NOT FOUND | AA15: NOT FOUND | AB15: NOT FOUND | AC15: NOT FOUND | AD15: NOT FOUND | AE15: NOT FOUND | AF15: NOT FOUND | AG15: NOT FOUND | AH15: NOT FOUND | AI15: NOT FOUND | AJ15: NOT FOUND | AK15: NOT FOUND | AL15: NOT FOUND | AM15: NOT FOUND | AN15: NOT FOUND | AO15: NOT FOUND | AP15: NOT FOUND | AQ15: NOT FOUND | AR15: NOT FOUND | AS15: NOT FOUND | AT15: NOT FOUND | AU15: NOT FOUND | AV15: NOT FOUND | AW15: NOT FOUND | AX15: NOT FOUND | AY15: NOT FOUND | AZ15: NOT FOUND | BA15: NOT FOUND | BB15: NOT FOUND | BC15: NOT FOUND | BD15: NOT FOUND | BE15: NOT FOUND | BF15: NOT FOUND | BG15: NOT FOUND | BH15: NOT FOUND | BI15: NOT FOUND | BJ15: NOT FOUND | BK15: NOT FOUND | BL15: NOT FOUND | BM15: NOT FOUND | BN15: NOT FOUND | BO15: NOT FOUND | BP15: NOT FOUND | BQ15: NOT FOUND | BR15: NOT FOUND | BS15: NOT FOUND | BT15: APPROVED | BU15: NO ISSUE | BV15: PREVIOUSLY APPROVED | BW15: NO ISSUE | BX15: PREVIOUSLY APPROVED | BY15: NO ISSUE | BZ15: PREVIOUSLY APPROVED | CA15: NO ISSUE | CB15: PREVIOUSLY APPROVED | CC15: NO ISSUE | CD15: PREVIOUSLY APPROVED | CE15: NO ISSUE | CF15: PREVIOUSLY APPROVED | CG15: NO ISSUE | CH15: PREVIOUSLY APPROVED | CI15: NO ISSUE | CJ15: PREVIOUSLY APPROVED | CK15: NO ISSUE | CL15: PREVIOUSLY APPROVED | CM15: =IF( OR(CL15="APPROVED", CL15="PREVIOUSLY APPROVED"), "APPROVED", "REPROVED" ) -> APPROVED | CP15: PENDENTE | CQ15: COMENTÁRIO
A16: 1 | B16: ARE ARQUITETURA | C16: ARE ARQUITETURA | D16: ARE ARQUITETURA | E16: 1130 | F16: =IFERROR(VLOOKUP(L16:L77,'R22 RELATÓRIO ACC'!B:F,5,FALSE),"NOT PUBLISHED") -> V29 | G16: =IFERROR(VLOOKUP(L16:L77,'R22 RELATÓRIO ACC'!B:P,15,FALSE),"NOT PUBLISHED") -> 13/04/2026 | H16: =IFERROR(VLOOKUP(M16:M77,'RELATÓRIO ACC'!B:F,5,FALSE),"NOT PUBLISHED") -> V3 | I16: =IFERROR(VLOOKUP(M16:M77,'RELATÓRIO ACC'!B:P,15,FALSE),"NOT PUBLISHED") -> 03/06/2026 | J16: V18 | K16: 45904 | L16: CPQ11-ARCH-ARCH-DATA-R22.rvt | M16: CPQ11-ARCH-ARCH-DATA-R24.rvt | N16: TRUE | O16: TRUE | P16: NOT FOUND | Q16: REPROVED | R16: REPROVED | S16: POSTED ISSUES | T16: APPROVED | U16: NO ISSUE | V16: PREVIOUSLY APPROVED | W16: NO ISSUE | X16: PREVIOUSLY APPROVED | Y16: NO ISSUE | Z16: PREVIOUSLY APPROVED | AA16: NO ISSUE | AB16: PREVIOUSLY APPROVED | AC16: NO ISSUE | AD16: PREVIOUSLY APPROVED | AE16: NO ISSUE | AF16: PREVIOUSLY APPROVED | AG16: NO ISSUE | AH16: PREVIOUSLY APPROVED | AI16: NO ISSUE | AJ16: PREVIOUSLY APPROVED | AK16: NO ISSUE | AL16: PREVIOUSLY APPROVED | AM16: NO ISSUE | AN16: PREVIOUSLY APPROVED | AO16: NO ISSUE | AP16: PREVIOUSLY APPROVED | AQ16: NO ISSUE | AR16: PREVIOUSLY APPROVED | AS16: NO ISSUE | AT16: PREVIOUSLY APPROVED | AU16: NO ISSUE | AV16: PREVIOUSLY APPROVED | AW16: NO ISSUE | AX16: PREVIOUSLY APPROVED | AY16: NO ISSUE | AZ16: PREVIOUSLY APPROVED | BA16: NO ISSUE | BB16: PREVIOUSLY APPROVED | BC16: NO ISSUE | BD16: PREVIOUSLY APPROVED | BE16: NO ISSUE | BF16: PREVIOUSLY APPROVED | BG16: NO ISSUE | BH16: PREVIOUSLY APPROVED | BI16: NO ISSUE | BJ16: PREVIOUSLY APPROVED | BK16: NO ISSUE | BL16: PREVIOUSLY APPROVED | BM16: NO ISSUE | BN16: PREVIOUSLY APPROVED | BO16: NO ISSUE | BP16: PREVIOUSLY APPROVED | BQ16: NO ISSUE | BR16: PREVIOUSLY APPROVED | BS16: NO ISSUE | BT16: PREVIOUSLY APPROVED | BU16: NO ISSUE | BV16: PREVIOUSLY APPROVED | BW16: NO ISSUE | BX16: PREVIOUSLY APPROVED | BY16: NO ISSUE | BZ16: PREVIOUSLY APPROVED | CA16: NO ISSUE | CB16: PREVIOUSLY APPROVED | CC16: NO ISSUE | CD16: PREVIOUSLY APPROVED | CE16: NO ISSUE | CF16: PREVIOUSLY APPROVED | CG16: NO ISSUE | CH16: PREVIOUSLY APPROVED | CI16: NO ISSUE | CJ16: PREVIOUSLY APPROVED | CK16: NO ISSUE | CL16: PREVIOUSLY APPROVED | CM16: =IF( OR(CL16="APPROVED", CL16="PREVIOUSLY APPROVED"), "APPROVED", "REPROVED" ) -> APPROVED | CP16: SEM ISSUE | CQ16: NA
A17: 2 | B17: ARE ARQUITETURA | D17: ARE ARQUITETURA | E17: 1130 | F17: =IFERROR(VLOOKUP(L17:L78,'R22 RELATÓRIO ACC'!B:F,5,FALSE),"NOT PUBLISHED") -> V28 | G17: =IFERROR(VLOOKUP(L17:L78,'R22 RELATÓRIO ACC'!B:P,15,FALSE),"NOT PUBLISHED") -> 17/04/2026 | H17: =IFERROR(VLOOKUP(M17:M78,'RELATÓRIO ACC'!B:F,5,FALSE),"NOT PUBLISHED") -> V4 | I17: =IFERROR(VLOOKUP(M17:M78,'RELATÓRIO ACC'!B:P,15,FALSE),"NOT PUBLISHED") -> 15/07/2026 | J17: V19 | K17: 45947 | L17: CPQ11-ARCH-ARCH-SITE-R22.rvt | M17: CPQ11-ARCH-ARCH-SITE-R24.rvt | N17: TRUE | O17: TRUE | P17: NOT FOUND | Q17: REPROVED | R17: REPROVED | S17: POSTED ISSUES | T17: REPROVED | U17: POSTED ISSUES | V17: OUTDATED | W17: OUTDATED | X17: OUTDATED | Y17: OUTDATED | Z17: REPROVED | AA17: POSTED ISSUES | AB17: APPROVED | AC17: NO ISSUE | AD17: PREVIOUSLY APPROVED | AE17: NO ISSUE | AF17: PREVIOUSLY APPROVED | AG17: NO ISSUE | AH17: PREVIOUSLY APPROVED | AI17: NO ISSUE | AJ17: PREVIOUSLY APPROVED | AK17: NO ISSUE | AL17: PREVIOUSLY APPROVED | AM17: NO ISSUE | AN17: PREVIOUSLY APPROVED | AO17: NO ISSUE | AP17: PREVIOUSLY APPROVED | AQ17: NO ISSUE | AR17: PREVIOUSLY APPROVED | AS17: NO ISSUE | AT17: PREVIOUSLY APPROVED | AU17: NO ISSUE | AV17: PREVIOUSLY APPROVED | AW17: NO ISSUE | AX17: PREVIOUSLY APPROVED | AY17: NO ISSUE | AZ17: PREVIOUSLY APPROVED | BA17: NO ISSUE | BB17: PREVIOUSLY APPROVED | BC17: NO ISSUE | BD17: PREVIOUSLY APPROVED | BE17: NO ISSUE | BF17: PREVIOUSLY APPROVED | BG17: NO ISSUE | BH17: PREVIOUSLY APPROVED | BI17: NO ISSUE | BJ17: PREVIOUSLY APPROVED | BK17: NO ISSUE | BL17: PREVIOUSLY APPROVED | BM17: NO ISSUE | BN17: PREVIOUSLY APPROVED | BO17: NO ISSUE | BP17: PREVIOUSLY APPROVED | BQ17: NO ISSUE | BR17: PREVIOUSLY APPROVED | BS17: NO ISSUE | BT17: PREVIOUSLY APPROVED | BU17: NO ISSUE | BV17: PREVIOUSLY APPROVED | BW17: NO ISSUE | BX17: PREVIOUSLY APPROVED | BY17: NO ISSUE | BZ17: PREVIOUSLY APPROVED | CA17: NO ISSUE | CB17: PREVIOUSLY APPROVED | CC17: NO ISSUE | CD17: PREVIOUSLY APPROVED | CE17: NO ISSUE | CF17: PREVIOUSLY APPROVED | CG17: NO ISSUE | CH17: PREVIOUSLY APPROVED | CI17: NO ISSUE | CJ17: PREVIOUSLY APPROVED | CK17: NO ISSUE | CL17: PREVIOUSLY APPROVED | CM17: =IF( OR(CL17="APPROVED", CL17="PREVIOUSLY APPROVED"), "APPROVED", "REPROVED" ) -> APPROVED | CP17: SEM ISSUE | CQ17: NA
A18: 4 | B18: INOVAGLASS | C18: INOVAGLASS | D18: INOVAGLASS | E18: 1109 | F18: =IFERROR(VLOOKUP(L18:L79,'R22 RELATÓRIO ACC'!B:F,5,FALSE),"NOT PUBLISHED") -> V9 | G18: =IFERROR(VLOOKUP(L18:L79,'R22 RELATÓRIO ACC'!B:P,15,FALSE),"NOT PUBLISHED") -> 04/12/2025 | H18: =IFERROR(VLOOKUP(M18:M79,'RELATÓRIO ACC'!B:F,5,FALSE),"NOT PUBLISHED") -> V1 | I18: =IFERROR(VLOOKUP(M18:M79,'RELATÓRIO ACC'!B:P,15,FALSE),"NOT PUBLISHED") -> 20/05/2026 | J18: V7 | K18: 45849 | L18: CPQ11-ARCH-BLPR-GUAR-R22.rvt | M18: CPQ11-ARCH-BLPR-GUAR-R24.rvt | N18: TRUE | O18: TRUE | P18: NOT FOUND | Q18: REPROVED | R18: APPROVED | S18: NO ISSUE | T18: APPROVED | U18: NO ISSUE | V18: PREVIOUSLY APPROVED | W18: NO ISSUE | X18: PREVIOUSLY APPROVED | Y18: NO ISSUE | Z18: PREVIOUSLY APPROVED | AA18: NO ISSUE | AB18: PREVIOUSLY APPROVED | AC18: NO ISSUE | AD18: PREVIOUSLY APPROVED | AE18: NO ISSUE | AF18: PREVIOUSLY APPROVED | AG18: NO ISSUE | AH18: PREVIOUSLY APPROVED | AI18: NO ISSUE | AJ18: PREVIOUSLY APPROVED | AK18: NO ISSUE | AL18: PREVIOUSLY APPROVED | AM18: NO ISSUE | AN18: PREVIOUSLY APPROVED | AO18: NO ISSUE | AP18: PREVIOUSLY APPROVED | AQ18: NO ISSUE | AR18: PREVIOUSLY APPROVED | AS18: NO ISSUE | AT18: PREVIOUSLY APPROVED | AU18: NO ISSUE | AV18: PREVIOUSLY APPROVED | AW18: NO ISSUE | AX18: PREVIOUSLY APPROVED | AY18: NO ISSUE | AZ18: PREVIOUSLY APPROVED | BA18: NO ISSUE | BB18: PREVIOUSLY APPROVED | BC18: NO ISSUE | BD18: PREVIOUSLY APPROVED | BE18: NO ISSUE | BF18: PREVIOUSLY APPROVED | BG18: NO ISSUE | BH18: PREVIOUSLY APPROVED | BI18: NO ISSUE | BJ18: PREVIOUSLY APPROVED | BK18: NO ISSUE | BL18: PREVIOUSLY APPROVED | BM18: NO ISSUE | BN18: PREVIOUSLY APPROVED | BO18: NO ISSUE | BP18: PREVIOUSLY APPROVED | BQ18: NO ISSUE | BR18: PREVIOUSLY APPROVED | BS18: NO ISSUE | BT18: PREVIOUSLY APPROVED | BU18: NO ISSUE | BV18: PREVIOUSLY APPROVED | BW18: NO ISSUE | BX18: PREVIOUSLY APPROVED | BY18: NO ISSUE | BZ18: PREVIOUSLY APPROVED | CA18: NO ISSUE | CB18: PREVIOUSLY APPROVED | CC18: NO ISSUE | CD18: PREVIOUSLY APPROVED | CE18: NO ISSUE | CF18: PREVIOUSLY APPROVED | CG18: NO ISSUE | CH18: PREVIOUSLY APPROVED | CI18: NO ISSUE | CJ18: PREVIOUSLY APPROVED | CK18: NO ISSUE | CL18: PREVIOUSLY APPROVED | CM18: =IF( OR(CL18="APPROVED", CL18="PREVIOUSLY APPROVED"), "APPROVED", "REPROVED" ) -> APPROVED | CP18: PENDENTE | CQ18: SEM INTERAÇÃO
A19: 5 | B19: VALE | D19: SPBIM | F19: =IFERROR(VLOOKUP(L19:L80,'R22 RELATÓRIO ACC'!B:F,5,FALSE),"NOT PUBLISHED") -> V12 | G19: =IFERROR(VLOOKUP(L19:L80,'R22 RELATÓRIO ACC'!B:P,15,FALSE),"NOT PUBLISHED") -> 06/04/2026 | H19: =IFERROR(VLOOKUP(M19:M80,'RELATÓRIO ACC'!B:F,5,FALSE),"NOT PUBLISHED") -> V1 | I19: =IFERROR(VLOOKUP(M19:M80,'RELATÓRIO ACC'!B:P,15,FALSE),"NOT PUBLISHED") -> 15/05/2026 | J19: V4 | K19: 45876 | L19: CPQ11-ARCH-CHAI-SITE-R22.rvt | M19: CPQ11-ARCH-CHAI-SITE-R24.rvt | N19: TRUE | O19: FALSE | P19: NOT FOUND | Q19: NOT FOUND | R19: APPROVED | S19: NO ISSUE | T19: APPROVED | U19: NO ISSUE | V19: PREVIOUSLY APPROVED | W19: NO ISSUE | X19: PREVIOUSLY APPROVED | Y19: NO ISSUE | Z19: PREVIOUSLY APPROVED | AA19: NO ISSUE | AB19: PREVIOUSLY APPROVED | AC19: NO ISSUE | AD19: PREVIOUSLY APPROVED | AE19: NO ISSUE | AF19: PREVIOUSLY APPROVED | AG19: NO ISSUE | AH19: PREVIOUSLY APPROVED | AI19: NO ISSUE | AJ19: PREVIOUSLY APPROVED | AK19: NO ISSUE | AL19: PREVIOUSLY APPROVED | AM19: NO ISSUE | AN19: PREVIOUSLY APPROVED | AO19: NO ISSUE | AP19: PREVIOUSLY APPROVED | AQ19: NO ISSUE | AR19: PREVIOUSLY APPROVED | AS19: NO ISSUE | AT19: PREVIOUSLY APPROVED | AU19: NO ISSUE | AV19: PREVIOUSLY APPROVED | AW19: NO ISSUE | AX19: PREVIOUSLY APPROVED | AY19: NO ISSUE | AZ19: PREVIOUSLY APPROVED | BA19: NO ISSUE | BB19: PREVIOUSLY APPROVED | BC19: NO ISSUE | BD19: PREVIOUSLY APPROVED | BE19: NO ISSUE | BF19: PREVIOUSLY APPROVED | BG19: NO ISSUE | BH19: PREVIOUSLY APPROVED | BI19: NO ISSUE | BJ19: PREVIOUSLY APPROVED | BK19: NO ISSUE | BL19: PREVIOUSLY APPROVED | BM19: NO ISSUE | BN19: PREVIOUSLY APPROVED | BO19: NO ISSUE | BP19: PREVIOUSLY APPROVED | BQ19: NO ISSUE | BR19: PREVIOUSLY APPROVED | BS19: NO ISSUE | BT19: PREVIOUSLY APPROVED | BU19: NO ISSUE | BV19: PREVIOUSLY APPROVED | BW19: NO ISSUE | BX19: PREVIOUSLY APPROVED | BY19: NO ISSUE | BZ19: PREVIOUSLY APPROVED | CA19: NO ISSUE | CB19: PREVIOUSLY APPROVED | CC19: NO ISSUE | CD19: PREVIOUSLY APPROVED | CE19: NO ISSUE | CF19: PREVIOUSLY APPROVED | CG19: NO ISSUE | CH19: PREVIOUSLY APPROVED | CI19: NO ISSUE | CJ19: PREVIOUSLY APPROVED | CK19: NO ISSUE | CL19: PREVIOUSLY APPROVED | CM19: =IF( OR(CL19="APPROVED", CL19="PREVIOUSLY APPROVED"), "APPROVED", "REPROVED" ) -> APPROVED | CO19: FALSE | CP19: ABERTO | CQ19: COMENTÁRIO
A20: 6 | B20: OMNITRADE | C20: 1110 | D20: CADBIM | E20: 1128 | F20: =IFERROR(VLOOKUP(L20:L81,'R22 RELATÓRIO ACC'!B:F,5,FALSE),"NOT PUBLISHED") -> V25 | G20: =IFERROR(VLOOKUP(L20:L81,'R22 RELATÓRIO ACC'!B:P,15,FALSE),"NOT PUBLISHED") -> 06/05/2026 | H20: =IFERROR(VLOOKUP(M20:M81,'RELATÓRIO ACC'!B:F,5,FALSE),"NOT PUBLISHED") -> V3 | I20: =IFERROR(VLOOKUP(M20:M81,'RELATÓRIO ACC'!B:P,15,FALSE),"NOT PUBLISHED") -> 07/07/2026 | J20: V8 | K20: 45854 | L20: CPQ11-ARCH-FACD-DATA-R22.rvt | M20: CPQ11-ARCH-FACD-DATA-R24.rvt | N20: TRUE | O20: TRUE | P20: NOT FOUND | Q20: REPROVED | R20: REPROVED | S20: POSTED ISSUES | T20: APPROVED | U20: NO ISSUE | V20: PREVIOUSLY APPROVED | W20: NO ISSUE | X20: PREVIOUSLY APPROVED | Y20: NO ISSUE | Z20: PREVIOUSLY APPROVED | AA20: NO ISSUE | AB20: PREVIOUSLY APPROVED | AC20: NO ISSUE | AD20: PREVIOUSLY APPROVED | AE20: NO ISSUE | AF20: PREVIOUSLY APPROVED | AG20: NO ISSUE | AH20: PREVIOUSLY APPROVED | AI20: NO ISSUE | AJ20: PREVIOUSLY APPROVED | AK20: NO ISSUE | AL20: PREVIOUSLY APPROVED | AM20: NO ISSUE | AN20: PREVIOUSLY APPROVED | AO20: NO ISSUE | AP20: PREVIOUSLY APPROVED | AQ20: NO ISSUE | AR20: PREVIOUSLY APPROVED | AS20: NO ISSUE | AT20: PREVIOUSLY APPROVED | AU20: NO ISSUE | AV20: PREVIOUSLY APPROVED | AW20: NO ISSUE | AX20: PREVIOUSLY APPROVED | AY20: NO ISSUE | AZ20: PREVIOUSLY APPROVED | BA20: NO ISSUE | BB20: PREVIOUSLY APPROVED | BC20: NO ISSUE | BD20: PREVIOUSLY APPROVED | BE20: NO ISSUE | BF20: PREVIOUSLY APPROVED | BG20: NO ISSUE | BH20: PREVIOUSLY APPROVED | BI20: NO ISSUE | BJ20: PREVIOUSLY APPROVED | BK20: NO ISSUE | BL20: PREVIOUSLY APPROVED | BM20: NO ISSUE | BN20: PREVIOUSLY APPROVED | BO20: NO ISSUE | BP20: PREVIOUSLY APPROVED | BQ20: NO ISSUE | BR20: PREVIOUSLY APPROVED | BS20: NO ISSUE | BT20: PREVIOUSLY APPROVED | BU20: NO ISSUE | BV20: PREVIOUSLY APPROVED | BW20: NO ISSUE | BX20: PREVIOUSLY APPROVED | BY20: NO ISSUE | BZ20: PREVIOUSLY APPROVED | CA20: NO ISSUE | CB20: PREVIOUSLY APPROVED | CC20: NO ISSUE | CD20: PREVIOUSLY APPROVED | CE20: NO ISSUE | CF20: PREVIOUSLY APPROVED | CG20: NO ISSUE | CH20: PREVIOUSLY APPROVED | CI20: NO ISSUE | CJ20: PREVIOUSLY APPROVED | CK20: NO ISSUE | CL20: PREVIOUSLY APPROVED | CM20: =IF( OR(CL20="APPROVED", CL20="PREVIOUSLY APPROVED"), "APPROVED", "REPROVED" ) -> APPROVED | CP20: SEM ISSUE | CQ20: NA
A21: 7 | B21: ZEUS/PORTEX | C21: PORTEX | D21: SPBIM | F21: =IFERROR(VLOOKUP(L21:L82,'R22 RELATÓRIO ACC'!B:F,5,FALSE),"NOT PUBLISHED") -> V9 | G21: =IFERROR(VLOOKUP(L21:L82,'R22 RELATÓRIO ACC'!B:P,15,FALSE),"NOT PUBLISHED") -> 27/03/2026 | H21: =IFERROR(VLOOKUP(M21:M82,'RELATÓRIO ACC'!B:F,5,FALSE),"NOT PUBLISHED") -> V2 | I21: =IFERROR(VLOOKUP(M21:M82,'RELATÓRIO ACC'!B:P,15,FALSE),"NOT PUBLISHED") -> 26/06/2026 | J21: V3 | K21: 45840 | L21: CPQ11-ARCH-HM90-DATA-R22.rvt | M21: CPQ11-ARCH-HM90-DATA-R24.rvt | N21: TRUE | O21: TRUE | P21: NOT FOUND | Q21: NOT FOUND | R21: APPROVED | S21: NO ISSUE | T21: APPROVED | U21: NO ISSUE | V21: PREVIOUSLY APPROVED | W21: NO ISSUE | X21: PREVIOUSLY APPROVED | Y21: NO ISSUE | Z21: PREVIOUSLY APPROVED | AA21: NO ISSUE | AB21: PREVIOUSLY APPROVED | AC21: NO ISSUE | AD21: PREVIOUSLY APPROVED | AE21: NO ISSUE | AF21: PREVIOUSLY APPROVED | AG21: NO ISSUE | AH21: PREVIOUSLY APPROVED | AI21: NO ISSUE | AJ21: PREVIOUSLY APPROVED | AK21: NO ISSUE | AL21: PREVIOUSLY APPROVED | AM21: NO ISSUE | AN21: PREVIOUSLY APPROVED | AO21: NO ISSUE | AP21: PREVIOUSLY APPROVED | AQ21: NO ISSUE | AR21: PREVIOUSLY APPROVED | AS21: NO ISSUE | AT21: PREVIOUSLY APPROVED | AU21: NO ISSUE | AV21: PREVIOUSLY APPROVED | AW21: NO ISSUE | AX21: PREVIOUSLY APPROVED | AY21: NO ISSUE | AZ21: PREVIOUSLY APPROVED | BA21: NO ISSUE | BB21: PREVIOUSLY APPROVED | BC21: NO ISSUE | BD21: PREVIOUSLY APPROVED | BE21: NO ISSUE | BF21: PREVIOUSLY APPROVED | BG21: NO ISSUE | BH21: PREVIOUSLY APPROVED | BI21: NO ISSUE | BJ21: PREVIOUSLY APPROVED | BK21: NO ISSUE | BL21: PREVIOUSLY APPROVED | BM21: NO ISSUE | BN21: PREVIOUSLY APPROVED | BO21: NO ISSUE | BP21: PREVIOUSLY APPROVED | BQ21: NO ISSUE | BR21: PREVIOUSLY APPROVED | BS21: NO ISSUE | BT21: PREVIOUSLY APPROVED | BU21: NO ISSUE | BV21: PREVIOUSLY APPROVED | BW21: NO ISSUE | BX21: PREVIOUSLY APPROVED | BY21: NO ISSUE | BZ21: PREVIOUSLY APPROVED | CA21: NO ISSUE | CB21: PREVIOUSLY APPROVED | CC21: NO ISSUE | CD21: PREVIOUSLY APPROVED | CE21: NO ISSUE | CF21: PREVIOUSLY APPROVED | CG21: NO ISSUE | CH21: PREVIOUSLY APPROVED | CI21: NO ISSUE | CJ21: PREVIOUSLY APPROVED | CK21: NO ISSUE | CL21: PREVIOUSLY APPROVED | CM21: =IF( OR(CL21="APPROVED", CL21="PREVIOUSLY APPROVED"), "APPROVED", "REPROVED" ) -> APPROVED | CO21: FALSE
A22: 8 | B22: S-VALE | C22: 1104 | D22: SPBIM | F22: =IFERROR(VLOOKUP(L22:L83,'R22 RELATÓRIO ACC'!B:F,5,FALSE),"NOT PUBLISHED") -> V12 | G22: =IFERROR(VLOOKUP(L22:L83,'R22 RELATÓRIO ACC'!B:P,15,FALSE),"NOT PUBLISHED") -> 08/04/2026 | H22: =IFERROR(VLOOKUP(M22:M83,'RELATÓRIO ACC'!B:F,5,FALSE),"NOT PUBLISHED") -> V1 | I22: =IFERROR(VLOOKUP(M22:M83,'RELATÓRIO ACC'!B:P,15,FALSE),"NOT PUBLISHED") -> 15/05/2026 | J22: V5 | K22: 45838 | L22: CPQ11-ARCH-HMET-DATA-R22.rvt | M22: CPQ11-ARCH-HMET-DATA-R24.rvt | N22: TRUE | O22: NON-RECIVED TABLE | P22: NOT FOUND | Q22: NOT FOUND | R22: APPROVED | S22: NO ISSUE | T22: APPROVED | U22: NO ISSUE | V22: PREVIOUSLY APPROVED | W22: NO ISSUE | X22: PREVIOUSLY APPROVED | Y22: NO ISSUE | Z22: PREVIOUSLY APPROVED | AA22: NO ISSUE | AB22: PREVIOUSLY APPROVED | AC22: NO ISSUE | AD22: PREVIOUSLY APPROVED | AE22: NO ISSUE | AF22: PREVIOUSLY APPROVED | AG22: NO ISSUE | AH22: PREVIOUSLY APPROVED | AI22: NO ISSUE | AJ22: PREVIOUSLY APPROVED | AK22: NO ISSUE | AL22: PREVIOUSLY APPROVED | AM22: NO ISSUE | AN22: PREVIOUSLY APPROVED | AO22: NO ISSUE | AP22: PREVIOUSLY APPROVED | AQ22: NO ISSUE | AR22: PREVIOUSLY APPROVED | AS22: NO ISSUE | AT22: PREVIOUSLY APPROVED | AU22: NO ISSUE | AV22: PREVIOUSLY APPROVED | AW22: NO ISSUE | AX22: PREVIOUSLY APPROVED | AY22: NO ISSUE | AZ22: PREVIOUSLY APPROVED | BA22: NO ISSUE | BB22: PREVIOUSLY APPROVED | BC22: NO ISSUE | BD22: PREVIOUSLY APPROVED | BE22: NO ISSUE | BF22: PREVIOUSLY APPROVED | BG22: NO ISSUE | BH22: PREVIOUSLY APPROVED | BI22: NO ISSUE | BJ22: PREVIOUSLY APPROVED | BK22: NO ISSUE | BL22: PREVIOUSLY APPROVED | BM22: NO ISSUE | BN22: PREVIOUSLY APPROVED | BO22: NO ISSUE | BP22: PREVIOUSLY APPROVED | BQ22: NO ISSUE | BR22: PREVIOUSLY APPROVED | BS22: NO ISSUE | BT22: PREVIOUSLY APPROVED | BU22: NO ISSUE | BV22: PREVIOUSLY APPROVED | BW22: NO ISSUE | BX22: PREVIOUSLY APPROVED | BY22: NO ISSUE | BZ22: PREVIOUSLY APPROVED | CA22: NO ISSUE | CB22: PREVIOUSLY APPROVED | CC22: NO ISSUE | CD22: PREVIOUSLY APPROVED | CE22: NO ISSUE | CF22: PREVIOUSLY APPROVED | CG22: NO ISSUE | CH22: PREVIOUSLY APPROVED | CI22: NO ISSUE | CJ22: PREVIOUSLY APPROVED | CK22: NO ISSUE | CL22: PREVIOUSLY APPROVED | CM22: =IF( OR(CL22="APPROVED", CL22="PREVIOUSLY APPROVED"), "APPROVED", "REPROVED" ) -> APPROVED | CO22: FALSE | CP22: ABERTO | CQ22: COMENTÁRIO
A23: 9 | B23: VALE | D23: SPBIM | F23: =IFERROR(VLOOKUP(L23:L84,'R22 RELATÓRIO ACC'!B:F,5,FALSE),"NOT PUBLISHED") -> V9 | G23: =IFERROR(VLOOKUP(L23:L84,'R22 RELATÓRIO ACC'!B:P,15,FALSE),"NOT PUBLISHED") -> 10/04/2026 | H23: =IFERROR(VLOOKUP(M23:M84,'RELATÓRIO ACC'!B:F,5,FALSE),"NOT PUBLISHED") -> V1 | I23: =IFERROR(VLOOKUP(M23:M84,'RELATÓRIO ACC'!B:P,15,FALSE),"NOT PUBLISHED") -> 15/05/2026 | J23: V3 | K23: 45898 | L23: CPQ11-ARCH-HMET-SITE-R22.rvt | M23: CPQ11-ARCH-HMET-SITE-R24.rvt | N23: TRUE | O23: PEDING INFORMATION | P23: NOT FOUND | Q23: NOT FOUND | R23: NOT FOUND | S23: NOT FOUND | T23: APPROVED | U23: NO ISSUE | V23: PREVIOUSLY APPROVED | W23: NO ISSUE | X23: PREVIOUSLY APPROVED | Y23: NO ISSUE | Z23: PREVIOUSLY APPROVED | AA23: NO ISSUE | AB23: PREVIOUSLY APPROVED | AC23: NO ISSUE | AD23: PREVIOUSLY APPROVED | AE23: NO ISSUE | AF23: PREVIOUSLY APPROVED | AG23: NO ISSUE | AH23: PREVIOUSLY APPROVED | AI23: NO ISSUE | AJ23: PREVIOUSLY APPROVED | AK23: NO ISSUE | AL23: PREVIOUSLY APPROVED | AM23: NO ISSUE | AN23: PREVIOUSLY APPROVED | AO23: NO ISSUE | AP23: PREVIOUSLY APPROVED | AQ23: NO ISSUE | AR23: PREVIOUSLY APPROVED | AS23: NO ISSUE | AT23: PREVIOUSLY APPROVED | AU23: NO ISSUE | AV23: PREVIOUSLY APPROVED | AW23: NO ISSUE | AX23: PREVIOUSLY APPROVED | AY23: NO ISSUE | AZ23: PREVIOUSLY APPROVED | BA23: NO ISSUE | BB23: PREVIOUSLY APPROVED | BC23: NO ISSUE | BD23: PREVIOUSLY APPROVED | BE23: NO ISSUE | BF23: PREVIOUSLY APPROVED | BG23: NO ISSUE | BH23: PREVIOUSLY APPROVED | BI23: NO ISSUE | BJ23: PREVIOUSLY APPROVED | BK23: NO ISSUE | BL23: PREVIOUSLY APPROVED | BM23: NO ISSUE | BN23: PREVIOUSLY APPROVED | BO23: NO ISSUE | BP23: PREVIOUSLY APPROVED | BQ23: NO ISSUE | BR23: PREVIOUSLY APPROVED | BS23: NO ISSUE | BT23: PREVIOUSLY APPROVED | BU23: NO ISSUE | BV23: PREVIOUSLY APPROVED | BW23: NO ISSUE | BX23: PREVIOUSLY APPROVED | BY23: NO ISSUE | BZ23: PREVIOUSLY APPROVED | CA23: NO ISSUE | CB23: PREVIOUSLY APPROVED | CC23: NO ISSUE | CD23: PREVIOUSLY APPROVED | CE23: NO ISSUE | CF23: PREVIOUSLY APPROVED | CG23: NO ISSUE | CH23: PREVIOUSLY APPROVED | CI23: NO ISSUE | CJ23: PREVIOUSLY APPROVED | CK23: NO ISSUE | CL23: PREVIOUSLY APPROVED | CM23: =IF( OR(CL23="APPROVED", CL23="PREVIOUSLY APPROVED"), "APPROVED", "REPROVED" ) -> APPROVED | CP23: ABERTO | CQ23: SEM INTERAÇÃO
A24: 12 | B24: IDEIA DRYWALL | D24: FCH | E24: 1126 | F24: =IFERROR(VLOOKUP(L24:L85,'R22 RELATÓRIO ACC'!B:F,5,FALSE),"NOT PUBLISHED") -> V14 | G24: =IFERROR(VLOOKUP(L24:L85,'R22 RELATÓRIO ACC'!B:P,15,FALSE),"NOT PUBLISHED") -> 18/03/2026 | H24: =IFERROR(VLOOKUP(M24:M85,'RELATÓRIO ACC'!B:F,5,FALSE),"NOT PUBLISHED") -> V2 | I24: =IFERROR(VLOOKUP(M24:M85,'RELATÓRIO ACC'!B:P,15,FALSE),"NOT PUBLISHED") -> 17/06/2026 | J24: V9 | K24: 45889 | L24: CPQ11-ARCH-PART-SITE-R22.rvt | M24: CPQ11-ARCH-PART-SITE-R24.rvt | N24: TRUE | O24: NON-FILLED | P24: NOT FOUND | Q24: REPROVED | R24: REPROVED | S24: POSTED ISSUES | T24: APPROVED | U24: NO ISSUE | V24: PREVIOUSLY APPROVED | W24: NO ISSUE | X24: PREVIOUSLY APPROVED | Y24: NO ISSUE | Z24: PREVIOUSLY APPROVED | AA24: NO ISSUE | AB24: PREVIOUSLY APPROVED | AC24: NO ISSUE | AD24: PREVIOUSLY APPROVED | AE24: NO ISSUE | AF24: PREVIOUSLY APPROVED | AG24: NO ISSUE | AH24: PREVIOUSLY APPROVED | AI24: NO ISSUE | AJ24: PREVIOUSLY APPROVED | AK24: NO ISSUE | AL24: PREVIOUSLY APPROVED | AM24: NO ISSUE | AN24: PREVIOUSLY APPROVED | AO24: NO ISSUE | AP24: PREVIOUSLY APPROVED | AQ24: NO ISSUE | AR24: PREVIOUSLY APPROVED | AS24: NO ISSUE | AT24: PREVIOUSLY APPROVED | AU24: NO ISSUE | AV24: PREVIOUSLY APPROVED | AW24: NO ISSUE | AX24: PREVIOUSLY APPROVED | AY24: NO ISSUE | AZ24: PREVIOUSLY APPROVED | BA24: NO ISSUE | BB24: PREVIOUSLY APPROVED | BC24: NO ISSUE | BD24: PREVIOUSLY APPROVED | BE24: NO ISSUE | BF24: PREVIOUSLY APPROVED | BG24: NO ISSUE | BH24: PREVIOUSLY APPROVED | BI24: NO ISSUE | BJ24: PREVIOUSLY APPROVED | BK24: NO ISSUE | BL24: PREVIOUSLY APPROVED | BM24: NO ISSUE | BN24: PREVIOUSLY APPROVED | BO24: NO ISSUE | BP24: PREVIOUSLY APPROVED | BQ24: NO ISSUE | BR24: PREVIOUSLY APPROVED | BS24: NO ISSUE | BT24: PREVIOUSLY APPROVED | BU24: NO ISSUE | BV24: PREVIOUSLY APPROVED | BW24: NO ISSUE | BX24: PREVIOUSLY APPROVED | BY24: NO ISSUE | BZ24: PREVIOUSLY APPROVED | CA24: NO ISSUE | CB24: PREVIOUSLY APPROVED | CC24: NO ISSUE | CD24: PREVIOUSLY APPROVED | CE24: NO ISSUE | CF24: PREVIOUSLY APPROVED | CG24: NO ISSUE | CH24: PREVIOUSLY APPROVED | CI24: NO ISSUE | CJ24: PREVIOUSLY APPROVED | CK24: NO ISSUE | CL24: PREVIOUSLY APPROVED | CM24: =IF( OR(CL24="APPROVED", CL24="PREVIOUSLY APPROVED"), "APPROVED", "REPROVED" ) -> APPROVED | CP24: ABERTO | CQ24: COMENTÁRIO
A25: 13 | B25: OMNITRADE | C25: 1110 | D25: CADBIM | E25: 1128 | F25: =IFERROR(VLOOKUP(L25:L86,'R22 RELATÓRIO ACC'!B:F,5,FALSE),"NOT PUBLISHED") -> V30 | G25: =IFERROR(VLOOKUP(L25:L86,'R22 RELATÓRIO ACC'!B:P,15,FALSE),"NOT PUBLISHED") -> 26/03/2026 | H25: =IFERROR(VLOOKUP(M25:M86,'RELATÓRIO ACC'!B:F,5,FALSE),"NOT PUBLISHED") -> V2 | I25: =IFERROR(VLOOKUP(M25:M86,'RELATÓRIO ACC'!B:P,15,FALSE),"NOT PUBLISHED") -> 20/05/2026 | J25: V17 | K25: 45867 | L25: CPQ11-ARCH-ROOF-DATA-R22.rvt | M25: CPQ11-ARCH-ROOF-DATA-R24.rvt | N25: TRUE | O25: TRUE | P25: NOT FOUND | Q25: REPROVED | R25: REPROVED | S25: POSTED ISSUES | T25: APPROVED | U25: NO ISSUE | V25: PREVIOUSLY APPROVED | W25: NO ISSUE | X25: PREVIOUSLY APPROVED | Y25: NO ISSUE | Z25: PREVIOUSLY APPROVED | AA25: NO ISSUE | AB25: PREVIOUSLY APPROVED | AC25: NO ISSUE | AD25: PREVIOUSLY APPROVED | AE25: NO ISSUE | AF25: PREVIOUSLY APPROVED | AG25: NO ISSUE | AH25: PREVIOUSLY APPROVED | AI25: NO ISSUE | AJ25: PREVIOUSLY APPROVED | AK25: NO ISSUE | AL25: PREVIOUSLY APPROVED | AM25: NO ISSUE | AN25: PREVIOUSLY APPROVED | AO25: NO ISSUE | AP25: PREVIOUSLY APPROVED | AQ25: NO ISSUE | AR25: PREVIOUSLY APPROVED | AS25: NO ISSUE | AT25: PREVIOUSLY APPROVED | AU25: NO ISSUE | AV25: PREVIOUSLY APPROVED | AW25: NO ISSUE | AX25: PREVIOUSLY APPROVED | AY25: NO ISSUE | AZ25: PREVIOUSLY APPROVED | BA25: NO ISSUE | BB25: PREVIOUSLY APPROVED | BC25: NO ISSUE | BD25: PREVIOUSLY APPROVED | BE25: NO ISSUE | BF25: PREVIOUSLY APPROVED | BG25: NO ISSUE | BH25: PREVIOUSLY APPROVED | BI25: NO ISSUE | BJ25: PREVIOUSLY APPROVED | BK25: NO ISSUE | BL25: PREVIOUSLY APPROVED | BM25: NO ISSUE | BN25: PREVIOUSLY APPROVED | BO25: NO ISSUE | BP25: PREVIOUSLY APPROVED | BQ25: NO ISSUE | BR25: PREVIOUSLY APPROVED | BS25: NO ISSUE | BT25: PREVIOUSLY APPROVED | BU25: NO ISSUE | BV25: PREVIOUSLY APPROVED | BW25: NO ISSUE | BX25: PREVIOUSLY APPROVED | BY25: NO ISSUE | BZ25: PREVIOUSLY APPROVED | CA25: NO ISSUE | CB25: PREVIOUSLY APPROVED | CC25: NO ISSUE | CD25: PREVIOUSLY APPROVED | CE25: NO ISSUE | CF25: PREVIOUSLY APPROVED | CG25: NO ISSUE | CH25: PREVIOUSLY APPROVED | CI25: NO ISSUE | CJ25: PREVIOUSLY APPROVED | CK25: NO ISSUE | CL25: PREVIOUSLY APPROVED | CM25: =IF( OR(CL25="APPROVED", CL25="PREVIOUSLY APPROVED"), "APPROVED", "REPROVED" ) -> APPROVED | CP25: SEM ISSUE | CQ25: NA
A26: 14 | B26: ALTAMIRA | C26: ALTAMIRA | D26: ALTAMIRA | F26: =IFERROR(VLOOKUP(L26:L87,'R22 RELATÓRIO ACC'!B:F,5,FALSE),"NOT PUBLISHED") -> V9 | G26: =IFERROR(VLOOKUP(L26:L87,'R22 RELATÓRIO ACC'!B:P,15,FALSE),"NOT PUBLISHED") -> 28/02/2026 | H26: =IFERROR(VLOOKUP(M26:M87,'RELATÓRIO ACC'!B:F,5,FALSE),"NOT PUBLISHED") -> V1 | I26: =IFERROR(VLOOKUP(M26:M87,'RELATÓRIO ACC'!B:P,15,FALSE),"NOT PUBLISHED") -> 20/05/2026 | J26: V1 | K26: 45874 | L26: CPQ11-ARCH-SHLV-DATA-R22.rvt | M26: CPQ11-ARCH-SHLV-DATA-R24.rvt | N26: TRUE | O26: TRUE | P26: NOT FOUND | Q26: NOT FOUND | R26: NOT FOUND | S26: NOT FOUND | T26: APPROVED | U26: NO ISSUE | V26: PREVIOUSLY APPROVED | W26: NO ISSUE | X26: PREVIOUSLY APPROVED | Y26: NO ISSUE | Z26: PREVIOUSLY APPROVED | AA26: NO ISSUE | AB26: PREVIOUSLY APPROVED | AC26: NO ISSUE | AD26: PREVIOUSLY APPROVED | AE26: NO ISSUE | AF26: PREVIOUSLY APPROVED | AG26: NO ISSUE | AH26: PREVIOUSLY APPROVED | AI26: NO ISSUE | AJ26: PREVIOUSLY APPROVED | AK26: NO ISSUE | AL26: PREVIOUSLY APPROVED | AM26: NO ISSUE | AN26: PREVIOUSLY APPROVED | AO26: NO ISSUE | AP26: PREVIOUSLY APPROVED | AQ26: NO ISSUE | AR26: PREVIOUSLY APPROVED | AS26: NO ISSUE | AT26: PREVIOUSLY APPROVED | AU26: NO ISSUE | AV26: PREVIOUSLY APPROVED | AW26: NO ISSUE | AX26: PREVIOUSLY APPROVED | AY26: NO ISSUE | AZ26: PREVIOUSLY APPROVED | BA26: NO ISSUE | BB26: PREVIOUSLY APPROVED | BC26: NO ISSUE | BD26: PREVIOUSLY APPROVED | BE26: NO ISSUE | BF26: PREVIOUSLY APPROVED | BG26: NO ISSUE | BH26: PREVIOUSLY APPROVED | BI26: NO ISSUE | BJ26: PREVIOUSLY APPROVED | BK26: NO ISSUE | BL26: PREVIOUSLY APPROVED | BM26: NO ISSUE | BN26: PREVIOUSLY APPROVED | BO26: NO ISSUE | BP26: PREVIOUSLY APPROVED | BQ26: NO ISSUE | BR26: PREVIOUSLY APPROVED | BS26: NO ISSUE | BT26: PREVIOUSLY APPROVED | BU26: NO ISSUE | BV26: PREVIOUSLY APPROVED | BW26: NO ISSUE | BX26: PREVIOUSLY APPROVED | BY26: NO ISSUE | BZ26: PREVIOUSLY APPROVED | CA26: NO ISSUE | CB26: PREVIOUSLY APPROVED | CC26: NO ISSUE | CD26: PREVIOUSLY APPROVED | CE26: NO ISSUE | CF26: PREVIOUSLY APPROVED | CG26: NO ISSUE | CH26: PREVIOUSLY APPROVED | CI26: NO ISSUE | CJ26: PREVIOUSLY APPROVED | CK26: NO ISSUE | CL26: PREVIOUSLY APPROVED | CM26: =IF( OR(CL26="APPROVED", CL26="PREVIOUSLY APPROVED"), "APPROVED", "REPROVED" ) -> APPROVED | CP26: ABERTO | CQ26: SEM INTERAÇÃO
A27: 15 | B27: S-VALE | C27: 1104 | D27: SPBIM | E27: 1127 | F27: =IFERROR(VLOOKUP(L27:L88,'R22 RELATÓRIO ACC'!B:F,5,FALSE),"NOT PUBLISHED") -> V13 | G27: =IFERROR(VLOOKUP(L27:L88,'R22 RELATÓRIO ACC'!B:P,15,FALSE),"NOT PUBLISHED") -> 02/03/2026 | H27: =IFERROR(VLOOKUP(M27:M88,'RELATÓRIO ACC'!B:F,5,FALSE),"NOT PUBLISHED") -> V3 | I27: =IFERROR(VLOOKUP(M27:M88,'RELATÓRIO ACC'!B:P,15,FALSE),"NOT PUBLISHED") -> 24/06/2026 | J27: V8 | K27: 45833 | L27: CPQ11-ARCH-WMES-DATA-R22.rvt | M27: CPQ11-ARCH-WMES-DATA-R24.rvt | N27: TRUE | O27: TRUE | P27: NOT FOUND | Q27: APPROVED | R27: APPROVED | S27: NO ISSUE | T27: APPROVED | U27: NO ISSUE | V27: PREVIOUSLY APPROVED | W27: NO ISSUE | X27: PREVIOUSLY APPROVED | Y27: NO ISSUE | Z27: PREVIOUSLY APPROVED | AA27: NO ISSUE | AB27: PREVIOUSLY APPROVED | AC27: NO ISSUE | AD27: PREVIOUSLY APPROVED | AE27: NO ISSUE | AF27: PREVIOUSLY APPROVED | AG27: NO ISSUE | AH27: PREVIOUSLY APPROVED | AI27: NO ISSUE | AJ27: PREVIOUSLY APPROVED | AK27: NO ISSUE | AL27: PREVIOUSLY APPROVED | AM27: NO ISSUE | AN27: PREVIOUSLY APPROVED | AO27: NO ISSUE | AP27: PREVIOUSLY APPROVED | AQ27: NO ISSUE | AR27: PREVIOUSLY APPROVED | AS27: NO ISSUE | AT27: PREVIOUSLY APPROVED | AU27: NO ISSUE | AV27: PREVIOUSLY APPROVED | AW27: NO ISSUE | AX27: PREVIOUSLY APPROVED | AY27: NO ISSUE | AZ27: PREVIOUSLY APPROVED | BA27: NO ISSUE | BB27: PREVIOUSLY APPROVED | BC27: NO ISSUE | BD27: PREVIOUSLY APPROVED | BE27: NO ISSUE | BF27: PREVIOUSLY APPROVED | BG27: NO ISSUE | BH27: PREVIOUSLY APPROVED | BI27: NO ISSUE | BJ27: PREVIOUSLY APPROVED | BK27: NO ISSUE | BL27: PREVIOUSLY APPROVED | BM27: NO ISSUE | BN27: PREVIOUSLY APPROVED | BO27: NO ISSUE | BP27: PREVIOUSLY APPROVED | BQ27: NO ISSUE | BR27: PREVIOUSLY APPROVED | BS27: NO ISSUE | BT27: PREVIOUSLY APPROVED | BU27: NO ISSUE | BV27: PREVIOUSLY APPROVED | BW27: NO ISSUE | BX27: PREVIOUSLY APPROVED | BY27: NO ISSUE | BZ27: PREVIOUSLY APPROVED | CA27: NO ISSUE | CB27: PREVIOUSLY APPROVED | CC27: NO ISSUE | CD27: PREVIOUSLY APPROVED | CE27: NO ISSUE | CF27: PREVIOUSLY APPROVED | CG27: NO ISSUE | CH27: PREVIOUSLY APPROVED | CI27: NO ISSUE | CJ27: PREVIOUSLY APPROVED | CK27: NO ISSUE | CL27: PREVIOUSLY APPROVED | CM27: =IF( OR(CL27="APPROVED", CL27="PREVIOUSLY APPROVED"), "APPROVED", "REPROVED" ) -> APPROVED | CP27: SEM ISSUE | CQ27: SEM INTERAÇÃO
A28: 16 | B28: BLACKBOX | C28: 1114 | D28: BLACKBOX | E28: 1114 | F28: =IFERROR(VLOOKUP(L28:L89,'R22 RELATÓRIO ACC'!B:F,5,FALSE),"NOT PUBLISHED") -> V20 | G28: =IFERROR(VLOOKUP(L28:L89,'R22 RELATÓRIO ACC'!B:P,15,FALSE),"NOT PUBLISHED") -> 05/05/2026 | H28: =IFERROR(VLOOKUP(M28:M89,'RELATÓRIO ACC'!B:F,5,FALSE),"NOT PUBLISHED") -> V2 | I28: =IFERROR(VLOOKUP(M28:M89,'RELATÓRIO ACC'!B:P,15,FALSE),"NOT PUBLISHED") -> 12/07/2026 | J28: V11 | K28: 45901 | L28: CPQ11-BASM-DEVS-DATA-R22.rvt | M28: CPQ11-BASM-DEVS-DATA-R24.rvt | N28: TRUE | O28: TRUE | P28: NOT FOUND | Q28: REPROVED | R28: REPROVED | S28: POSTED ISSUES | T28: APPROVED | U28: NO ISSUE | V28: PREVIOUSLY APPROVED | W28: NO ISSUE | X28: PREVIOUSLY APPROVED | Y28: NO ISSUE | Z28: PREVIOUSLY APPROVED | AA28: NO ISSUE | AB28: PREVIOUSLY APPROVED | AC28: NO ISSUE | AD28: PREVIOUSLY APPROVED | AE28: NO ISSUE | AF28: PREVIOUSLY APPROVED | AG28: NO ISSUE | AH28: PREVIOUSLY APPROVED | AI28: NO ISSUE | AJ28: PREVIOUSLY APPROVED | AK28: NO ISSUE | AL28: PREVIOUSLY APPROVED | AM28: NO ISSUE | AN28: PREVIOUSLY APPROVED | AO28: NO ISSUE | AP28: PREVIOUSLY APPROVED | AQ28: NO ISSUE | AR28: PREVIOUSLY APPROVED | AS28: NO ISSUE | AT28: PREVIOUSLY APPROVED | AU28: NO ISSUE | AV28: PREVIOUSLY APPROVED | AW28: NO ISSUE | AX28: PREVIOUSLY APPROVED | AY28: NO ISSUE | AZ28: PREVIOUSLY APPROVED | BA28: NO ISSUE | BB28: PREVIOUSLY APPROVED | BC28: NO ISSUE | BD28: PREVIOUSLY APPROVED | BE28: NO ISSUE | BF28: PREVIOUSLY APPROVED | BG28: NO ISSUE | BH28: PREVIOUSLY APPROVED | BI28: NO ISSUE | BJ28: PREVIOUSLY APPROVED | BK28: NO ISSUE | BL28: PREVIOUSLY APPROVED | BM28: NO ISSUE | BN28: PREVIOUSLY APPROVED | BO28: NO ISSUE | BP28: PREVIOUSLY APPROVED | BQ28: NO ISSUE | BR28: PREVIOUSLY APPROVED | BS28: NO ISSUE | BT28: PREVIOUSLY APPROVED | BU28: NO ISSUE | BV28: PREVIOUSLY APPROVED | BW28: NO ISSUE | BX28: PREVIOUSLY APPROVED | BY28: NO ISSUE | BZ28: PREVIOUSLY APPROVED | CA28: NO ISSUE | CB28: PREVIOUSLY APPROVED | CC28: NO ISSUE | CD28: PREVIOUSLY APPROVED | CE28: NO ISSUE | CF28: PREVIOUSLY APPROVED | CG28: NO ISSUE | CH28: PREVIOUSLY APPROVED | CI28: NO ISSUE | CJ28: PREVIOUSLY APPROVED | CK28: NO ISSUE | CL28: PREVIOUSLY APPROVED | CM28: =IF( OR(CL28="APPROVED", CL28="PREVIOUSLY APPROVED"), "APPROVED", "REPROVED" ) -> APPROVED | CP28: PENDENTE | CQ28: COMENTÁRIO
