Workbook

Sheet PROGRESS CONTROL
D2: GENERAL AUDIT CONTROL
A4: ORDEM | B4: TRADE COMPANY | C4: TRADE CODE | D4: BIM COMPANY | E4: BIM COD | F4: ACC VERSION (R22) - META DO DIA 17/07 | G4: ACC FILE DATE (R22) - META DO DIA 17/07 | H4: ACC VERSION (R24) - META DO DIA 17/07 | I4: ACC FILE DATE (R24) - META DO DIA 17/07 | J4: VERSION DATE (DD/MM) | K4: VERSION | L4: VERSÃO DO MODELO | M4: FILE NAME (R22) | N4: FILE NAME (R24) | O4: STANDARD NAME | P4: LISTA PRIORIDADE RACIONAL | Q4: ISSUES ACC | R4: AUDITORIA | S4: STATUS TABELA ASPECTOS GERAIS | T4: STATUS RELATÓRIO | U4: RESPONSÁVEL | V4: DATA DE INÍCIO DA AUDITORIA | W4: DATA DE FINALIZAÇÃO DA AUDITORIA | X4: ROUND 1 - APPROVAL (%) | Y4: ROUND 2 - APPROVAL (%) | Z4: ROUND 3 - APPROVAL (%) | AA4: ROUND 4 - APPROVAL (%) | AB4: ROUND 5 - APPROVAL (%) | AC4: ROUND 6 - APPROVAL (%) | AD4: ROUND 7 - APPROVAL (%) | AE4: ROUND 8 - APPROVAL (%) | AF4: ROUND 9 - APPROVAL (%) | AG4: ROUND 10 - APPROVAL (%) | AH4: ROUND 11 - APPROVAL (%) | AI4: ROUND 12 - APPROVAL (%) | AJ4: ROUND 13 - APPROVAL (%) | AK4: ROUND 14 - APPROVAL (%) | AL4: ROUND 15 - APPROVAL (%) | AM4: ROUND 16 - APPROVAL (%) | AN4: ROUND 17 - APPROVAL (%) | AO4: ROUND 18 - APPROVAL (%) | AP4: ROUND 19 - APPROVAL (%) | AQ4: ROUND 20 - APPROVAL (%) | AR4: ROUND 21 - APPROVAL (%) | AS4: ROUND 22 - APPROVAL (%) | AT4: ROUND 23 - APPROVAL (%) | AU4: ROUND 24 - APPROVAL (%) | AV4: ROUND 25- APPROVAL (%) | AW4: ROUND 26- APPROVAL (%) | AX4: ROUND 27- APPROVAL (%) | AY4: ROUND 28- APPROVAL (%) | AZ4: ROUND 29- APPROVAL (%) | BA4: ROUND 30- APPROVAL (%) | BB4: ROUND 31- APPROVAL (%) | BC4: ROUND 32- APPROVAL (%) | BD4: ROUND 33- APPROVAL (%) | BE4: ROUND 34- APPROVAL (%) | BF4: ROUND 35- APPROVAL (%) | BG4: ROUND 36- APPROVAL (%) | BH4: ROUND 37- APPROVAL (%) | BI4: ROUND 38- APPROVAL (%) | BJ4: ROUND 39- APPROVAL (%) | BK4: ROUND 40- APPROVAL (%) | BL4: ROUND 41- APPROVAL (%) | BM4: ROUND 42- APPROVAL (%) | BN4: ISSUES (ROUND 42) | BO4: ESTIMATED DELIVERY (DD/MM) | BP4: RESUMO
A5: 28 | B5: MENDES HOLLER | C5: 1112 | D5: MENDES HOLLER | E5: 1112 | F5: =IFERROR(VLOOKUP(M5:M78,'R22 RELATÓRIO ACC'!B:F,5,FALSE),"NOT PUBLISHED") -> V17 | G5: =IFERROR(VLOOKUP(M5:M76,'R22 RELATÓRIO ACC'!B:P,15,FALSE),"NOT PUBLISHED") -> 14/05/2026 | H5: =IFERROR(VLOOKUP(N5:N78,'RELATÓRIO ACC'!B:F,5,FALSE),"NOT PUBLISHED") -> V4 | I5: =IFERROR(VLOOKUP(N5:N76,'RELATÓRIO ACC'!B:P,15,FALSE),"NOT PUBLISHED") -> 25/06/2026 | J5: 25/06/2026 | K5: V4 | L5: CONTINUA MESMA VERSÃO | M5: CPQ11-FPRT-FPRT-DATA-R22.rvt | N5: CPQ11-FPRT-FPRT-DATA-R24.rvt | O5: FPRT-FPRT-DATA | P5: FALSE | Q5: ABERTO | R5: FOI AUDITADO R7 | W5: 45876 | X5: NOT PUBLISHED | Y5: NOT PUBLISHED | Z5: 0.69 | AA5: OUTDATED | AB5: OUTDATED | AC5: 0.59 | AD5: 0.76 | AE5: OUTDATED | AF5: OUTDATED | AG5: OUTDATED | AH5: OUTDATED | AI5: OUTDATED | AJ5: OUTDATED | AK5: OUTDATED | AL5: 0.82 | AM5: OUTDATED | AN5: 0.88 | AO5: 0.88 | AP5: OUTDATED | AQ5: OUTDATED | AR5: OUTDATED | AS5: 0.88 | AT5: OUTDATED | AU5: 0.88 | AV5: OUTDATED | AW5: OUTDATED | AX5: NEXT ROUND | AY5: 0.82 | AZ5: OUTDATED | BA5: NEXT ROUND | BB5: 0.94 | BC5: NEXT ROUND | BD5: 0.94 | BE5: OUTDATED | BF5: NEXT ROUND | BG5: IMPROPER | BH5: OUTDATED | BI5: 0.82 | BJ5: NEXT ROUND | BK5: 0.94 | BL5: OUTDATED | BM5: OUTDATED | BN5: ON HOLD | BO5: OUTDATED | BP5: =IFERROR(__xludf.DUMMYFUNCTION("IFERROR( INDEX( FILTER(X5:BM5, ISNUMBER(X5:BM5)), COUNTA(FILTER(X5:BM5, ISNUMBER(X5:BM5))) ), BM5 )"),0.94) -> 0.94
A6: 68 | B6: IDEIA DRYWALL | C6: IDEIA DRYWALL | D6: T2B | F6: =IFERROR(VLOOKUP(M6:M79,'R22 RELATÓRIO ACC'!B:F,5,FALSE),"NOT PUBLISHED") -> V4 | G6: =IFERROR(VLOOKUP(M6:M77,'R22 RELATÓRIO ACC'!B:P,15,FALSE),"NOT PUBLISHED") -> 29/04/2026 | H6: =IFERROR(VLOOKUP(N6:N79,'RELATÓRIO ACC'!B:F,5,FALSE),"NOT PUBLISHED") -> V1 | I6: =IFERROR(VLOOKUP(N6:N77,'RELATÓRIO ACC'!B:P,15,FALSE),"NOT PUBLISHED") -> 04/06/2026 | J6: 04/06/2026 | K6: V1 | M6: CPQ11-ARCH-CEIL-DATA-R22.rvt | N6: CPQ11-ARCH-CEIL-DATA-R24.rvt | O6: ARCH-CEIL-DATA | P6: FALSE | X6: NOT PUBLISHED | Y6: NOT PUBLISHED | Z6: NOT PUBLISHED | AA6: NOT PUBLISHED | AB6: NOT PUBLISHED | AC6: NOT PUBLISHED | AD6: NOT PUBLISHED | AE6: NOT PUBLISHED | AF6: NOT PUBLISHED | AG6: NOT PUBLISHED | AH6: NOT PUBLISHED | AI6: NOT PUBLISHED | AJ6: NOT PUBLISHED | AK6: NOT PUBLISHED | AL6: 0.76 | AM6: OUTDATED | AN6: OUTDATED | AO6: OUTDATED | AP6: OUTDATED | AQ6: OUTDATED | AR6: OUTDATED | AS6: OUTDATED | AT6: 0.76 | AU6: OUTDATED | AV6: OUTDATED | AW6: OUTDATED | AX6: NEXT ROUND | AY6: IMPROPER | AZ6: OUTDATED | BA6: OUTDATED | BB6: OUTDATED | BC6: IMPROPER | BD6: OUTDATED | BE6: OUTDATED | BF6: OUTDATED | BG6: OUTDATED | BH6: IMPROPER | BI6: OUTDATED | BJ6: OUTDATED | BK6: OUTDATED | BL6: OUTDATED | BM6: OUTDATED | BN6: ON HOLD | BO6: OUTDATED | BP6: =IFERROR(__xludf.DUMMYFUNCTION("IFERROR( INDEX( FILTER(X6:BM6, ISNUMBER(X6:BM6)), COUNTA(FILTER(X6:BM6, ISNUMBER(X6:BM6))) ), BM6 )"),0.76) -> 0.76
A7: 69 | B7: IDEIA DRYWALL | C7: IDEIA DRYWALL | D7: T2B | F7: =IFERROR(VLOOKUP(M7:M80,'R22 RELATÓRIO ACC'!B:F,5,FALSE),"NOT PUBLISHED") -> V2 | G7: =IFERROR(VLOOKUP(M7:M78,'R22 RELATÓRIO ACC'!B:P,15,FALSE),"NOT PUBLISHED") -> 29/04/2026 | H7: =IFERROR(VLOOKUP(N7:N80,'RELATÓRIO ACC'!B:F,5,FALSE),"NOT PUBLISHED") -> V1 | I7: =IFERROR(VLOOKUP(N7:N78,'RELATÓRIO ACC'!B:P,15,FALSE),"NOT PUBLISHED") -> 12/06/2026 | J7: 46185 | K7: V1 | M7: CPQ11-ARCH-CEIL-SITE-R22.rvt | N7: CPQ11-ARCH-CEIL-SITE-R24.rvt | O7: ARCH-CEIL-SITE | P7: FALSE | X7: NOT PUBLISHED | Y7: NOT PUBLISHED | Z7: NOT PUBLISHED | AA7: NOT PUBLISHED | AB7: NOT PUBLISHED | AC7: NOT PUBLISHED | AD7: NOT PUBLISHED | AE7: NOT PUBLISHED | AF7: NOT PUBLISHED | AG7: NOT PUBLISHED | AH7: NOT PUBLISHED | AI7: NOT PUBLISHED | AJ7: NOT PUBLISHED | AK7: NOT PUBLISHED | AL7: 0.76 | AM7: OUTDATED | AN7: OUTDATED | AO7: OUTDATED | AP7: OUTDATED | AQ7: OUTDATED | AR7: OUTDATED | AS7: OUTDATED | AT7: OUTDATED | AU7: OUTDATED | AV7: OUTDATED | AW7: OUTDATED | AX7: OUTDATED | AY7: OUTDATED | AZ7: OUTDATED | BA7: OUTDATED | BB7: OUTDATED | BC7: IMPROPER | BD7: OUTDATED | BE7: OUTDATED | BF7: OUTDATED | BG7: OUTDATED | BH7: IMPROPER | BI7: OUTDATED | BJ7: OUTDATED | BK7: OUTDATED | BL7: OUTDATED | BM7: OUTDATED | BN7: ON HOLD | BO7: OUTDATED | BP7: =IFERROR(__xludf.DUMMYFUNCTION("IFERROR( INDEX( FILTER(X7:BM7, ISNUMBER(X7:BM7)), COUNTA(FILTER(X7:BM7, ISNUMBER(X7:BM7))) ), BM7 )"),0.76) -> 0.76
A8: 29 | B8: MENDES HOLLER | C8: 1112 | D8: MENDES HOLLER | E8: 1112 | F8: =IFERROR(VLOOKUP(M8:M81,'R22 RELATÓRIO ACC'!B:F,5,FALSE),"NOT PUBLISHED") -> V16 | G8: =IFERROR(VLOOKUP(M8:M79,'R22 RELATÓRIO ACC'!B:P,15,FALSE),"NOT PUBLISHED") -> 14/05/2026 | H8: =IFERROR(VLOOKUP(N8:N81,'RELATÓRIO ACC'!B:F,5,FALSE),"NOT PUBLISHED") -> V4 | I8: =IFERROR(VLOOKUP(N8:N79,'RELATÓRIO ACC'!B:P,15,FALSE),"NOT PUBLISHED") -> 13/07/2026 | J8: 24/06/2026 | K8: V3 | L8: CONTINUA MESMA VERSÃO | M8: CPQ11-FPRT-FPRT-SITE-R22.rvt | N8: CPQ11-FPRT-FPRT-SITE-R24.rvt | O8: FPRT-FPRT-SITE | P8: FALSE | Q8: ABERTO | R8: FOI AUDITADO R9 | V8: 45923 | W8: 45923 | X8: NOT PUBLISHED | Y8: NOT PUBLISHED | Z8: 0.5 | AA8: OUTDATED | AB8: OUTDATED | AC8: OUTDATED | AD8: 0.65 | AE8: OUTDATED | AF8: 0.76 | AG8: OUTDATED | AH8: OUTDATED | AI8: 0.76 | AJ8: OUTDATED | AK8: OUTDATED | AL8: OUTDATED | AM8: OUTDATED | AN8: 0.76 | AO8: 0.88 | AP8: OUTDATED | AQ8: 0.82 | AR8: OUTDATED | AS8: 0.94 | AT8: OUTDATED | AU8: 0.94 | AV8: OUTDATED | AW8: OUTDATED | AX8: NEXT ROUND | AY8: 0.88 | AZ8: OUTDATED | BA8: 0.94 | BB8: OUTDATED | BC8: NEXT ROUND | BD8: 0.88 | BE8: OUTDATED | BF8: NEXT ROUND | BG8: IMPROPER | BH8: OUTDATED | BI8: 0.88 | BJ8: NEXT ROUND | BK8: 1 | BL8: PREVIOUSLY APPROVED | BM8: PREVIOUSLY APPROVED | BN8: CLOSED | BO8: PREVIOUSLY APPROVED | BP8: =IFERROR(__xludf.DUMMYFUNCTION("IFERROR( INDEX( FILTER(X8:BK8, ISNUMBER(X8:BK8)), COUNTA(FILTER(X8:BK8, ISNUMBER(X8:BK8))) ), BK8 )"),1.0) -> 1
A9: 73 | B9: MODAX | D9: MODAX | F9: =IFERROR(VLOOKUP(M9:M82,'R22 RELATÓRIO ACC'!B:F,5,FALSE),"NOT PUBLISHED") -> V1 | G9: =IFERROR(VLOOKUP(M9:M80,'R22 RELATÓRIO ACC'!B:P,15,FALSE),"NOT PUBLISHED") -> 05/05/2026 | H9: =IFERROR(VLOOKUP(N9:N82,'RELATÓRIO ACC'!B:F,5,FALSE),"NOT PUBLISHED") -> V3 | I9: =IFERROR(VLOOKUP(N9:N80,'RELATÓRIO ACC'!B:P,15,FALSE),"NOT PUBLISHED") -> 20/06/2026 | J9: 26/05/2026 | K9: V2 | M9: CPQ11-STRC-FLOO-DATA-R22.rvt | N9: CPQ11-STRC-FLOO-DATA-R24.rvt | P9: FALSE | X9: NOT PUBLISHED | Y9: NOT PUBLISHED | Z9: NOT PUBLISHED | AA9: NOT PUBLISHED | AB9: NOT PUBLISHED | AC9: NOT PUBLISHED | AD9: NOT PUBLISHED | AE9: NOT PUBLISHED | AF9: NOT PUBLISHED | AG9: NOT PUBLISHED | AH9: NOT PUBLISHED | AI9: NOT PUBLISHED | AJ9: NOT PUBLISHED | AK9: NOT PUBLISHED | AL9: NOT PUBLISHED | AM9: NOT PUBLISHED | AN9: NOT PUBLISHED | AO9: NOT PUBLISHED | AP9: NOT PUBLISHED | AQ9: NOT PUBLISHED | AR9: NOT PUBLISHED | AS9: NOT PUBLISHED | AT9: NOT PUBLISHED | AU9: NOT PUBLISHED | AV9: NOT PUBLISHED | AW9: NOT PUBLISHED | AX9: NOT PUBLISHED | AY9: NOT PUBLISHED | AZ9: NOT PUBLISHED | BA9: NOT PUBLISHED | BB9: NOT PUBLISHED | BC9: NOT PUBLISHED | BD9: NEXT ROUND | BE9: 0.76 | BF9: OUTDATED | BG9: NEXT ROUND | BH9: 0.94 | BI9: OUTDATED | BJ9: 1 | BK9: PREVIOUSLY APPROVED | BL9: PREVIOUSLY APPROVED | BM9: PREVIOUSLY APPROVED | BN9: CLOSED | BO9: PREVIOUSLY APPROVED | BP9: =IFERROR(__xludf.DUMMYFUNCTION("IFERROR( INDEX( FILTER(X9:BK9, ISNUMBER(X9:BK9)), COUNTA(FILTER(X9:BK9, ISNUMBER(X9:BK9))) ), BK9 )"),1.0) -> 1
A10: 70 | B10: STONE | C10: STONE | D10: STONE | F10: =IFERROR(VLOOKUP(M10:M83,'R22 RELATÓRIO ACC'!B:F,5,FALSE),"NOT PUBLISHED") -> V10 | G10: =IFERROR(VLOOKUP(M10:M81,'R22 RELATÓRIO ACC'!B:P,15,FALSE),"NOT PUBLISHED") -> 11/05/2026 | H10: =IFERROR(VLOOKUP(N10:N83,'RELATÓRIO ACC'!B:F,5,FALSE),"NOT PUBLISHED") -> V3 | I10: =IFERROR(VLOOKUP(N10:N81,'RELATÓRIO ACC'!B:P,15,FALSE),"NOT PUBLISHED") -> 09/06/2026 | J10: 46182 | K10: V3 | M10: CPQ11-ARCH-STON-SITE-R23.rvt | N10: CPQ11-ARCH-STON-SITE-R24.rvt | O10: ARCH-STON-SITE | P10: FALSE | X10: NOT PUBLISHED | Y10: NOT PUBLISHED | Z10: NOT PUBLISHED | AA10: NOT PUBLISHED | AB10: NOT PUBLISHED | AC10: NOT PUBLISHED | AD10: NOT PUBLISHED | AE10: NOT PUBLISHED | AF10: NOT PUBLISHED | AG10: NOT PUBLISHED | AH10: NOT PUBLISHED | AI10: NOT PUBLISHED | AJ10: NOT PUBLISHED | AK10: NOT PUBLISHED | AL10: NOT PUBLISHED | AM10: NOT PUBLISHED | AN10: NOT PUBLISHED | AO10: NOT PUBLISHED | AP10: 0 | AQ10: 0.65 | AR10: OUTDATED | AS10: 0.82 | AT10: IMPROPER | AU10: 0.94 | AV10: OUTDATED | AW10: OUTDATED | AX10: OUTDATED | AY10: 0.94 | AZ10: OUTDATED | BA10: 0.88 | BB10: OUTDATED | BC10: 0.94 | BD10: OUTDATED | BE10: NEXT ROUND | BF10: 0.88 | BG10: 0.94 | BH10: NEXT ROUND | BI10: 1 | BJ10: PREVIOUSLY APPROVED | BK10: PREVIOUSLY APPROVED | BL10: PREVIOUSLY APPROVED | BM10: PREVIOUSLY APPROVED | BN10: CLOSED | BO10: PREVIOUSLY APPROVED | BP10: =IFERROR(__xludf.DUMMYFUNCTION("IFERROR( INDEX( FILTER(X10:BK10, ISNUMBER(X10:BK10)), COUNTA(FILTER(X10:BK10, ISNUMBER(X10:BK10))) ), BK10 )"),1.0) -> 1
A11: 72 | B11: FM SECURITY | C11: STONE | D11: FM SECURITY | F11: =IFERROR(VLOOKUP(M11:M84,'R22 RELATÓRIO ACC'!B:F,5,FALSE),"NOT PUBLISHED") -> V2 | G11: =IFERROR(VLOOKUP(M11:M82,'R22 RELATÓRIO ACC'!B:P,15,FALSE),"NOT PUBLISHED") -> 07/05/2026 | H11: =IFERROR(VLOOKUP(N11:N84,'RELATÓRIO ACC'!B:F,5,FALSE),"NOT PUBLISHED") -> V5 | I11: =IFERROR(VLOOKUP(N11:N82,'RELATÓRIO ACC'!B:P,15,FALSE),"NOT PUBLISHED") -> 08/07/2026 | J11: 16/06/2026 | K11: V2 | M11: CPQ11-SCTY-GATE-SITE-R24.rvt | N11: CPQ11-SCTY-GATE-SITE-R24.rvt | O11: ARCH-OHCD-DATA | P11: FALSE | X11: NOT PUBLISHED | Y11: NOT PUBLISHED | Z11: NOT PUBLISHED | AA11: NOT PUBLISHED | AB11: NOT PUBLISHED | AC11: NOT PUBLISHED | AD11: NOT PUBLISHED | AE11: NOT PUBLISHED | AF11: NOT PUBLISHED | AG11: NOT PUBLISHED | AH11: NOT PUBLISHED | AI11: NOT PUBLISHED | AJ11: NOT PUBLISHED | AK11: NOT PUBLISHED | AL11: NOT PUBLISHED | AM11: NOT PUBLISHED | AN11: NOT PUBLISHED | AO11: NOT PUBLISHED | AP11: NOT PUBLISHED | AQ11: NOT PUBLISHED | AR11: NOT PUBLISHED | AS11: NOT PUBLISHED | AT11: NOT PUBLISHED | AU11: NOT PUBLISHED | AV11: NOT PUBLISHED | AW11: NOT PUBLISHED | AX11: NOT PUBLISHED | AY11: NOT PUBLISHED | AZ11: NOT PUBLISHED | BA11: 0.47 | BB11: OUTDATED | BC11: OUTDATED | BD11: NEXT ROUND | BE11: 0.65 | BF11: OUTDATED | BG11: OUTDATED | BH11: OUTDATED | BI11: 1 | BJ11: PREVIOUSLY APPROVED | BK11: PREVIOUSLY APPROVED | BL11: PREVIOUSLY APPROVED | BM11: PREVIOUSLY APPROVED | BN11: CLOSED | BO11: PREVIOUSLY APPROVED | BP11: =IFERROR(__xludf.DUMMYFUNCTION("IFERROR( INDEX( FILTER(X11:BK11, ISNUMBER(X11:BK11)), COUNTA(FILTER(X11:BK11, ISNUMBER(X11:BK11))) ), BK11 )"),1.0) -> 1
A12: 74 | B12: MODAX | D12: MODAX | F12: =IFERROR(VLOOKUP(M12:M85,'R22 RELATÓRIO ACC'!B:F,5,FALSE),"NOT PUBLISHED") -> V1 | G12: =IFERROR(VLOOKUP(M12:M83,'R22 RELATÓRIO ACC'!B:P,15,FALSE),"NOT PUBLISHED") -> 05/05/2026 | H12: =IFERROR(VLOOKUP(N12:N85,'RELATÓRIO ACC'!B:F,5,FALSE),"NOT PUBLISHED") -> V2 | I12: =IFERROR(VLOOKUP(N12:N83,'RELATÓRIO ACC'!B:P,15,FALSE),"NOT PUBLISHED") -> 26/05/2026 | J12: 26/05/2026 | K12: V2 | M12: CPQ11-STRC-FLOO-SITE-R22.rvt | N12: CPQ11-STRC-FLOO-SITE-R24.rvt | P12: FALSE | X12: NOT PUBLISHED | Y12: NOT PUBLISHED | Z12: NOT PUBLISHED | AA12: NOT PUBLISHED | AB12: NOT PUBLISHED | AC12: NOT PUBLISHED | AD12: NOT PUBLISHED | AE12: NOT PUBLISHED | AF12: NOT PUBLISHED | AG12: NOT PUBLISHED | AH12: NOT PUBLISHED | AI12: NOT PUBLISHED | AJ12: NOT PUBLISHED | AK12: NOT PUBLISHED | AL12: NOT PUBLISHED | AM12: NOT PUBLISHED | AN12: NOT PUBLISHED | AO12: NOT PUBLISHED | AP12: NOT PUBLISHED | AQ12: NOT PUBLISHED | AR12: NOT PUBLISHED | AS12: NOT PUBLISHED | AT12: NOT PUBLISHED | AU12: NOT PUBLISHED | AV12: NOT PUBLISHED | AW12: NOT PUBLISHED | AX12: NOT PUBLISHED | AY12: NOT PUBLISHED | AZ12: NOT PUBLISHED | BA12: NOT PUBLISHED | BB12: NOT PUBLISHED | BC12: NOT PUBLISHED | BD12: NEXT ROUND | BE12: 0.82 | BF12: OUTDATED | BG12: NEXT ROUND | BH12: 1 | BI12: PREVIOUSLY APPROVED | BJ12: PREVIOUSLY APPROVED | BK12: PREVIOUSLY APPROVED | BL12: PREVIOUSLY APPROVED | BM12: PREVIOUSLY APPROVED | BN12: CLOSED | BO12: PREVIOUSLY APPROVED | BP12: =IFERROR(__xludf.DUMMYFUNCTION("IFERROR( INDEX( FILTER(X12:BK12, ISNUMBER(X12:BK12)), COUNTA(FILTER(X12:BK12, ISNUMBER(X12:BK12))) ), BK12 )"),1.0) -> 1
A13: 27 | B13: MENDES HOLLER | C13: 1112 | D13: MENDES HOLLER | E13: 1112 | F13: =IFERROR(VLOOKUP(M13:M86,'R22 RELATÓRIO ACC'!B:F,5,FALSE),"NOT PUBLISHED") -> V11 | G13: =IFERROR(VLOOKUP(M13:M84,'R22 RELATÓRIO ACC'!B:P,15,FALSE),"NOT PUBLISHED") -> 08/05/2026 | H13: =IFERROR(VLOOKUP(N13:N86,'RELATÓRIO ACC'!B:F,5,FALSE),"NOT PUBLISHED") -> V3 | I13: =IFERROR(VLOOKUP(N13:N84,'RELATÓRIO ACC'!B:P,15,FALSE),"NOT PUBLISHED") -> 10/07/2026 | J13: 08/05/2026 | K13: V11 | L13: CONTINUA MESMA VERSÃO | M13: CPQ11-FALM-FALM-SITE-R22.rvt | N13: CPQ11-FALM-FALM-SITE-R24.rvt | O13: FALM-FALM-SITE | P13: FALSE | Q13: ABERTO | R13: FOI AUDITADO R7 | W13: 45874 | X13: NOT PUBLISHED | Y13: NOT PUBLISHED | Z13: NOT PUBLISHED | AA13: NOT PUBLISHED | AB13: NOT PUBLISHED | AC13: NOT PUBLISHED | AD13: 0.88 | AE13: OUTDATED | AF13: OUTDATED | AG13: OUTDATED | AH13: OUTDATED | AI13: OUTDATED | AJ13: OUTDATED | AK13: OUTDATED | AL13: OUTDATED | AM13: OUTDATED | AN13: 0.94 | AO13: 0.94 | AP13: OUTDATED | AQ13: 0.94 | AR13: OUTDATED | AS13: 0.88 | AT13: OUTDATED | AU13: 0.94 | AV13: OUTDATED | AW13: NEXT ROUND | AX13: 0.88 | AY13: OUTDATED | AZ13: 0.88 | BA13: OUTDATED | BB13: OUTDATED | BC13: OUTDATED | BD13: NEXT ROUND | BE13: 1 | BF13: PREVIOUSLY APPROVED | BG13: PREVIOUSLY APPROVED | BH13: PREVIOUSLY APPROVED | BI13: PREVIOUSLY APPROVED | BJ13: PREVIOUSLY APPROVED | BK13: PREVIOUSLY APPROVED | BL13: PREVIOUSLY APPROVED | BM13: PREVIOUSLY APPROVED | BN13: CLOSED | BO13: PREVIOUSLY APPROVED | BP13: =IFERROR(__xludf.DUMMYFUNCTION("IFERROR( INDEX( FILTER(X13:BK13, ISNUMBER(X13:BK13)), COUNTA(FILTER(X13:BK13, ISNUMBER(X13:BK13))) ), BK13 )"),1.0) -> 1
A14: 1 | B14: ARE ARQUITETURA | C14: 1130 | D14: ARE ARQUITETURA | E14: 1130 | F14: =IFERROR(VLOOKUP(M14:M87,'R22 RELATÓRIO ACC'!B:F,5,FALSE),"NOT PUBLISHED") -> V28 | G14: =IFERROR(VLOOKUP(M14:M85,'R22 RELATÓRIO ACC'!B:P,15,FALSE),"NOT PUBLISHED") -> 17/04/2026 | H14: =IFERROR(VLOOKUP(N14:N87,'RELATÓRIO ACC'!B:F,5,FALSE),"NOT PUBLISHED") -> V4 | I14: =IFERROR(VLOOKUP(N14:N85,'RELATÓRIO ACC'!B:P,15,FALSE),"NOT PUBLISHED") -> 15/07/2026 | J14: 45971 | K14: V20 | L14: MODELO FOI ATUALIZADO | M14: CPQ11-ARCH-ARCH-SITE-R22.rvt | N14: CPQ11-ARCH-ARCH-SITE-R24.rvt | O14: ARCH-ARCH-SITE | P14: FALSE | Q14: ABERTO | R14: FOI AUDITADO R8 | S14: FINALIZADO | T14: FINALIZADO | U14: ALINNE | V14: 45944 | W14: 45944 | X14: NOT PUBLISHED | Y14: NOT PUBLISHED | Z14: 0.5 | AA14: 0.63 | AB14: 0.82 | AC14: 1 | AD14: 0.94 | AE14: 0.94 | AF14: OUTDATED | AG14: OUTDATED | AH14: 0.94 | AI14: 0.94 | AJ14: OUTDATED | AK14: 1 | AL14: 1 | AM14: 1 | AN14: 1 | AO14: 1 | AP14: 1 | AQ14: 1 | AR14: 1 | AS14: 1 | AT14: 1 | AU14: 1 | AV14: 1 | AW14: 1 | AX14: 1 | AY14: 1 | AZ14: 1 | BA14: PREVIOUSLY APPROVED | BB14: PREVIOUSLY APPROVED | BC14: PREVIOUSLY APPROVED | BD14: PREVIOUSLY APPROVED | BE14: PREVIOUSLY APPROVED | BF14: PREVIOUSLY APPROVED | BG14: PREVIOUSLY APPROVED | BH14: PREVIOUSLY APPROVED | BI14: PREVIOUSLY APPROVED | BJ14: PREVIOUSLY APPROVED | BK14: PREVIOUSLY APPROVED | BL14: PREVIOUSLY APPROVED | BM14: PREVIOUSLY APPROVED | BN14: CLOSED | BO14: PREVIOUSLY APPROVED | BP14: =IFERROR(__xludf.DUMMYFUNCTION("IFERROR( INDEX( FILTER(X14:BK14, ISNUMBER(X14:BK14)), COUNTA(FILTER(X14:BK14, ISNUMBER(X14:BK14))) ), BK14 )"),1.0) -> 1
A15: 2 | B15: TENAX | D15: TENAX | F15: =IFERROR(VLOOKUP(M15:M88,'R22 RELATÓRIO ACC'!B:F,5,FALSE),"NOT PUBLISHED") -> V10 | G15: =IFERROR(VLOOKUP(M15:M86,'R22 RELATÓRIO ACC'!B:P,15,FALSE),"NOT PUBLISHED") -> 22/04/2026 | H15: =IFERROR(VLOOKUP(N15:N88,'RELATÓRIO ACC'!B:F,5,FALSE),"NOT PUBLISHED") -> V1 | I15: =IFERROR(VLOOKUP(N15:N86,'RELATÓRIO ACC'!B:P,15,FALSE),"NOT PUBLISHED") -> 15/05/2026 | J15: 45957 | K15: V5 | L15: MODELO FOI ATUALIZADO | M15: CPQ11-STRC-CONC-DATA-R22.rvt | N15: CPQ11-STRC-CONC-DATA-R24.rvt | O15: STRC-CONC-DATA | P15: FALSE | Q15: ABERTO | R15: FOI AUDITADO R8 | S15: FINALIZADO | T15: FINALIZADO | U15: ALINNE | V15: 45944 | W15: 45944 | X15: NOT PUBLISHED | Y15: NOT PUBLISHED | Z15: NOT PUBLISHED | AA15: NOT PUBLISHED | AB15: NOT PUBLISHED | AC15: 0.41 | AD15: OUTDATED | AE15: 0.88 | AF15: OUTDATED | AG15: OUTDATED | AH15: 0.94 | AI15: OUTDATED | AJ15: 1 | AK15: 1 | AL15: 1 | AM15: 1 | AN15: 1 | AO15: 1 | AP15: 1 | AQ15: 1 | AR15: 1 | AS15: 1 | AT15: 1 | AU15: 1 | AV15: 1 | AW15: 1 | AX15: 1 | AY15: 1 | AZ15: 1 | BA15: PREVIOUSLY APPROVED | BB15: PREVIOUSLY APPROVED | BC15: PREVIOUSLY APPROVED | BD15: PREVIOUSLY APPROVED | BE15: PREVIOUSLY APPROVED | BF15: PREVIOUSLY APPROVED | BG15: PREVIOUSLY APPROVED | BH15: PREVIOUSLY APPROVED | BI15: PREVIOUSLY APPROVED | BJ15: PREVIOUSLY APPROVED | BK15: PREVIOUSLY APPROVED | BL15: PREVIOUSLY APPROVED | BM15: PREVIOUSLY APPROVED | BN15: CLOSED | BO15: PREVIOUSLY APPROVED | BP15: =IFERROR(__xludf.DUMMYFUNCTION("IFERROR( INDEX( FILTER(X15:BK15, ISNUMBER(X15:BK15)), COUNTA(FILTER(X15:BK15, ISNUMBER(X15:BK15))) ), BK15 )"),1.0) -> 1
A16: 3 | B16: ALTAMIRA | D16: ALTAMIRA | F16: =IFERROR(VLOOKUP(M16:M89,'R22 RELATÓRIO ACC'!B:F,5,FALSE),"NOT PUBLISHED") -> V9 | G16: =IFERROR(VLOOKUP(M16:M87,'R22 RELATÓRIO ACC'!B:P,15,FALSE),"NOT PUBLISHED") -> 28/02/2026 | H16: =IFERROR(VLOOKUP(N16:N89,'RELATÓRIO ACC'!B:F,5,FALSE),"NOT PUBLISHED") -> V1 | I16: =IFERROR(VLOOKUP(N16:N87,'RELATÓRIO ACC'!B:P,15,FALSE),"NOT PUBLISHED") -> 20/05/2026 | J16: 45970 | K16: V7 | L16: CONTINUA MESMA VERSÃO | M16: CPQ11-ARCH-SHLV-DATA-R22.rvt | N16: CPQ11-ARCH-SHLV-DATA-R24.rvt | O16: ARCH-SHLV-DATA | P16: FALSE | Q16: ABERTO | R16: FOI AUDITADO R9 | V16: 45923 | W16: 45923 | X16: NOT PUBLISHED | Y16: NOT PUBLISHED | Z16: NOT PUBLISHED | AA16: NOT PUBLISHED | AB16: NOT PUBLISHED | AC16: NOT PUBLISHED | AD16: NOT PUBLISHED | AE16: 0.82 | AF16: 0.82 | AG16: OUTDATED | AH16: OUTDATED | AI16: OUTDATED | AJ16: 0.94 | AK16: 1 | AL16: 1 | AM16: 1 | AN16: 1 | AO16: 1 | AP16: 1 | AQ16: 1 | AR16: 1 | AS16: 1 | AT16: 1 | AU16: 1 | AV16: 1 | AW16: 1 | AX16: 1 | AY16: 1 | AZ16: 1 | BA16: PREVIOUSLY APPROVED | BB16: PREVIOUSLY APPROVED | BC16: PREVIOUSLY APPROVED | BD16: PREVIOUSLY APPROVED | BE16: PREVIOUSLY APPROVED | BF16: PREVIOUSLY APPROVED | BG16: PREVIOUSLY APPROVED | BH16: PREVIOUSLY APPROVED | BI16: PREVIOUSLY APPROVED | BJ16: PREVIOUSLY APPROVED | BK16: PREVIOUSLY APPROVED | BL16: PREVIOUSLY APPROVED | BM16: PREVIOUSLY APPROVED | BN16: CLOSED | BO16: PREVIOUSLY APPROVED | BP16: =IFERROR(__xludf.DUMMYFUNCTION("IFERROR( INDEX( FILTER(X16:BK16, ISNUMBER(X16:BK16)), COUNTA(FILTER(X16:BK16, ISNUMBER(X16:BK16))) ), BK16 )"),1.0) -> 1
A17: 4 | B17: IDEIA DRYWALL | C17: 1101 | D17: FCH | E17: 1126 | F17: =IFERROR(VLOOKUP(M17:M90,'R22 RELATÓRIO ACC'!B:F,5,FALSE),"NOT PUBLISHED") -> V14 | G17: =IFERROR(VLOOKUP(M17:M88,'R22 RELATÓRIO ACC'!B:P,15,FALSE),"NOT PUBLISHED") -> 30/01/2026 | H17: =IFERROR(VLOOKUP(N17:N90,'RELATÓRIO ACC'!B:F,5,FALSE),"NOT PUBLISHED") -> V1 | I17: =IFERROR(VLOOKUP(N17:N88,'RELATÓRIO ACC'!B:P,15,FALSE),"NOT PUBLISHED") -> 19/05/2026 | J17: 45671 | K17: V12 | L17: CONTINUA MESMA VERSÃO | M17: CPQ11-ARCH-PART-C345-R22.rvt | N17: CPQ11-ARCH-PART-C345-R24.rvt | O17: ARCH-PART-C345 | P17: FALSE | Q17: ABERTO | R17: FOI AUDITADO R8 | S17: FINALIZADO | T17: FINALIZADO | U17: IURY | V17: 45951 | W17: 45951 | X17: NOT PUBLISHED | Y17: 0.5 | Z17: 0.47 | AA17: 0.5 | AB17: OUTDATED | AC17: 0.65 | AD17: 0.82 | AE17: 0.76 | AF17: OUTDATED | AG17: OUTDATED | AH17: OUTDATED | AI17: 0.82 | AJ17: OUTDATED | AK17: OUTDATED | AL17: OUTDATED | AM17: OUTDATED | AN17: OUTDATED | AO17: 1 | AP17: 1 | AQ17: 1 | AR17: 1 | AS17: 1 | AT17: 1 | AU17: 1 | AV17: 1 | AW17: 1 | AX17: 1 | AY17: 1 | AZ17: 1 | BA17: PREVIOUSLY APPROVED | BB17: PREVIOUSLY APPROVED | BC17: PREVIOUSLY APPROVED | BD17: PREVIOUSLY APPROVED | BE17: PREVIOUSLY APPROVED | BF17: PREVIOUSLY APPROVED | BG17: PREVIOUSLY APPROVED | BH17: PREVIOUSLY APPROVED | BI17: PREVIOUSLY APPROVED | BJ17: PREVIOUSLY APPROVED | BK17: PREVIOUSLY APPROVED | BL17: PREVIOUSLY APPROVED | BM17: PREVIOUSLY APPROVED | BN17: CLOSED | BO17: PREVIOUSLY APPROVED | BP17: =IFERROR(__xludf.DUMMYFUNCTION("IFERROR( INDEX( FILTER(X17:BK17, ISNUMBER(X17:BK17)), COUNTA(FILTER(X17:BK17, ISNUMBER(X17:BK17))) ), BK17 )"),1.0) -> 1
A18: 5 | B18: TENAX | D18: TENAX | F18: =IFERROR(VLOOKUP(M18:M91,'R22 RELATÓRIO ACC'!B:F,5,FALSE),"NOT PUBLISHED") -> V11 | G18: =IFERROR(VLOOKUP(M18:M89,'R22 RELATÓRIO ACC'!B:P,15,FALSE),"NOT PUBLISHED") -> 28/04/2026 | H18: =IFERROR(VLOOKUP(N18:N91,'RELATÓRIO ACC'!B:F,5,FALSE),"NOT PUBLISHED") -> V1 | I18: =IFERROR(VLOOKUP(N18:N89,'RELATÓRIO ACC'!B:P,15,FALSE),"NOT PUBLISHED") -> 15/05/2026 | J18: 45938 | K18: V4 | L18: MODELO FOI ATUALIZADO | M18: CPQ11-STRC-DPFN-DATA-R22.rvt | N18: CPQ11-STRC-DPFN-DATA-R24.rvt | O18: STRC-DPFN-DATA | P18: FALSE | Q18: ABERTO | R18: FOI AUDITADO R8 | S18: FINALIZADO | T18: FINALIZADO | U18: IURY | V18: 45944 | W18: 45944 | X18: NOT PUBLISHED | Y18: NOT PUBLISHED | Z18: NOT PUBLISHED | AA18: NOT PUBLISHED | AB18: NOT PUBLISHED | AC18: 0.41 | AD18: OUTDATED | AE18: 0.88 | AF18: OUTDATED | AG18: OUTDATED | AH18: 1 | AI18: 1 | AJ18: 1 | AK18: 1 | AL18: 1 | AM18: 1 | AN18: 1 | AO18: 1 | AP18: 1 | AQ18: 1 | AR18: 1 | AS18: 1 | AT18: 1 | AU18: 1 | AV18: 1 | AW18: 1 | AX18: 1 | AY18: 1 | AZ18: 1 | BA18: PREVIOUSLY APPROVED | BB18: PREVIOUSLY APPROVED | BC18: PREVIOUSLY APPROVED | BD18: PREVIOUSLY APPROVED | BE18: PREVIOUSLY APPROVED | BF18: PREVIOUSLY APPROVED | BG18: PREVIOUSLY APPROVED | BH18: PREVIOUSLY APPROVED | BI18: PREVIOUSLY APPROVED | BJ18: PREVIOUSLY APPROVED | BK18: PREVIOUSLY APPROVED | BL18: PREVIOUSLY APPROVED | BM18: PREVIOUSLY APPROVED | BN18: CLOSED | BO18: PREVIOUSLY APPROVED | BP18: =IFERROR(__xludf.DUMMYFUNCTION("IFERROR( INDEX( FILTER(X18:BK18, ISNUMBER(X18:BK18)), COUNTA(FILTER(X18:BK18, ISNUMBER(X18:BK18))) ), BK18 )"),1.0) -> 1
A19: 6 | B19: INOVAGLASS | C19: 1109 | D19: INOVAGLASS | E19: 1109 | F19: =IFERROR(VLOOKUP(M19:M92,'R22 RELATÓRIO ACC'!B:F,5,FALSE),"NOT PUBLISHED") -> V9 | G19: =IFERROR(VLOOKUP(M19:M90,'R22 RELATÓRIO ACC'!B:P,15,FALSE),"NOT PUBLISHED") -> 04/12/2025 | H19: =IFERROR(VLOOKUP(N19:N92,'RELATÓRIO ACC'!B:F,5,FALSE),"NOT PUBLISHED") -> V1 | I19: =IFERROR(VLOOKUP(N19:N90,'RELATÓRIO ACC'!B:P,15,FALSE),"NOT PUBLISHED") -> 20/05/2026 | J19: 45841 | K19: V5 | L19: MODELO FOI ATUALIZADO | M19: CPQ11-ARCH-BLPR-GUAR-R22.rvt | N19: CPQ11-ARCH-BLPR-GUAR-R24.rvt | O19: ARCH-BLPR-GUAR | P19: FALSE | Q19: FECHADA | R19: FOI AUDITADO R6 | W19: 45849 | X19: NOT PUBLISHED | Y19: NOT PUBLISHED | Z19: 0.69 | AA19: OUTDATED | AB19: 0.71 | AC19: 1 | AD19: 1 | AE19: 1 | AF19: 1 | AG19: 1 | AH19: 1 | AI19: 1 | AJ19: 1 | AK19: 1 | AL19: 1 | AM19: 1 | AN19: 1 | AO19: 1 | AP19: 1 | AQ19: 1 | AR19: 1 | AS19: 1 | AT19: 1 | AU19: 1 | AV19: 1 | AW19: 1 | AX19: 1 | AY19: 1 | AZ19: 1 | BA19: PREVIOUSLY APPROVED | BB19: PREVIOUSLY APPROVED | BC19: PREVIOUSLY APPROVED | BD19: PREVIOUSLY APPROVED | BE19: PREVIOUSLY APPROVED | BF19: PREVIOUSLY APPROVED | BG19: PREVIOUSLY APPROVED | BH19: PREVIOUSLY APPROVED | BI19: PREVIOUSLY APPROVED | BJ19: PREVIOUSLY APPROVED | BK19: PREVIOUSLY APPROVED | BL19: PREVIOUSLY APPROVED | BM19: PREVIOUSLY APPROVED | BN19: CLOSED | BO19: PREVIOUSLY APPROVED | BP19: =IFERROR(__xludf.DUMMYFUNCTION("IFERROR( INDEX( FILTER(X19:BK19, ISNUMBER(X19:BK19)), COUNTA(FILTER(X19:BK19, ISNUMBER(X19:BK19))) ), BK19 )"),1.0) -> 1
A20: 7 | B20: TENAX | D20: TENAX | F20: =IFERROR(VLOOKUP(M20:M93,'R22 RELATÓRIO ACC'!B:F,5,FALSE),"NOT PUBLISHED") -> V13 | G20: =IFERROR(VLOOKUP(M20:M91,'R22 RELATÓRIO ACC'!B:P,15,FALSE),"NOT PUBLISHED") -> 12/05/2026 | H20: =IFERROR(VLOOKUP(N20:N93,'RELATÓRIO ACC'!B:F,5,FALSE),"NOT PUBLISHED") -> V1 | I20: =IFERROR(VLOOKUP(N20:N91,'RELATÓRIO ACC'!B:P,15,FALSE),"NOT PUBLISHED") -> 15/05/2026 | J20: 45940 | K20: V4 | L20: MODELO FOI ATUALIZADO | M20: CPQ11-STRC-DPFN-SITE-R22.rvt | N20: CPQ11-STRC-DPFN-SITE-R24.rvt | O20: STRC-DPFN-SITE | P20: FALSE | Q20: ABERTO | R20: FOI AUDITADO R8 | S20: INICIADO | T20: INICIADO | U20: ALINNE | V20: 45945 | W20: 45945 | X20: NOT PUBLISHED | Y20: NOT PUBLISHED | Z20: NOT PUBLISHED | AA20: NOT PUBLISHED | AB20: NOT PUBLISHED | AC20: NOT PUBLISHED | AD20: 0.82 | AE20: 0.82 | AF20: OUTDATED | AG20: OUTDATED | AH20: 1 | AI20: 1 | AJ20: 1 | AK20: 1 | AL20: 1 | AM20: 1 | AN20: 1 | AO20: 1 | AP20: 1 | AQ20: 1 | AR20: 1 | AS20: 1 | AT20: 1 | AU20: 1 | AV20: 1 | AW20: 1 | AX20: 1 | AY20: 1 | AZ20: 1 | BA20: PREVIOUSLY APPROVED | BB20: PREVIOUSLY APPROVED | BC20: PREVIOUSLY APPROVED | BD20: PREVIOUSLY APPROVED | BE20: PREVIOUSLY APPROVED | BF20: PREVIOUSLY APPROVED | BG20: PREVIOUSLY APPROVED | BH20: PREVIOUSLY APPROVED | BI20: PREVIOUSLY APPROVED | BJ20: PREVIOUSLY APPROVED | BK20: PREVIOUSLY APPROVED | BL20: PREVIOUSLY APPROVED | BM20: PREVIOUSLY APPROVED | BN20: CLOSED | BO20: PREVIOUSLY APPROVED | BP20: =IFERROR(__xludf.DUMMYFUNCTION("IFERROR( INDEX( FILTER(X20:BK20, ISNUMBER(X20:BK20)), COUNTA(FILTER(X20:BK20, ISNUMBER(X20:BK20))) ), BK20 )"),1.0) -> 1
A21: 8 | B21: GARCIA | D21: CADBIM | F21: =IFERROR(VLOOKUP(M21:M94,'R22 RELATÓRIO ACC'!B:F,5,FALSE),"NOT PUBLISHED") -> V18 | G21: =IFERROR(VLOOKUP(M21:M92,'R22 RELATÓRIO ACC'!B:P,15,FALSE),"NOT PUBLISHED") -> 30/04/2026 | H21: =IFERROR(VLOOKUP(N21:N94,'RELATÓRIO ACC'!B:F,5,FALSE),"NOT PUBLISHED") -> V2 | I21: =IFERROR(VLOOKUP(N21:N92,'RELATÓRIO ACC'!B:P,15,FALSE),"NOT PUBLISHED") -> 20/05/2026 | J21: 45939 | K21: V3 | L21: MODELO FOI ATUALIZADO | M21: CPQ11-CIVL-PAVM-SITE-R22.rvt | N21: CPQ11-CIVL-PAVM-SITE-R24.rvt | O21: CIVL-PAVM-SITE | P21: FALSE | Q21: ABERTO | R21: FOI AUDITADO R9 | S21: FINALIZADO | T21: FINALIZADO | U21: IURY | V21: 45944 | W21: 45944 | X21: NOT PUBLISHED | Y21: NOT PUBLISHED | Z21: NOT PUBLISHED | AA21: NOT PUBLISHED | AB21: NOT PUBLISHED | AC21: NOT PUBLISHED | AD21: NOT PUBLISHED | AE21: NOT PUBLISHED | AF21: 0.71 | AG21: OUTDATED | AH21: 1 | AI21: 1 | AJ21: 1 | AK21: 1 | AL21: 1 | AM21: 1 | AN21: 1 | AO21: 1 | AP21: 1 | AQ21: 1 | AR21: 1 | AS21: 1 | AT21: 1 | AU21: 1 | AV21: 1 | AW21: 1 | AX21: 1 | AY21: 1 | AZ21: 1 | BA21: PREVIOUSLY APPROVED | BB21: PREVIOUSLY APPROVED | BC21: PREVIOUSLY APPROVED | BD21: PREVIOUSLY APPROVED | BE21: PREVIOUSLY APPROVED | BF21: PREVIOUSLY APPROVED | BG21: PREVIOUSLY APPROVED | BH21: PREVIOUSLY APPROVED | BI21: PREVIOUSLY APPROVED | BJ21: PREVIOUSLY APPROVED | BK21: PREVIOUSLY APPROVED | BL21: PREVIOUSLY APPROVED | BM21: PREVIOUSLY APPROVED | BN21: CLOSED | BO21: PREVIOUSLY APPROVED | BP21: =IFERROR(__xludf.DUMMYFUNCTION("IFERROR( INDEX( FILTER(X21:BK21, ISNUMBER(X21:BK21)), COUNTA(FILTER(X21:BK21, ISNUMBER(X21:BK21))) ), BK21 )"),1.0) -> 1
A22: 9 | B22: PORTEX | D22: SPBIM | F22: =IFERROR(VLOOKUP(M22:M95,'R22 RELATÓRIO ACC'!B:F,5,FALSE),"NOT PUBLISHED") -> V9 | G22: =IFERROR(VLOOKUP(M22:M93,'R22 RELATÓRIO ACC'!B:P,15,FALSE),"NOT PUBLISHED") -> 27/03/2026 | H22: =IFERROR(VLOOKUP(N22:N95,'RELATÓRIO ACC'!B:F,5,FALSE),"NOT PUBLISHED") -> V2 | I22: =IFERROR(VLOOKUP(N22:N93,'RELATÓRIO ACC'!B:P,15,FALSE),"NOT PUBLISHED") -> 26/06/2026 | J22: 45783 | K22: V1 | L22: MODELO FOI ATUALIZADO | M22: CPQ11-ARCH-HM90-DATA-R22.rvt | N22: CPQ11-ARCH-HM90-DATA-R24.rvt | O22: ARCH-HM90-DATA | P22: FALSE | Q22: NÃO POSSUI ISSUE | R22: FOI AUDITADO R7 | S22: INICIADO | U22: IURY | V22: 45926 | W22: 45876 | X22: NOT PUBLISHED | Y22: NOT PUBLISHED | Z22: NOT PUBLISHED | AA22: NOT PUBLISHED | AB22: 1 | AC22: OUTDATED | AD22: 1 | AE22: 1 | AF22: 1 | AG22: 1 | AH22: 1 | AI22: 1 | AJ22: 1 | AK22: 1 | AL22: 1 | AM22: 1 | AN22: 1 | AO22: 1 | AP22: 1 | AQ22: 1 | AR22: 1 | AS22: 1 | AT22: 1 | AU22: 1 | AV22: 1 | AW22: 1 | AX22: 1 | AY22: 1 | AZ22: 1 | BA22: PREVIOUSLY APPROVED | BB22: PREVIOUSLY APPROVED | BC22: PREVIOUSLY APPROVED | BD22: PREVIOUSLY APPROVED | BE22: PREVIOUSLY APPROVED | BF22: PREVIOUSLY APPROVED | BG22: PREVIOUSLY APPROVED | BH22: PREVIOUSLY APPROVED | BI22: PREVIOUSLY APPROVED | BJ22: PREVIOUSLY APPROVED | BK22: PREVIOUSLY APPROVED | BL22: PREVIOUSLY APPROVED | BM22: PREVIOUSLY APPROVED | BN22: CLOSED | BO22: PREVIOUSLY APPROVED | BP22: =IFERROR(__xludf.DUMMYFUNCTION("IFERROR( INDEX( FILTER(X22:BK22, ISNUMBER(X22:BK22)), COUNTA(FILTER(X22:BK22, ISNUMBER(X22:BK22))) ), BK22 )"),1.0) -> 1
A23: 10 | B23: GARCIA | D23: CADBIM | F23: =IFERROR(VLOOKUP(M23:M96,'R22 RELATÓRIO ACC'!B:F,5,FALSE),"NOT PUBLISHED") -> V20 | G23: =IFERROR(VLOOKUP(M23:M94,'R22 RELATÓRIO ACC'!B:P,15,FALSE),"NOT PUBLISHED") -> 06/05/2026 | H23: =IFERROR(VLOOKUP(N23:N96,'RELATÓRIO ACC'!B:F,5,FALSE),"NOT PUBLISHED") -> V4 | I23: =IFERROR(VLOOKUP(N23:N94,'RELATÓRIO ACC'!B:P,15,FALSE),"NOT PUBLISHED") -> 11/06/2026 | J23: 45935 | K23: V3 | L23: MODELO FOI ATUALIZADO | M23: CPQ11-CIVL-DRNG-SITE-R22.rvt | N23: CPQ11-CIVL-DRNG-SITE-R24.rvt | O23: CIVL-DRNG-SITE | P23: FALSE | Q23: ABERTO | R23: FOI AUDITADO R9 | S23: FINALIZADO | T23: FINALIZADO | U23: IURY | V23: 45944 | W23: 45944 | X23: NOT PUBLISHED | Y23: NOT PUBLISHED | Z23: NOT PUBLISHED | AA23: NOT PUBLISHED | AB23: NOT PUBLISHED | AC23: NOT PUBLISHED | AD23: NOT PUBLISHED | AE23: NOT PUBLISHED | AF23: 0.53 | AG23: OUTDATED | AH23: 1 | AI23: 1 | AJ23: 1 | AK23: 1 | AL23: 1 | AM23: 1 | AN23: 1 | AO23: 1 | AP23: 1 | AQ23: 1 | AR23: 1 | AS23: 1 | AT23: 1 | AU23: 1 | AV23: 1 | AW23: 1 | AX23: 1 | AY23: 1 | AZ23: 1 | BA23: PREVIOUSLY APPROVED | BB23: PREVIOUSLY APPROVED | BC23: PREVIOUSLY APPROVED | BD23: PREVIOUSLY APPROVED | BE23: PREVIOUSLY APPROVED | BF23: PREVIOUSLY APPROVED | BG23: PREVIOUSLY APPROVED | BH23: PREVIOUSLY APPROVED | BI23: PREVIOUSLY APPROVED | BJ23: PREVIOUSLY APPROVED | BK23: PREVIOUSLY APPROVED | BL23: PREVIOUSLY APPROVED | BM23: PREVIOUSLY APPROVED | BN23: CLOSED | BO23: PREVIOUSLY APPROVED | BP23: =IFERROR(__xludf.DUMMYFUNCTION("IFERROR( INDEX( FILTER(X23:BK23, ISNUMBER(X23:BK23)), COUNTA(FILTER(X23:BK23, ISNUMBER(X23:BK23))) ), BK23 )"),1.0) -> 1
A24: 11 | B24: TENAX | D24: TENAX | F24: =IFERROR(VLOOKUP(M24:M97,'R22 RELATÓRIO ACC'!B:F,5,FALSE),"NOT PUBLISHED") -> V17 | G24: =IFERROR(VLOOKUP(M24:M95,'R22 RELATÓRIO ACC'!B:P,15,FALSE),"NOT PUBLISHED") -> 12/05/2026 | H24: =IFERROR(VLOOKUP(N24:N97,'RELATÓRIO ACC'!B:F,5,FALSE),"NOT PUBLISHED") -> V1 | I24: =IFERROR(VLOOKUP(N24:N95,'RELATÓRIO ACC'!B:P,15,FALSE),"NOT PUBLISHED") -> 15/05/2026 | J24: 45919 | K24: V5 | L24: MODELO FOI ATUALIZADO | M24: CPQ11-STRC-CONC-SITE-R22.rvt | N24: CPQ11-STRC-CONC-SITE-R24.rvt | O24: STRC-CONC-SITE | P24: FALSE | Q24: ABERTO | R24: FOI AUDITADO R9 | S24: FINALIZADO | T24: FINALIZADO | U24: ALINNE | V24: 45923 | W24: 45923 | X24: NOT PUBLISHED | Y24: NOT PUBLISHED | Z24: NOT PUBLISHED | AA24: NOT PUBLISHED | AB24: NOT PUBLISHED | AC24: 0.29 | AD24: 0.71 | AE24: 0.82 | AF24: 1 | AG24: 1 | AH24: 1 | AI24: 1 | AJ24: 1 | AK24: 1 | AL24: 1 | AM24: 1 | AN24: 1 | AO24: 1 | AP24: 1 | AQ24: 1 | AR24: 1 | AS24: 1 | AT24: 1 | AU24: 1 | AV24: 1 | AW24: 1 | AX24: 1 | AY24: 1 | AZ24: 1 | BA24: PREVIOUSLY APPROVED | BB24: PREVIOUSLY APPROVED | BC24: PREVIOUSLY APPROVED | BD24: PREVIOUSLY APPROVED | BE24: PREVIOUSLY APPROVED | BF24: PREVIOUSLY APPROVED | BG24: PREVIOUSLY APPROVED | BH24: PREVIOUSLY APPROVED | BI24: PREVIOUSLY APPROVED | BJ24: PREVIOUSLY APPROVED | BK24: PREVIOUSLY APPROVED | BL24: PREVIOUSLY APPROVED | BM24: PREVIOUSLY APPROVED | BN24: CLOSED | BO24: PREVIOUSLY APPROVED | BP24: =IFERROR(__xludf.DUMMYFUNCTION("IFERROR( INDEX( FILTER(X24:BK24, ISNUMBER(X24:BK24)), COUNTA(FILTER(X24:BK24, ISNUMBER(X24:BK24))) ), BK24 )"),1.0) -> 1
A25: 12 | B25: IDEIA DRYWALL | C25: 1101 | D25: FCH | E25: 1126 | F25: =IFERROR(VLOOKUP(M25:M98,'R22 RELATÓRIO ACC'!B:F,5,FALSE),"NOT PUBLISHED") -> V24 | G25: =IFERROR(VLOOKUP(M25:M96,'R22 RELATÓRIO ACC'!B:P,15,FALSE),"NOT PUBLISHED") -> 07/04/2026 | H25: =IFERROR(VLOOKUP(N25:N98,'RELATÓRIO ACC'!B:F,5,FALSE),"NOT PUBLISHED") -> V2 | I25: =IFERROR(VLOOKUP(N25:N96,'RELATÓRIO ACC'!B:P,15,FALSE),"NOT PUBLISHED") -> 27/05/2026 | J25: 45979 | K25: V15 | L25: CONTINUA MESMA VERSÃO | M25: CPQ11-ARCH-PART-C12A-R22.rvt | N25: CPQ11-ARCH-PART-C12A-R24.rvt | O25: ARCH-PART-C12A | P25: FALSE | Q25: ABERTO | R25: FOI AUDITADO R8 | X25: NOT PUBLISHED | Y25: 0.44 | Z25: 0.47 | AA25: 0.63 | AB25: OUTDATED | AC25: 0.71 | AD25: 0.82 | AE25: 0.88 | AF25: OUTDATED | AG25: 0.94 | AH25: OUTDATED | AI25: 0.94 | AJ25: OUTDATED | AK25: 0.94 | AL25: 0.94 | AM25: 1 | AN25: 1 | AO25: 1 | AP25: 1 | AQ25: 1 | AR25: 1 | AS25: 1 | AT25: 1 | AU25: 1 | AV25: 1 | AW25: 1 | AX25: 1 | AY25: 1 | AZ25: 1 | BA25: PREVIOUSLY APPROVED | BB25: PREVIOUSLY APPROVED | BC25: PREVIOUSLY APPROVED | BD25: PREVIOUSLY APPROVED | BE25: PREVIOUSLY APPROVED | BF25: PREVIOUSLY APPROVED | BG25: PREVIOUSLY APPROVED | BH25: PREVIOUSLY APPROVED | BI25: PREVIOUSLY APPROVED | BJ25: PREVIOUSLY APPROVED | BK25: PREVIOUSLY APPROVED | BL25: PREVIOUSLY APPROVED | BM25: PREVIOUSLY APPROVED | BN25: CLOSED | BO25: PREVIOUSLY APPROVED | BP25: =IFERROR(__xludf.DUMMYFUNCTION("IFERROR( INDEX( FILTER(X25:BK25, ISNUMBER(X25:BK25)), COUNTA(FILTER(X25:BK25, ISNUMBER(X25:BK25))) ), BK25 )"),1.0) -> 1
A26: 13 | B26: ARE ARQUITETURA | C26: 1130 | D26: ARE ARQUITETURA | E26: 1130 | F26: =IFERROR(VLOOKUP(M26:M99,'R22 RELATÓRIO ACC'!B:F,5,FALSE),"NOT PUBLISHED") -> V29 | G26: =IFERROR(VLOOKUP(M26:M97,'R22 RELATÓRIO ACC'!B:P,15,FALSE),"NOT PUBLISHED") -> 13/04/2026 | H26: =IFERROR(VLOOKUP(N26:N99,'RELATÓRIO ACC'!B:F,5,FALSE),"NOT PUBLISHED") -> V3 | I26: =IFERROR(VLOOKUP(N26:N97,'RELATÓRIO ACC'!B:P,15,FALSE),"NOT PUBLISHED") -> 03/06/2026 | J26: 45898 | K26: V17 | L26: MODELO FOI ATUALIZADO | M26: CPQ11-ARCH-ARCH-DATA-R22.rvt | N26: CPQ11-ARCH-ARCH-DATA-R24.rvt | O26: ARCH-ARCH-DATA | P26: FALSE | Q26: FECHADA | R26: FOI AUDITADO R8 | S26: FINALIZADO | T26: FINALIZADO | U26: IURY | V26: 45901 | W26: 45901 | X26: NOT PUBLISHED | Y26: NOT PUBLISHED | Z26: 0.53 | AA26: 0.59 | AB26: 0.88 | AC26: 0.82 | AD26: 0.88 | AE26: 1 | AF26: 1 | AG26: 1 | AH26: 1 | AI26: 1 | AJ26: 1 | AK26: 1 | AL26: 1 | AM26: 1 | AN26: 1 | AO26: 1 | AP26: 1 | AQ26: 1 | AR26: 1 | AS26: 1 | AT26: 1 | AU26: 1 | AV26: 1 | AW26: 1 | AX26: 1 | AY26: 1 | AZ26: 1 | BA26: PREVIOUSLY APPROVED | BB26: PREVIOUSLY APPROVED | BC26: PREVIOUSLY APPROVED | BD26: PREVIOUSLY APPROVED | BE26: PREVIOUSLY APPROVED | BF26: PREVIOUSLY APPROVED | BG26: PREVIOUSLY APPROVED | BH26: PREVIOUSLY APPROVED | BI26: PREVIOUSLY APPROVED | BJ26: PREVIOUSLY APPROVED | BK26: PREVIOUSLY APPROVED | BL26: PREVIOUSLY APPROVED | BM26: PREVIOUSLY APPROVED | BN26: CLOSED | BO26: PREVIOUSLY APPROVED | BP26: =IFERROR(__xludf.DUMMYFUNCTION("IFERROR( INDEX( FILTER(X26:BK26, ISNUMBER(X26:BK26)), COUNTA(FILTER(X26:BK26, ISNUMBER(X26:BK26))) ), BK26 )"),1.0) -> 1
A27: 14 | B27: GARCIA | D27: CADBIM | F27: =IFERROR(VLOOKUP(M27:M100,'R22 RELATÓRIO ACC'!B:F,5,FALSE),"NOT PUBLISHED") -> V18 | G27: =IFERROR(VLOOKUP(M27:M98,'R22 RELATÓRIO ACC'!B:P,15,FALSE),"NOT PUBLISHED") -> 08/04/2026 | H27: =IFERROR(VLOOKUP(N27:N100,'RELATÓRIO ACC'!B:F,5,FALSE),"NOT PUBLISHED") -> V6 | I27: =IFERROR(VLOOKUP(N27:N98,'RELATÓRIO ACC'!B:P,15,FALSE),"NOT PUBLISHED") -> 24/06/2026 | J27: 45895 | K27: V2 | L27: MODELO FOI ATUALIZADO | M27: CPQ11-CIVL-ERTH-SITE-R22.rvt | N27: CPQ11-CIVL-ERTH-SITE-R24.rvt | O27: CIVL-ERTH-SITE | P27: FALSE | Q27: FECHADA | R27: FOI AUDITADO R8 | S27: FINALIZADO | T27: FINALIZADO | U27: EDSON | V27: 45895 | W27: 45895 | X27: NOT PUBLISHED | Y27: NOT PUBLISHED | Z27: NOT PUBLISHED | AA27: NOT PUBLISHED | AB27: NOT PUBLISHED | AC27: NOT PUBLISHED | AD27: NOT PUBLISHED | AE27: 1 | AF27: 1 | AG27: 1 | AH27: 1 | AI27: 1 | AJ27: 1 | AK27: 1 | AL27: 1 | AM27: 1 | AN27: 1 | AO27: 1 | AP27: 1 | AQ27: 1 | AR27: 1 | AS27: 1 | AT27: 1 | AU27: 1 | AV27: 1 | AW27: 1 | AX27: 1 | AY27: 1 | AZ27: 1 | BA27: PREVIOUSLY APPROVED | BB27: PREVIOUSLY APPROVED | BC27: PREVIOUSLY APPROVED | BD27: PREVIOUSLY APPROVED | BE27: PREVIOUSLY APPROVED | BF27: PREVIOUSLY APPROVED | BG27: PREVIOUSLY APPROVED | BH27: PREVIOUSLY APPROVED | BI27: PREVIOUSLY APPROVED | BJ27: PREVIOUSLY APPROVED | BK27: PREVIOUSLY APPROVED | BL27: PREVIOUSLY APPROVED | BM27: PREVIOUSLY APPROVED | BN27: CLOSED | BO27: PREVIOUSLY APPROVED | BP27: =IFERROR(__xludf.DUMMYFUNCTION("IFERROR( INDEX( FILTER(X27:BK27, ISNUMBER(X27:BK27)), COUNTA(FILTER(X27:BK27, ISNUMBER(X27:BK27))) ), BK27 )"),1.0) -> 1
A28: 15 | B28: MENDES HOLLER | C28: 1112 | D28: PGMAK | E28: 1129 | F28: =IFERROR(VLOOKUP(M28:M101,'R22 RELATÓRIO ACC'!B:F,5,FALSE),"NOT PUBLISHED") -> V40 | G28: =IFERROR(VLOOKUP(M28:M99,'R22 RELATÓRIO ACC'!B:P,15,FALSE),"NOT PUBLISHED") -> 10/04/2026 | H28: =IFERROR(VLOOKUP(N28:N101,'RELATÓRIO ACC'!B:F,5,FALSE),"NOT PUBLISHED") -> V3 | I28: =IFERROR(VLOOKUP(N28:N99,'RELATÓRIO ACC'!B:P,15,FALSE),"NOT PUBLISHED") -> 13/07/2026 | J28: 45882 | K28: V24 | L28: MODELO FOI ATUALIZADO | M28: CPQ11-SYST-INFR-DATA-R22.rvt | N28: CPQ11-SYST-INFR-DATA-R24.rvt | O28: SYST-INFR-DATA | P28: FALSE | Q28: FECHADA | R28: FOI AUDITADO R8 | S28: FINALIZADO | T28: FINALIZADO | U28: EDSON | V28: 45883 | W28: 45883 | X28: NOT PUBLISHED | Y28: NOT PUBLISHED | Z28: 0.44 | AA28: 0.69 | AB28: 0.94 | AC28: 0.82 | AD28: 0.88 | AE28: 1 | AF28: 1 | AG28: 1 | AH28: 1 | AI28: 1 | AJ28: 1 | AK28: 1 | AL28: 1 | AM28: 1 | AN28: 1 | AO28: 1 | AP28: 1 | AQ28: 1 | AR28: 1 | AS28: 1 | AT28: 1 | AU28: 1 | AV28: 1 | AW28: 1 | AX28: 1 | AY28: 1 | AZ28: 1 | BA28: PREVIOUSLY APPROVED | BB28: PREVIOUSLY APPROVED | BC28: PREVIOUSLY APPROVED | BD28: PREVIOUSLY APPROVED | BE28: PREVIOUSLY APPROVED | BF28: PREVIOUSLY APPROVED | BG28: PREVIOUSLY APPROVED | BH28: PREVIOUSLY APPROVED | BI28: PREVIOUSLY APPROVED | BJ28: PREVIOUSLY APPROVED | BK28: PREVIOUSLY APPROVED | BL28: PREVIOUSLY APPROVED | BM28: PREVIOUSLY APPROVED | BN28: CLOSED | BO28: PREVIOUSLY APPROVED | BP28: =IFERROR(__xludf.DUMMYFUNCTION("IFERROR( INDEX( FILTER(X28:BK28, ISNUMBER(X28:BK28)), COUNTA(FILTER(X28:BK28, ISNUMBER(X28:BK28))) ), BK28 )"),1.0) -> 1
A29: 16 | B29: MENDES HOLLER | C29: 1112 | D29: PGMAK | E29: 1129 | F29: =IFERROR(VLOOKUP(M29:M102,'R22 RELATÓRIO ACC'!B:F,5,FALSE),"NOT PUBLISHED") -> V39 | G29: =IFERROR(VLOOKUP(M29:M100,'R22 RELATÓRIO ACC'!B:P,15,FALSE),"NOT PUBLISHED") -> 12/05/2026 | H29: =IFERROR(VLOOKUP(N29:N102,'RELATÓRIO ACC'!B:F,5,FALSE),"NOT PUBLISHED") -> V4 | I29: =IFERROR(VLOOKUP(N29:N100,'RELATÓRIO ACC'!B:P,15,FALSE),"NOT PUBLISHED") -> 14/07/2026 | J29: 45863 | K29: V20 | L29: MODELO FOI ATUALIZADO | M29: CPQ11-SYST-INFR-SITE-R22.rvt | N29: CPQ11-SYST-INFR-SITE-R24.rvt | O29: SYST-INFR-SITE | P29: FALSE | Q29: FECHADA | R29: FOI AUDITADO R7 | W29: 45870 | X29: NOT PUBLISHED | Y29: 0.69 | Z29: 0.81 | AA29: 0.69 | AB29: 1 | AC29: 0.82 | AD29: 1 | AE29: 1 | AF29: 1 | AG29: 1 | AH29: 1 | AI29: 1 | AJ29: 1 | AK29: 1 | AL29: 1 | AM29: 1 | AN29: 1 | AO29: 1 | AP29: 1 | AQ29: 1 | AR29: 1 | AS29: 1 | AT29: 1 | AU29: 1 | AV29: 1 | AW29: 1 | AX29: 1 | AY29: 1 | AZ29: 1 | BA29: PREVIOUSLY APPROVED | BB29: PREVIOUSLY APPROVED | BC29: PREVIOUSLY APPROVED | BD29: PREVIOUSLY APPROVED | BE29: PREVIOUSLY APPROVED | BF29: PREVIOUSLY APPROVED | BG29: PREVIOUSLY APPROVED | BH29: PREVIOUSLY APPROVED | BI29: PREVIOUSLY APPROVED | BJ29: PREVIOUSLY APPROVED | BK29: PREVIOUSLY APPROVED | BL29: PREVIOUSLY APPROVED | BM29: PREVIOUSLY APPROVED | BN29: CLOSED | BO29: PREVIOUSLY APPROVED | BP29: =IFERROR(__xludf.DUMMYFUNCTION("IFERROR( INDEX( FILTER(X29:BK29, ISNUMBER(X29:BK29)), COUNTA(FILTER(X29:BK29, ISNUMBER(X29:BK29))) ), BK29 )"),1.0) -> 1
A30: 17 | B30: MENDES HOLLER | C30: 1112 | D30: PGMAK | E30: 1129 | F30: =IFERROR(VLOOKUP(M30:M103,'R22 RELATÓRIO ACC'!B:F,5,FALSE),"NOT PUBLISHED") -> V39 | G30: =IFERROR(VLOOKUP(M30:M101,'R22 RELATÓRIO ACC'!B:P,15,FALSE),"NOT PUBLISHED") -> 19/03/2026 | H30: =IFERROR(VLOOKUP(N30:N103,'RELATÓRIO ACC'!B:F,5,FALSE),"NOT PUBLISHED") -> V5 | I30: =IFERROR(VLOOKUP(N30:N101,'RELATÓRIO ACC'!B:P,15,FALSE),"NOT PUBLISHED") -> 10/07/2026 | J30: 45982 | K30: V34 | L30: MODELO FOI ATUALIZADO | M30: CPQ11-SCTY-INFR-DATA-R22.rvt | N30: CPQ11-SCTY-INFR-DATA-R24.rvt | O30: SCTY-INFR-DATA | P30: FALSE | Q30: ABERTO | R30: FOI AUDITADO R8 | S30: FINALIZADO | T30: FINALIZADO | U30: ALINNE | V30: 45944 | W30: 45944 | X30: NOT PUBLISHED | Y30: 0.56 | Z30: 0.56 | AA30: 0.75 | AB30: 0.88 | AC30: 0.82 | AD30: 0.94 | AE30: 0.94 | AF30: OUTDATED | AG30: OUTDATED | AH30: 0.94 | AI30: OUTDATED | AJ30: 0.94 | AK30: OUTDATED | AL30: 1 | AM30: 1 | AN30: 1 | AO30: 1 | AP30: 1 | AQ30: 1 | AR30: 1 | AS30: 1 | AT30: 1 | AU30: 1 | AV30: 1 | AW30: 1 | AX30: 1 | AY30: 1 | AZ30: 1 | BA30: PREVIOUSLY APPROVED | BB30: PREVIOUSLY APPROVED | BC30: PREVIOUSLY APPROVED | BD30: PREVIOUSLY APPROVED | BE30: PREVIOUSLY APPROVED | BF30: PREVIOUSLY APPROVED | BG30: PREVIOUSLY APPROVED | BH30: PREVIOUSLY APPROVED | BI30: PREVIOUSLY APPROVED | BJ30: PREVIOUSLY APPROVED | BK30: PREVIOUSLY APPROVED | BL30: PREVIOUSLY APPROVED | BM30: PREVIOUSLY APPROVED | BN30: CLOSED | BO30: PREVIOUSLY APPROVED | BP30: =IFERROR(__xludf.DUMMYFUNCTION("IFERROR( INDEX( FILTER(X30:BK30, ISNUMBER(X30:BK30)), COUNTA(FILTER(X30:BK30, ISNUMBER(X30:BK30))) ), BK30 )"),1.0) -> 1
A31: 18 | B31: MENDES HOLLER | C31: 1112 | D31: PGMAK | E31: 1129 | F31: =IFERROR(VLOOKUP(M31:M104,'R22 RELATÓRIO ACC'!B:F,5,FALSE),"NOT PUBLISHED") -> V34 | G31: =IFERROR(VLOOKUP(M31:M102,'R22 RELATÓRIO ACC'!B:P,15,FALSE),"NOT PUBLISHED") -> 05/05/2026 | H31: =IFERROR(VLOOKUP(N31:N104,'RELATÓRIO ACC'!B:F,5,FALSE),"NOT PUBLISHED") -> V3 | I31: =IFERROR(VLOOKUP(N31:N102,'RELATÓRIO ACC'!B:P,15,FALSE),"NOT PUBLISHED") -> 03/07/2026 | J31: 45849 | K31: V18 | L31: MODELO FOI ATUALIZADO | M31: CPQ11-SCTY-INFR-SITE-R22.rvt | N31: CPQ11-SCTY-INFR-SITE-R24.rvt | O31: SCTY-INFR-SITE | P31: FALSE | Q31: FECHADA | R31: FOI AUDITADO R6 | W31: 45853 | X31: NOT PUBLISHED | Y31: 0.56 | Z31: 0.88 | AA31: 0.81 | AB31: 0.94 | AC31: 1 | AD31: 1 | AE31: 1 | AF31: 1 | AG31: 1 | AH31: 1 | AI31: 1 | AJ31: 1 | AK31: 1 | AL31: 1 | AM31: 1 | AN31: 1 | AO31: 1 | AP31: 1 | AQ31: 1 | AR31: 1 | AS31: 1 | AT31: 1 | AU31: 1 | AV31: 1 | AW31: 1 | AX31: 1 | AY31: 1 | AZ31: 1 | BA31: PREVIOUSLY APPROVED | BB31: PREVIOUSLY APPROVED | BC31: PREVIOUSLY APPROVED | BD31: PREVIOUSLY APPROVED | BE31: PREVIOUSLY APPROVED | BF31: PREVIOUSLY APPROVED | BG31: PREVIOUSLY APPROVED | BH31: PREVIOUSLY APPROVED | BI31: PREVIOUSLY APPROVED | BJ31: PREVIOUSLY APPROVED | BK31: PREVIOUSLY APPROVED | BL31: PREVIOUSLY APPROVED | BM31: PREVIOUSLY APPROVED | BN31: CLOSED | BO31: PREVIOUSLY APPROVED | BP31: =IFERROR(__xludf.DUMMYFUNCTION("IFERROR( INDEX( FILTER(X31:BK31, ISNUMBER(X31:BK31)), COUNTA(FILTER(X31:BK31, ISNUMBER(X31:BK31))) ), BK31 )"),1.0) -> 1
A32: 19 | B32: MENDES HOLLER | C32: 1112 | D32: PGMAK | E32: 1129 | F32: =IFERROR(VLOOKUP(M32:M105,'R22 RELATÓRIO ACC'!B:F,5,FALSE),"NOT PUBLISHED") -> V33 | G32: =IFERROR(VLOOKUP(M32:M103,'R22 RELATÓRIO ACC'!B:P,15,FALSE),"NOT PUBLISHED") -> 04/03/2026 | H32: =IFERROR(VLOOKUP(N32:N105,'RELATÓRIO ACC'!B:F,5,FALSE),"NOT PUBLISHED") -> V2 | I32: =IFERROR(VLOOKUP(N32:N103,'RELATÓRIO ACC'!B:P,15,FALSE),"NOT PUBLISHED") -> 13/07/2026 | J32: 45868 | K32: V25 | L32: MODELO FOI ATUALIZADO | M32: CPQ11-BASM-INFR-DATA-R22.rvt | N32: CPQ11-BASM-INFR-DATA-R24.rvt | O32: BASM-INFR-DATA | P32: FALSE | Q32: FECHADA | R32: FOI AUDITADO R7 | W32: 45870 | X32: NOT PUBLISHED | Y32: 0.75 | Z32: 0.56 | AA32: 0.94 | AB32: 1 | AC32: 0.94 | AD32: 1 | AE32: 1 | AF32: 1 | AG32: 1 | AH32: 1 | AI32: 1 | AJ32: 1 | AK32: 1 | AL32: 1 | AM32: 1 | AN32: 1 | AO32: 1 | AP32: 1 | AQ32: 1 | AR32: 1 | AS32: 1 | AT32: 1 | AU32: 1 | AV32: 1 | AW32: 1 | AX32: 1 | AY32: 1 | AZ32: 1 | BA32: PREVIOUSLY APPROVED | BB32: PREVIOUSLY APPROVED | BC32: PREVIOUSLY APPROVED | BD32: PREVIOUSLY APPROVED | BE32: PREVIOUSLY APPROVED | BF32: PREVIOUSLY APPROVED | BG32: PREVIOUSLY APPROVED | BH32: PREVIOUSLY APPROVED | BI32: PREVIOUSLY APPROVED | BJ32: PREVIOUSLY APPROVED | BK32: PREVIOUSLY APPROVED | BL32: PREVIOUSLY APPROVED | BM32: PREVIOUSLY APPROVED | BN32: CLOSED | BO32: PREVIOUSLY APPROVED | BP32: =IFERROR(__xludf.DUMMYFUNCTION("IFERROR( INDEX( FILTER(X32:BK32, ISNUMBER(X32:BK32)), COUNTA(FILTER(X32:BK32, ISNUMBER(X32:BK32))) ), BK32 )"),1.0) -> 1
A33: 20 | B33: MENDES HOLLER | C33: 1112 | D33: PGMAK | E33: 1129 | F33: =IFERROR(VLOOKUP(M33:M106,'R22 RELATÓRIO ACC'!B:F,5,FALSE),"NOT PUBLISHED") -> V32 | G33: =IFERROR(VLOOKUP(M33:M104,'R22 RELATÓRIO ACC'!B:P,15,FALSE),"NOT PUBLISHED") -> 24/04/2026 | H33: =IFERROR(VLOOKUP(N33:N106,'RELATÓRIO ACC'!B:F,5,FALSE),"NOT PUBLISHED") -> V3 | I33: =IFERROR(VLOOKUP(N33:N104,'RELATÓRIO ACC'!B:P,15,FALSE),"NOT PUBLISHED") -> 03/07/2026 | J33: 45846 | K33: V19 | L33: MODELO FOI ATUALIZADO | M33: CPQ11-BASM-INFR-PUMP-R22.rvt | N33: CPQ11-BASM-INFR-PUMP-R24.rvt | O33: BASM-INFR-PUMP | P33: FALSE | Q33: FECHADA | R33: FOI AUDITADO R6 | W33: 45852 | X33: NOT PUBLISHED | Y33: 0.75 | Z33: 0.75 | AA33: 0.94 | AB33: 1 | AC33: 1 | AD33: 1 | AE33: 1 | AF33: 1 | AG33: 1 | AH33: 1 | AI33: 1 | AJ33: 1 | AK33: 1 | AL33: 1 | AM33: 1 | AN33: 1 | AO33: 1 | AP33: 1 | AQ33: 1 | AR33: 1 | AS33: 1 | AT33: 1 | AU33: 1 | AV33: 1 | AW33: 1 | AX33: 1 | AY33: 1 | AZ33: 1 | BA33: PREVIOUSLY APPROVED | BB33: PREVIOUSLY APPROVED | BC33: PREVIOUSLY APPROVED | BD33: PREVIOUSLY APPROVED | BE33: PREVIOUSLY APPROVED | BF33: PREVIOUSLY APPROVED | BG33: PREVIOUSLY APPROVED | BH33: PREVIOUSLY APPROVED | BI33: PREVIOUSLY APPROVED | BJ33: PREVIOUSLY APPROVED | BK33: PREVIOUSLY APPROVED | BL33: PREVIOUSLY APPROVED | BM33: PREVIOUSLY APPROVED | BN33: CLOSED | BO33: PREVIOUSLY APPROVED | BP33: =IFERROR(__xludf.DUMMYFUNCTION("IFERROR( INDEX( FILTER(X33:BK33, ISNUMBER(X33:BK33)), COUNTA(FILTER(X33:BK33, ISNUMBER(X33:BK33))) ), BK33 )"),1.0) -> 1
A34: 21 | B34: MENDES HOLLER | C34: 1112 | D34: PGMAK | E34: 1129 | F34: =IFERROR(VLOOKUP(M34:M107,'R22 RELATÓRIO ACC'!B:F,5,FALSE),"NOT PUBLISHED") -> V52 | G34: =IFERROR(VLOOKUP(M34:M105,'R22 RELATÓRIO ACC'!B:P,15,FALSE),"NOT PUBLISHED") -> 30/04/2026 | H34: =IFERROR(VLOOKUP(N34:N107,'RELATÓRIO ACC'!B:F,5,FALSE),"NOT PUBLISHED") -> V4 | I34: =IFERROR(VLOOKUP(N34:N105,'RELATÓRIO ACC'!B:P,15,FALSE),"NOT PUBLISHED") -> 06/07/2026 | J34: 46077 | K34: V46 | L34: MODELO FOI ATUALIZADO | M34: CPQ11-ELEC-ELEC-DATA-R22.rvt | N34: CPQ11-ELEC-ELEC-DATA-R24.rvt | O34: ELEC-ELEC-DATA | P34: FALSE | Q34: ABERTO | R34: FOI AUDITADO R8 | S34: FINALIZADO | T34: FINALIZADO | U34: ALINNE | V34: 45944 | W34: 45944 | X34: NOT PUBLISHED | Y34: 0.44 | Z34: 0.44 | AA34: 0.63 | AB34: 0.75 | AC34: 0.76 | AD34: 0.88 | AE34: 0.82 | AF34: OUTDATED | AG34: OUTDATED | AH34: 0.82 | AI34: OUTDATED | AJ34: 0.82 | AK34: 0.88 | AL34: 0.88 | AM34: OUTDATED | AN34: 0.88 | AO34: 0.88 | AP34: OUTDATED | AQ34: OUTDATED | AR34: 0.82 | AS34: OUTDATED | AT34: 1 | AU34: 1 | AV34: 1 | AW34: 1 | AX34: 1 | AY34: 1 | AZ34: 1 | BA34: PREVIOUSLY APPROVED | BB34: PREVIOUSLY APPROVED | BC34: PREVIOUSLY APPROVED | BD34: PREVIOUSLY APPROVED | BE34: PREVIOUSLY APPROVED | BF34: PREVIOUSLY APPROVED | BG34: PREVIOUSLY APPROVED | BH34: PREVIOUSLY APPROVED | BI34: PREVIOUSLY APPROVED | BJ34: PREVIOUSLY APPROVED | BK34: PREVIOUSLY APPROVED | BL34: PREVIOUSLY APPROVED | BM34: PREVIOUSLY APPROVED | BN34: CLOSED | BO34: PREVIOUSLY APPROVED | BP34: =IFERROR(__xludf.DUMMYFUNCTION("IFERROR( INDEX( FILTER(X34:BK34, ISNUMBER(X34:BK34)), COUNTA(FILTER(X34:BK34, ISNUMBER(X34:BK34))) ), BK34 )"),1.0) -> 1
A35: 22 | B35: MENDES HOLLER | C35: 1112 | D35: PGMAK | E35: 1129 | F35: =IFERROR(VLOOKUP(M35:M108,'R22 RELATÓRIO ACC'!B:F,5,FALSE),"NOT PUBLISHED") -> V33 | G35: =IFERROR(VLOOKUP(M35:M106,'R22 RELATÓRIO ACC'!B:P,15,FALSE),"NOT PUBLISHED") -> 05/03/2026 | H35: =IFERROR(VLOOKUP(N35:N108,'RELATÓRIO ACC'!B:F,5,FALSE),"NOT PUBLISHED") -> V1 | I35: =IFERROR(VLOOKUP(N35:N106,'RELATÓRIO ACC'!B:P,15,FALSE),"NOT PUBLISHED") -> 19/05/2026 | J35: 46077 | K35: V32 | L35: MODELO FOI ATUALIZADO | M35: CPQ11-ELEC-ELEC-SITE-R22.rvt | N35: CPQ11-ELEC-ELEC-SITE-R24.rvt | O35: ELEC-ELEC-SITE | P35: FALSE | Q35: ABERTO | R35: FOI AUDITADO R8 | S35: FINALIZADO | T35: FINALIZADO | U35: IURY | V35: 45944 | W35: 45944 | X35: NOT PUBLISHED | Y35: 0.38 | Z35: 0.5 | AA35: 0.5 | AB35: 0.94 | AC35: 0.88 | AD35: 0.88 | AE35: 0.88 | AF35: OUTDATED | AG35: OUTDATED | AH35: 0.94 | AI35: 0.94 | AJ35: 0.94 | AK35: OUTDATED | AL35: 0.94 | AM35: OUTDATED | AN35: 0.94 | AO35: 0.94 | AP35: OUTDATED | AQ35: OUTDATED | AR35: 0.94 | AS35: OUTDATED | AT35: 1 | AU35: 1 | AV35: 1 | AW35: 1 | AX35: 1 | AY35: 1 | AZ35: 1 | BA35: PREVIOUSLY APPROVED | BB35: PREVIOUSLY APPROVED | BC35: PREVIOUSLY APPROVED | BD35: PREVIOUSLY APPROVED | BE35: PREVIOUSLY APPROVED | BF35: PREVIOUSLY APPROVED | BG35: PREVIOUSLY APPROVED | BH35: PREVIOUSLY APPROVED | BI35: PREVIOUSLY APPROVED | BJ35: PREVIOUSLY APPROVED | BK35: PREVIOUSLY APPROVED | BL35: PREVIOUSLY APPROVED | BM35: PREVIOUSLY APPROVED | BN35: CLOSED | BO35: PREVIOUSLY APPROVED | BP35: =IFERROR(__xludf.DUMMYFUNCTION("IFERROR( INDEX( FILTER(X35:BK35, ISNUMBER(X35:BK35)), COUNTA(FILTER(X35:BK35, ISNUMBER(X35:BK35))) ), BK35 )"),1.0) -> 1
A36: 23 | B36: MENDES HOLLER | C36: 1112 | D36: PGMAK | E36: 1129 | F36: =IFERROR(VLOOKUP(M36:M109,'R22 RELATÓRIO ACC'!B:F,5,FALSE),"NOT PUBLISHED") -> V30 | G36: =IFERROR(VLOOKUP(M36:M107,'R22 RELATÓRIO ACC'!B:P,15,FALSE),"NOT PUBLISHED") -> 24/03/2026 | H36: =IFERROR(VLOOKUP(N36:N109,'RELATÓRIO ACC'!B:F,5,FALSE),"NOT PUBLISHED") -> V2 | I36: =IFERROR(VLOOKUP(N36:N107,'RELATÓRIO ACC'!B:P,15,FALSE),"NOT PUBLISHED") -> 13/07/2026 | J36: 46091 | K36: V29 | L36: MODELO FOI ATUALIZADO | M36: CPQ11-PLMB-PLMB-DATA-R22.rvt | N36: CPQ11-PLMB-PLMB-DATA-R24.rvt | O36: PLMB-PLMB-DATA | P36: FALSE | Q36: ABERTO | R36: FOI AUDITADO R6 | S36: FINALIZADO | T36: FINALIZADO | U36: ALINNE | V36: 45944 | W36: 45944 | X36: NOT PUBLISHED | Y36: 0.63 | Z36: 0.56 | AA36: 0.5 | AB36: 0.56 | AC36: 0.65 | AD36: OUTDATED | AE36: OUTDATED | AF36: OUTDATED | AG36: OUTDATED | AH36: 0.71 | AI36: OUTDATED | AJ36: 0.71 | AK36: OUTDATED | AL36: 0.71 | AM36: OUTDATED | AN36: 0.71 | AO36: 0.71 | AP36: 0.76 | AQ36: OUTDATED | AR36: 0.76 | AS36: 0.88 | AT36: OUTDATED | AU36: 1 | AV36: 1 | AW36: 1 | AX36: 1 | AY36: 1 | AZ36: 1 | BA36: PREVIOUSLY APPROVED | BB36: PREVIOUSLY APPROVED | BC36: PREVIOUSLY APPROVED | BD36: PREVIOUSLY APPROVED | BE36: PREVIOUSLY APPROVED | BF36: PREVIOUSLY APPROVED | BG36: PREVIOUSLY APPROVED | BH36: PREVIOUSLY APPROVED | BI36: PREVIOUSLY APPROVED | BJ36: PREVIOUSLY APPROVED | BK36: PREVIOUSLY APPROVED | BL36: PREVIOUSLY APPROVED | BM36: PREVIOUSLY APPROVED | BN36: CLOSED | BO36: PREVIOUSLY APPROVED | BP36: =IFERROR(__xludf.DUMMYFUNCTION("IFERROR( INDEX( FILTER(X36:BK36, ISNUMBER(X36:BK36)), COUNTA(FILTER(X36:BK36, ISNUMBER(X36:BK36))) ), BK36 )"),1.0) -> 1
A37: 24 | B37: MENDES HOLLER | C37: 1112 | D37: PGMAK | E37: 1129 | F37: =IFERROR(VLOOKUP(M37:M110,'R22 RELATÓRIO ACC'!B:F,5,FALSE),"NOT PUBLISHED") -> V27 | G37: =IFERROR(VLOOKUP(M37:M108,'R22 RELATÓRIO ACC'!B:P,15,FALSE),"NOT PUBLISHED") -> 08/04/2026 | H37: =IFERROR(VLOOKUP(N37:N110,'RELATÓRIO ACC'!B:F,5,FALSE),"NOT PUBLISHED") -> V2 | I37: =IFERROR(VLOOKUP(N37:N108,'RELATÓRIO ACC'!B:P,15,FALSE),"NOT PUBLISHED") -> 23/06/2026 | J37: 08/04/2026 | K37: V27 | L37: MODELO FOI ATUALIZADO | M37: CPQ11-PLMB-PLMB-SITE-R22.rvt | N37: CPQ11-PLMB-PLMB-SITE-R24.rvt | O37: PLMB-PLMB-SITE | P37: FALSE | Q37: ABERTO | R37: FOI AUDITADO R8 | S37: FINALIZADO | T37: FINALIZADO | U37: IURY | V37: 45944 | W37: 45944 | X37: NOT PUBLISHED | Y37: 0.5 | Z37: 0.44 | AA37: 0.5 | AB37: OUTDATED | AC37: 0.65 | AD37: 0.71 | AE37: 0.71 | AF37: OUTDATED | AG37: OUTDATED | AH37: 0.71 | AI37: 0.82 | AJ37: 0.82 | AK37: OUTDATED | AL37: 0.82 | AM37: OUTDATED | AN37: 0.82 | AO37: 0.82 | AP37: 0.82 | AQ37: OUTDATED | AR37: IMPROPER | AS37: 0.94 | AT37: OUTDATED | AU37: 0.94 | AV37: OUTDATED | AW37: OUTDATED | AX37: NEXT ROUND | AY37: 0.94 | AZ37: 1 | BA37: PREVIOUSLY APPROVED | BB37: PREVIOUSLY APPROVED | BC37: PREVIOUSLY APPROVED | BD37: PREVIOUSLY APPROVED | BE37: PREVIOUSLY APPROVED | BF37: PREVIOUSLY APPROVED | BG37: PREVIOUSLY APPROVED | BH37: PREVIOUSLY APPROVED | BI37: PREVIOUSLY APPROVED | BJ37: PREVIOUSLY APPROVED | BK37: PREVIOUSLY APPROVED | BL37: PREVIOUSLY APPROVED | BM37: PREVIOUSLY APPROVED | BN37: CLOSED | BO37: PREVIOUSLY APPROVED | BP37: =IFERROR(__xludf.DUMMYFUNCTION("IFERROR( INDEX( FILTER(X37:BK37, ISNUMBER(X37:BK37)), COUNTA(FILTER(X37:BK37, ISNUMBER(X37:BK37))) ), BK37 )"),1.0) -> 1
A38: 25 | B38: MENDES HOLLER | C38: 1112 | D38: MENDES HOLLER | E38: 1112 | F38: =IFERROR(VLOOKUP(M38:M111,'R22 RELATÓRIO ACC'!B:F,5,FALSE),"NOT PUBLISHED") -> V14 | G38: =IFERROR(VLOOKUP(M38:M109,'R22 RELATÓRIO ACC'!B:P,15,FALSE),"NOT PUBLISHED") -> 03/03/2026 | H38: =IFERROR(VLOOKUP(N38:N111,'RELATÓRIO ACC'!B:F,5,FALSE),"NOT PUBLISHED") -> V4 | I38: =IFERROR(VLOOKUP(N38:N109,'RELATÓRIO ACC'!B:P,15,FALSE),"NOT PUBLISHED") -> 13/07/2026 | J38: 45895 | K38: V5 | L38: MODELO FOI ATUALIZADO | M38: CPQ11-PLMB-DIES-SITE-R22.rvt | N38: CPQ11-PLMB-DIES-SITE-R24.rvt | O38: PLMB-DIES-SITE | P38: FALSE | Q38: FECHADA | R38: FOI AUDITADO R8 | S38: FINALIZADO | T38: FINALIZADO | U38: EDSON | V38: 45895 | W38: 45895 | X38: NOT PUBLISHED | Y38: 0.88 | Z38: 0.69 | AA38: OUTDATED | AB38: OUTDATED | AC38: OUTDATED | AD38: 0.75 | AE38: 1 | AF38: 1 | AG38: 1 | AH38: 1 | AI38: 1 | AJ38: 1 | AK38: 1 | AL38: 1 | AM38: 1 | AN38: 1 | AO38: 1 | AP38: 1 | AQ38: 1 | AR38: 1 | AS38: 1 | AT38: 1 | AU38: 1 | AV38: 1 | AW38: 1 | AX38: 1 | AY38: 1 | AZ38: 1 | BA38: PREVIOUSLY APPROVED | BB38: PREVIOUSLY APPROVED | BC38: PREVIOUSLY APPROVED | BD38: PREVIOUSLY APPROVED | BE38: PREVIOUSLY APPROVED | BF38: PREVIOUSLY APPROVED | BG38: PREVIOUSLY APPROVED | BH38: PREVIOUSLY APPROVED | BI38: PREVIOUSLY APPROVED | BJ38: PREVIOUSLY APPROVED | BK38: PREVIOUSLY APPROVED | BL38: PREVIOUSLY APPROVED | BM38: PREVIOUSLY APPROVED | BN38: CLOSED | BO38: PREVIOUSLY APPROVED | BP38: =IFERROR(__xludf.DUMMYFUNCTION("IFERROR( INDEX( FILTER(X38:BK38, ISNUMBER(X38:BK38)), COUNTA(FILTER(X38:BK38, ISNUMBER(X38:BK38))) ), BK38 )"),1.0) -> 1
A39: 26 | B39: MENDES HOLLER | C39: 1112 | D39: MENDES HOLLER | E39: 1112 | F39: =IFERROR(VLOOKUP(M39:M112,'R22 RELATÓRIO ACC'!B:F,5,FALSE),"NOT PUBLISHED") -> V24 | G39: =IFERROR(VLOOKUP(M39:M110,'R22 RELATÓRIO ACC'!B:P,15,FALSE),"NOT PUBLISHED") -> 15/05/2026 | H39: =IFERROR(VLOOKUP(N39:N112,'RELATÓRIO ACC'!B:F,5,FALSE),"NOT PUBLISHED") -> V2 | I39: =IFERROR(VLOOKUP(N39:N110,'RELATÓRIO ACC'!B:P,15,FALSE),"NOT PUBLISHED") -> 06/07/2026 | J39: 07/05/2026 | K39: V23 | L39: CONTINUA MESMA VERSÃO | M39: CPQ11-FALM-FALM-DATA-R22.rvt | N39: CPQ11-FALM-FALM-DATA-R24.rvt | O39: FALM-FALM-DATA | P39: FALSE | Q39: ABERTO | R39: FOI AUDITADO R7 | W39: 45876 | X39: NOT PUBLISHED | Y39: NOT PUBLISHED | Z39: 0.81 | AA39: OUTDATED | AB39: 0.53 | AC39: 0.76 | AD39: 0.76 | AE39: OUTDATED | AF39: OUTDATED | AG39: OUTDATED | AH39: OUTDATED | AI39: OUTDATED | AJ39: OUTDATED | AK39: OUTDATED | AL39: 0.88 | AM39: OUTDATED | AN39: 0.88 | AO39: 0.88 | AP39: OUTDATED | AQ39: OUTDATED | AR39: OUTDATED | AS39: 0.94 | AT39: OUTDATED | AU39: 0.88 | AV39: OUTDATED | AW39: NEXT ROUND | AX39: 0.76 | AY39: OUTDATED | AZ39: 0.82 | BA39: 0.88 | BB39: OUTDATED | BC39: 1 | BD39: PREVIOUSLY APPROVED | BE39: PREVIOUSLY APPROVED | BF39: PREVIOUSLY APPROVED | BG39: PREVIOUSLY APPROVED | BH39: PREVIOUSLY APPROVED | BI39: PREVIOUSLY APPROVED | BJ39: PREVIOUSLY APPROVED | BK39: PREVIOUSLY APPROVED | BL39: PREVIOUSLY APPROVED | BM39: PREVIOUSLY APPROVED | BN39: CLOSED | BO39: PREVIOUSLY APPROVED | BP39: =IFERROR(__xludf.DUMMYFUNCTION("IFERROR( INDEX( FILTER(X39:BK39, ISNUMBER(X39:BK39)), COUNTA(FILTER(X39:BK39, ISNUMBER(X39:BK39))) ), BK39 )"),1.0) -> 1
A40: 30 | B40: AUTOBRÁS | C40: 1118 | D40: AUTOBRÁS | E40: 1118 | F40: =IFERROR(VLOOKUP(M40:M113,'R22 RELATÓRIO ACC'!B:F,5,FALSE),"NOT PUBLISHED") -> V15 | G40: =IFERROR(VLOOKUP(M40:M111,'R22 RELATÓRIO ACC'!B:P,15,FALSE),"NOT PUBLISHED") -> 15/04/2026 | H40: =IFERROR(VLOOKUP(N40:N113,'RELATÓRIO ACC'!B:F,5,FALSE),"NOT PUBLISHED") -> V2 | I40: =IFERROR(VLOOKUP(N40:N111,'RELATÓRIO ACC'!B:P,15,FALSE),"NOT PUBLISHED") -> 02/06/2026 | J40: 45910 | K40: V7 | L40: MODELO FOI ATUALIZADO | M40: CPQ11-DALI-DEVS-DATA-R22.rvt | N40: CPQ11-DALI-DEVS-DATA-R24.rvt | O40: DALI-DEVS-DATA | P40: FALSE | Q40: ABERTO | R40: FOI AUDITADO R8 | S40: FINALIZADO | T40: FINALIZADO | U40: ALINNE | V40: 45911 | W40: 45911 | X40: NOT PUBLISHED | Y40: NOT PUBLISHED | Z40: NOT PUBLISHED | AA40: NOT PUBLISHED | AB40: NOT PUBLISHED | AC40: 0.65 | AD40: OUTDATED | AE40: 1 | AF40: 1 | AG40: 1 | AH40: 1 | AI40: 1 | AJ40: 1 | AK40: 1 | AL40: 1 | AM40: 1 | AN40: 1 | AO40: 1 | AP40: 1 | AQ40: 1 | AR40: 1 | AS40: 1 | AT40: 1 | AU40: 1 | AV40: 1 | AW40: 1 | AX40: 1 | AY40: 1 | AZ40: 1 | BA40: PREVIOUSLY APPROVED | BB40: PREVIOUSLY APPROVED | BC40: PREVIOUSLY APPROVED | BD40: PREVIOUSLY APPROVED | BE40: PREVIOUSLY APPROVED | BF40: PREVIOUSLY APPROVED | BG40: PREVIOUSLY APPROVED | BH40: PREVIOUSLY APPROVED | BI40: PREVIOUSLY APPROVED | BJ40: PREVIOUSLY APPROVED | BK40: PREVIOUSLY APPROVED | BL40: PREVIOUSLY APPROVED | BM40: PREVIOUSLY APPROVED | BN40: CLOSED | BO40: PREVIOUSLY APPROVED | BP40: =IFERROR(__xludf.DUMMYFUNCTION("IFERROR( INDEX( FILTER(X40:BK40, ISNUMBER(X40:BK40)), COUNTA(FILTER(X40:BK40, ISNUMBER(X40:BK40))) ), BK40 )"),1.0) -> 1
