Workbook

Sheet LOD 300 - CONTROL
D1: SPECIFIC AUDIT CONTROL | LOD 300
B2: META DO DIA 17/07 | V2: CONTROLE INTERNO (OCULTAR) | W2: ADMN | BK2: COLO1 | CY2: COLO2 | EI2: COLO3 | EZ2: COL4 | FB2: ANNEXES
B3: FILE NAME (R24) | C3: FILE NAME (R22) | D3: AREA | E3: TRADE COMPANY | F3: CODE | G3: BIM COMPANY | H3: CODE | I3: ACC VERSION (R22) | J3: ACC FILE DATE (R22) | K3: ACC VERSION (R24) | L3: ACC FILE DATE (R24) | M3: VERSION (ADMN/COLO1/COLO2 AND ANNEXES) | N3: FILE DATE (ADMN/COLO1/COLO2 AND ANNEXES) | O3: RVT TYPE APROVAL (ADMN/COL1/COL2/ANNEXES) | P3: VERSION (COLO3) | Q3: FILE DATE (COLO3) | R3: RVT TYPE APROVAL (COLO3) | S3: VERSION (COLO4) | T3: FILE DATE (COLO4) | U3: RVT TYPE APROVAL (COLO4) | V3: RESPONSÁVEL DA ANÁLISE | W3: R1 - APPROVAL (%) | X3: R2 - APPROVAL (%) | Y3: R3 - APPROVAL (%) | Z3: R4 - APPROVAL (%) | AA3: R5 - APPROVAL (%) | AB3: R6 - APPROVAL (%) | AC3: R7 - APPROVAL (%) | AD3: R8 - APPROVAL (%) | AE3: R9 - APPROVAL (%) | AF3: R10 - APPROVAL (%) | AG3: R11 - APPROVAL (%) | AH3: R12 - APPROVAL (%) | AI3: R13 - APPROVAL (%) | AJ3: R14 - APPROVAL (%) | AK3: R15 - APPROVAL (%) | AL3: R16 - APPROVAL (%) | AM3: R17 - APPROVAL (%) | AN3: R18 - APPROVAL (%) | AO3: R19 - APPROVAL (%) | AP3: R20 - APPROVAL (%) | AQ3: R21 - APPROVAL (%) | AR3: R22 - APPROVAL (%) | AS3: R23 - APPROVAL (%) | AT3: R24 - APPROVAL (%) | AU3: R25 - APPROVAL (%) | AV3: R26 - APPROVAL (%) | AW3: R27 - APPROVAL (%) | AX3: R28 - APPROVAL (%) | AY3: R29 - APPROVAL (%) | AZ3: R30 - APPROVAL (%) | BA3: R31 - APPROVAL (%) | BB3: R32 - APPROVAL (%) | BC3: R33 - APPROVAL (%) | BD3: R34 - APPROVAL (%) | BE3: R35 - APPROVAL (%) | BF3: R36 - APPROVAL (%) | BG3: R37 - APPROVAL (%) | BH3: R38 - APPROVAL (%) | BI3: R39 - APPROVAL (%) | BJ3: GERAL | BK3: R1 - APPROVAL (%) | BL3: R2 - APPROVAL (%) | BM3: R3 - APPROVAL (%) | BN3: R4 - APPROVAL (%) | BO3: R5 - APPROVAL (%) | BP3: R6 - APPROVAL (%) | BQ3: R7 - APPROVAL (%) | BR3: R8 - APPROVAL (%) | BS3: R9 - APPROVAL (%) | BT3: R10 - APPROVAL (%) | BU3: R11 - APPROVAL (%) | BV3: R12 - APPROVAL (%) | BW3: R13 - APPROVAL (%) | BX3: R14 - APPROVAL (%) | BY3: R15 - APPROVAL (%) | BZ3: R16 - APPROVAL (%) | CA3: R17 - APPROVAL (%) | CB3: R18 - APPROVAL (%) | CC3: R19 - APPROVAL (%) | CD3: R20 - APPROVAL (%) | CE3: R21 - APPROVAL (%) | CF3: R22 - APPROVAL (%) | CG3: R23 - APPROVAL (%) | CH3: R24 - APPROVAL (%) | CI3: R25 - APPROVAL (%) | CJ3: R26 - APPROVAL (%) | CK3: R27 - APPROVAL (%) | CL3: R28 - APPROVAL (%) | CM3: R29 - APPROVAL (%) | CN3: R30 - APPROVAL (%) | CO3: R31 - APPROVAL (%) | CP3: R32 - APPROVAL (%) | CQ3: R33 - APPROVAL (%) | CR3: R34 - APPROVAL (%) | CS3: R35 - APPROVAL (%) | CT3: R36 - APPROVAL (%) | CU3: R37 - APPROVAL (%) | CV3: R38 - APPROVAL (%) | CW3: R39 - APPROVAL (%) | CX3: GERAL | CY3: R1 - APPROVAL (%) | CZ3: R2 - APPROVAL (%) | DA3: R3 - APPROVAL (%) | DB3: R4 - APPROVAL (%) | DC3: R5 - APPROVAL (%) | DD3: R6 - APPROVAL (%) | DE3: R7 - APPROVAL (%) | DF3: R8 - APPROVAL (%) | DG3: R9 - APPROVAL (%) | DH3: R10 - APPROVAL (%) | DI3: R11 - APPROVAL (%) | DJ3: R12 - APPROVAL (%) | DK3: R13 - APPROVAL (%) | DL3: R14 - APPROVAL (%) | DM3: R15 - APPROVAL (%) | DN3: R16 - APPROVAL (%) | DO3: R17 - APPROVAL (%) | DP3: R18 - APPROVAL (%) | DQ3: R19 - APPROVAL (%) | DR3: R20 - APPROVAL (%) | DS3: R21 - APPROVAL (%) | DT3: R22 - APPROVAL (%) | DU3: R23 - APPROVAL (%) | DV3: R24 - APPROVAL (%) | DW3: R25 - APPROVAL (%) | DX3: R26 - APPROVAL (%) | DY3: R27 - APPROVAL (%) | DZ3: R28 - APPROVAL (%) | EA3: R29 - APPROVAL (%) | EB3: R30 - APPROVAL (%) | EC3: R31 - APPROVAL (%) | ED3: R32 - APPROVAL (%) | EE3: R33 - APPROVAL (%) | EF3: R34 - APPROVAL (%) | EG3: R35 - APPROVAL (%) | EH3: GERAL | EI3: R1 - APPROVAL (%) | EJ3: R2 - APPROVAL (%) | EK3: R3 - APPROVAL (%) | EL3: R4- APPROVAL (%) | EM3: R5- APPROVAL (%) | EN3: R6- APPROVAL (%) | EO3: R7- APPROVAL (%) | EP3: R8- APPROVAL (%) | EQ3: R9- APPROVAL (%) | ER3: R10- APPROVAL (%) | ES3: R11- APPROVAL (%) | ET3: R12- APPROVAL (%) | EU3: R13- APPROVAL (%) | EV3: R14- APPROVAL (%) | EW3: R15- APPROVAL (%) | EX3: R16- APPROVAL (%) | EY3: GERAL | EZ3: R1 - APPROVAL (%) | FA3: GERAL | FB3: R1 - APPROVAL (%) | FC3: R2 - APPROVAL (%) | FD3: R3 - APPROVAL (%) | FE3: R4 - APPROVAL (%) | FF3: R5 - APPROVAL (%) | FG3: R6 - APPROVAL (%) | FH3: R7 - APPROVAL (%) | FI3: R8 - APPROVAL (%) | FJ3: R9 - APPROVAL (%) | FK3: R10 - APPROVAL (%) | FL3: R11 - APPROVAL (%) | FM3: R12 - APPROVAL (%) | FN3: R13 - APPROVAL (%) | FO3: R14 - APPROVAL (%) | FP3: R15 - APPROVAL (%) | FQ3: R16 - APPROVAL (%) | FR3: R17 - APPROVAL (%) | FS3: R18 - APPROVAL (%) | FT3: R19 - APPROVAL (%) | FU3: R20 - APPROVAL (%) | FV3: R21 - APPROVAL (%) | FW3: R22 - APPROVAL (%) | FX3: R23 - APPROVAL (%) | FY3: R24 - APPROVAL (%) | FZ3: R25 - APPROVAL (%) | GA3: R26 - APPROVAL (%) | GB3: R27 - APPROVAL (%) | GC3: R28 - APPROVAL (%) | GD3: R29 - APPROVAL (%) | GE3: R30 - APPROVAL (%) | GF3: R31 - APPROVAL (%) | GG3: R32 - APPROVAL (%) | GH3: R33 - APPROVAL (%) | GI3: R34 - APPROVAL (%) | GJ3: R35 - APPROVAL (%) | GK3: R36 - APPROVAL (%) | GL3: R37 - APPROVAL (%) | GM3: GERAL
A4: 1 | B4: ARCH | ARCHITECTURE
A5: 2 | B5: CPQ11-ARCH-ARCH-DATA-R24.rvt | C5: CPQ11-ARCH-ARCH-DATA-R22.rvt | D5: DATA | E5: ARE ARQUITETURA | F5: 1130 | G5: ARE ARQUITETURA | H5: 1130 | I5: =IFERROR(VLOOKUP(C2:C144,'R22 RELATÓRIO ACC'!B:F,5,FALSE),"NOT PUBLISHED") -> V29 | J5: =IFERROR(VLOOKUP(C2:C144,'R22 RELATÓRIO ACC'!B:P,15,FALSE),"NOT PUBLISHED") -> 13/04/2026 | K5: =IFERROR(VLOOKUP(B2:B188,'RELATÓRIO ACC'!B:F,5,FALSE),"NOT PUBLISHED") -> V3 | L5: =IFERROR(VLOOKUP(B2:B188,'RELATÓRIO ACC'!B:P,15,FALSE),"NOT PUBLISHED") -> 03/06/2026 | M5: =IF(OR($D5="UTLS",$D5="GUAR",$D5="STIR",$D5="PUMP",$D5="SITE"), VLOOKUP($B5,'LOD 300 - SITE'!B:M,12,FALSE), VLOOKUP($B5,'LOD 300 - ADMN'!B:M,12,FALSE) ) -> V20 | N5: =IF(OR($D5="UTLS",$D5="GUAR",$D5="STIR",$D5="PUMP",$D5="SITE"), VLOOKUP($B5,'LOD 300 - SITE'!B:N,13,FALSE), VLOOKUP($B5,'LOD 300 - ADMN'!B:N,13,FALSE) ) -> 04/11/2025 | O5: =IF(OR($D5="UTLS",$D5="GUAR",$D5="STIR",$D5="PUMP",$D5="SITE"), VLOOKUP($B5,'LOD 300 - SITE'!B:O,14,FALSE), VLOOKUP($B5,'LOD 300 - ADMN'!B:O,14,FALSE) ) -> R22 | P5: =IF(OR($D5="C345",$D5="C12A",$D5="DATA"), VLOOKUP($B5,'LOD 300 - COLO3'!B:M,12,FALSE),"N/A") -> V29 | Q5: =IF(OR($D5="C345",$D5="C12A",$D5="DATA"), VLOOKUP($B5,'LOD 300 - COLO3'!B:N,13,FALSE),"N/A") -> 46125 | R5: =IF(OR($D5="C345",$D5="C12A",$D5="DATA"), VLOOKUP($B5,'LOD 300 - COLO3'!B:O,14,FALSE),"N/A") -> R22 | S5: =IF(OR($D5="C345",$D5="C12A",$D5="DATA"), VLOOKUP($B5,'LOD 300 - COLO4'!B:M,12,FALSE),"N/A") -> N/A | T5: =IF(OR($D5="C345",$D5="C12A",$D5="DATA"), VLOOKUP($B5,'LOD 300 - COLO4'!B:T,13,FALSE),"N/A") -> N/A | U5: =IF(OR($D5="C345",$D5="C12A",$D5="DATA"), VLOOKUP($B5,'LOD 300 - COLO4'!B:U,17,FALSE),"N/A") -> 0 | V5: CICI | W5: =IFERROR(VLOOKUP($B5,'LOD 300 - ADMN'!$B:S,18,FALSE),"N/A") -> 0.58 | X5: =IFERROR(VLOOKUP($B5,'LOD 300 - ADMN'!$B:V,21,FALSE),"N/A") -> OUTDATED MODEL | Y5: =IFERROR(VLOOKUP($B5,'LOD 300 - ADMN'!$B:Y,24,FALSE),"N/A") -> 0.73 | Z5: =IFERROR(VLOOKUP($B5,'LOD 300 - ADMN'!$B:AB,27,FALSE),"N/A") -> 0.77 | AA5: =IFERROR(VLOOKUP($B5,'LOD 300 - ADMN'!$B:AE,30,FALSE),"N/A") -> OUTDATED MODEL | AB5: =IFERROR(VLOOKUP($B5,'LOD 300 - ADMN'!$B:AH,33,FALSE),"N/A") -> OUTDATED MODEL | AC5: =IFERROR(VLOOKUP($B5,'LOD 300 - ADMN'!$B:AK,36,FALSE),"N/A") -> OUTDATED MODEL | AD5: =IFERROR(VLOOKUP($B5,'LOD 300 - ADMN'!$B:AN,39,FALSE),"N/A") -> 0.87 | AE5: =IFERROR(VLOOKUP($B5,'LOD 300 - ADMN'!$B:AQ,42,FALSE),"N/A") -> OUTDATED MODEL | AF5: =IFERROR(VLOOKUP($B5,'LOD 300 - ADMN'!$B:AT,45,FALSE),"N/A") -> NEXT ROUND | AG5: =IFERROR(VLOOKUP($B5,'LOD 300 - ADMN'!$B:AW,48,FALSE),"N/A") -> 1 | AH5: =IFERROR(VLOOKUP($B5,'LOD 300 - ADMN'!$B:AZ,51,FALSE),"N/A") -> 1 | AI5: =IFERROR(VLOOKUP($B5,'LOD 300 - ADMN'!$B:BC,54,FALSE),"N/A") -> 1 | AJ5: =IFERROR(VLOOKUP($B5,'LOD 300 - ADMN'!$B:BF,57,FALSE),"N/A") -> 1 | AK5: =IFERROR(VLOOKUP($B5,'LOD 300 - ADMN'!$B:EP,60,FALSE),"N/A") -> 1 | AL5: =IFERROR(VLOOKUP($B5,'LOD 300 - ADMN'!$B:EQ,63,FALSE),"N/A") -> 1 | AM5: =IFERROR(VLOOKUP($B5,'LOD 300 - ADMN'!$B:BO,66,FALSE),"N/A") -> 1 | AN5: =IFERROR(VLOOKUP($B5,'LOD 300 - ADMN'!$B:BR,69,FALSE),"N/A") -> 1 | AO5: =IFERROR(VLOOKUP($B5,'LOD 300 - ADMN'!$B:BU,72,FALSE),"N/A") -> 1 | AP5: =IFERROR(VLOOKUP($B5,'LOD 300 - ADMN'!$B:BX,75,FALSE),"N/A") -> 1 | AQ5: =IFERROR(VLOOKUP($B5,'LOD 300 - ADMN'!$B:CA,78,FALSE),"N/A") -> 1 | AR5: =IFERROR(VLOOKUP($B5,'LOD 300 - ADMN'!$B:CD,81,FALSE),"N/A") -> 1 | AS5: =IFERROR(VLOOKUP($B5,'LOD 300 - ADMN'!$B:CG,84,FALSE),"N/A") -> 1 | AT5: =IFERROR(VLOOKUP($B5,'LOD 300 - ADMN'!$B:CJ,87,FALSE),"N/A") -> 1 | AU5: =IFERROR(VLOOKUP($B5,'LOD 300 - ADMN'!$B:CM,90,FALSE),"N/A") -> 1 | AV5: =IFERROR(VLOOKUP($B5,'LOD 300 - ADMN'!$B:CP,93,FALSE),"N/A") -> 1 | AW5: =IFERROR(VLOOKUP($B5,'LOD 300 - ADMN'!$B:CS,96,FALSE),"N/A") -> 1 | AX5: =IFERROR(VLOOKUP($B5,'LOD 300 - ADMN'!$B:CV,99,FALSE),"N/A") -> 1 | AY5: =IFERROR(VLOOKUP($B5,'LOD 300 - ADMN'!$B:CY,102,FALSE),"N/A") -> 1 | AZ5: =IFERROR(VLOOKUP($B5,'LOD 300 - ADMN'!$B:DB,105,FALSE),"N/A") -> 1 | BA5: =IFERROR(VLOOKUP($B5,'LOD 300 - ADMN'!$B:DE,108,FALSE),"N/A") -> 1 | BB5: =IFERROR(VLOOKUP($B5,'LOD 300 - ADMN'!$B:DH,111,FALSE),"N/A") -> 1 | BC5: =IFERROR(VLOOKUP($B5,'LOD 300 - ADMN'!$B:DK,114,FALSE),"N/A") -> 1 | BD5: =IFERROR(VLOOKUP($B5,'LOD 300 - ADMN'!$B:DN,117,FALSE),"N/A") -> 1 | BE5: =IFERROR(VLOOKUP($B5,'LOD 300 - ADMN'!$B:DQ,120,FALSE),"N/A") -> 1 | BF5: =IFERROR(VLOOKUP($B5,'LOD 300 - ADMN'!$B:DT,123,FALSE),"N/A") -> 1 | BG5: =IFERROR(VLOOKUP($B5,'LOD 300 - ADMN'!$B:DW,126,FALSE),"N/A") -> 1 | BH5: =IFERROR(VLOOKUP($B5,'LOD 300 - ADMN'!$B:DZ,129,FALSE),"N/A") -> 1 | BI5: =IFERROR(VLOOKUP($B5,'LOD 300 - ADMN'!$B:EC,132,FALSE),"N/A") -> 1 | BJ5: =IFERROR(__xludf.DUMMYFUNCTION("IFERROR( MAX(FILTER(X5:BI5, ISNUMBER(X5:BI5))), BI5 )"),1.0) -> 1 | BK5: =IFERROR(VLOOKUP($B5,'LOD 300 - COLO1'!$B:S,18,FALSE),"N/A") -> 0.6 | BL5: =IFERROR(VLOOKUP($B5,'LOD 300 - COLO1'!$B:V,21,FALSE),"N/A") -> OUTDATED MODEL | BM5: =IFERROR(VLOOKUP($B5,'LOD 300 - COLO1'!$B:Y,24,FALSE),"N/A") -> 0.78 | BN5: =IFERROR(VLOOKUP($B5,'LOD 300 - COLO1'!$B:AB,27,FALSE),"N/A") -> 0.78 | BO5: =IFERROR(VLOOKUP($B5,'LOD 300 - COLO1'!$B:AE,30,FALSE),"N/A") -> OUTDATED MODEL | BP5: =IFERROR(VLOOKUP($B5,'LOD 300 - COLO1'!$B:AH,33,FALSE),"N/A") -> OUTDATED MODEL | BQ5: =IFERROR(VLOOKUP($B5,'LOD 300 - COLO1'!$B:AK,36,FALSE),"N/A") -> OUTDATED MODEL | BR5: =IFERROR(VLOOKUP($B5,'LOD 300 - COLO1'!$B:AN,39,FALSE),"N/A") -> 0.93 | BS5: =IFERROR(VLOOKUP($B5,'LOD 300 - COLO1'!$B:AQ,42,FALSE),"N/A") -> OUTDATED MODEL | BT5: =IFERROR(VLOOKUP($B5,'LOD 300 - COLO1'!$B:AT,45,FALSE),"N/A") -> NEXT ROUND | BU5: =IFERROR(VLOOKUP($B5,'LOD 300 - COLO1'!$B:AW,48,FALSE),"N/A") -> 1 | BV5: =IFERROR(VLOOKUP($B5,'LOD 300 - COLO1'!$B:AZ,51,FALSE),"N/A") -> 1 | BW5: =IFERROR(VLOOKUP($B5,'LOD 300 - COLO1'!$B:BC,54,FALSE),"N/A") -> 1 | BX5: =IFERROR(VLOOKUP($B5,'LOD 300 - COLO1'!$B:BF,57,FALSE),"N/A") -> 1 | BY5: =IFERROR(VLOOKUP($B5,'LOD 300 - COLO1'!$B:BI,60,FALSE),"N/A") -> 1 | BZ5: =IFERROR(VLOOKUP($B5,'LOD 300 - COLO1'!$B:BL,63,FALSE),"N/A") -> 1 | CA5: =IFERROR(VLOOKUP($B5,'LOD 300 - COLO1'!$B:BO,66,FALSE),"N/A") -> 1 | CB5: =IFERROR(VLOOKUP($B5,'LOD 300 - COLO1'!$B:BR,69,FALSE),"N/A") -> 1 | CC5: =IFERROR(VLOOKUP($B5,'LOD 300 - COLO1'!$B:BU,72,FALSE),"N/A") -> 1 | CD5: =IFERROR(VLOOKUP($B5,'LOD 300 - COLO1'!$B:BX,75,FALSE),"N/A") -> 1 | CE5: =IFERROR(VLOOKUP($B5,'LOD 300 - COLO1'!$B:CA,78,FALSE),"N/A") -> 1 | CF5: =IFERROR(VLOOKUP($B5,'LOD 300 - COLO1'!$B:CD,81,FALSE),"N/A") -> 1 | CG5: =IFERROR(VLOOKUP($B5,'LOD 300 - COLO1'!$B:CG,84,FALSE),"N/A") -> 1 | CH5: =IFERROR(VLOOKUP($B5,'LOD 300 - COLO1'!$B:CJ,87,FALSE),"N/A") -> 1 | CI5: =IFERROR(VLOOKUP($B5,'LOD 300 - COLO1'!$B:CM,90,FALSE),"N/A") -> 1 | CJ5: =IFERROR(VLOOKUP($B5,'LOD 300 - COLO1'!$B:CP,93,FALSE),"N/A") -> 1 | CK5: =IFERROR(VLOOKUP($B5,'LOD 300 - COLO1'!$B:CS,96,FALSE),"N/A") -> 1 | CL5: =IFERROR(VLOOKUP($B5,'LOD 300 - COLO1'!$B:CV,99,FALSE),"N/A") -> 1 | CM5: =IFERROR(VLOOKUP($B5,'LOD 300 - COLO1'!$B:CY,102,FALSE),"N/A") -> 1 | CN5: =IFERROR(VLOOKUP($B5,'LOD 300 - COLO1'!$B:DB,105,FALSE),"N/A") -> 1 | CO5: =IFERROR(VLOOKUP($B5,'LOD 300 - COLO1'!$B:EE,108,FALSE),"N/A") -> 1 | CP5: =IFERROR(VLOOKUP($B5,'LOD 300 - COLO1'!$B:EH,111,FALSE),"N/A") -> 1 | CQ5: =IFERROR(VLOOKUP($B5,'LOD 300 - COLO1'!$B:EK,114,FALSE),"N/A") -> 1 | CR5: =IFERROR(VLOOKUP($B5,'LOD 300 - COLO1'!$B:EN,117,FALSE),"N/A") -> 1 | CS5: =IFERROR(VLOOKUP($B5,'LOD 300 - COLO1'!$B:EQ,120,FALSE),"N/A") -> 1 | CT5: =IFERROR(VLOOKUP($B5,'LOD 300 - COLO1'!$B:ET,123,FALSE),"N/A") -> 1 | CU5: =IFERROR(VLOOKUP($B5,'LOD 300 - COLO1'!$B:EW,126,FALSE),"N/A") -> 1 | CV5: =IFERROR(VLOOKUP($B5,'LOD 300 - COLO1'!$B:EZ,129,FALSE),"N/A") -> 1 | CW5: =IFERROR(VLOOKUP($B5,'LOD 300 - COLO1'!$B:FC,132,FALSE),"N/A") -> 1 | CX5: =IFERROR(__xludf.DUMMYFUNCTION("IFERROR( MAX(FILTER(BK5:CW5, ISNUMBER(BK5:CW5))), CW5 )"),1.0) -> 1 | CY5: =IFERROR(VLOOKUP($B5,'LOD 300 - COLO2'!$B:S,18,FALSE),"N/A") -> 0.73 | CZ5: =IFERROR(VLOOKUP($B5,'LOD 300 - COLO2'!$B:V,21,FALSE),"N/A") -> OUTDATED MODEL | DA5: =IFERROR(VLOOKUP($B5,'LOD 300 - COLO2'!$B:Y,24,FALSE),"N/A") -> OUTDATED MODEL | DB5: =IFERROR(VLOOKUP($B5,'LOD 300 - COLO2'!$B:AB,27,FALSE),"N/A") -> 0.84 | DC5: =IFERROR(VLOOKUP($B5,'LOD 300 - COLO2'!$B:AE,30,FALSE),"N/A") -> OUTDATED MODEL | DD5: =IFERROR(VLOOKUP($B5,'LOD 300 - COLO2'!$B:AH,33,FALSE),"N/A") -> NEXT ROUND | DE5: =IFERROR(VLOOKUP($B5,'LOD 300 - COLO2'!$B:AK,36,FALSE),"N/A") -> 1 | DF5: =IFERROR(VLOOKUP($B5,'LOD 300 - COLO2'!$B:AN,39,FALSE),"N/A") -> 1 | DG5: =IFERROR(VLOOKUP($B5,'LOD 300 - COLO2'!$B:AQ,42,FALSE),"N/A") -> 1 | DH5: =IFERROR(VLOOKUP($B5,'LOD 300 - COLO2'!$B:AT,45,FALSE),"N/A") -> 1 | DI5: =IFERROR(VLOOKUP($B5,'LOD 300 - COLO2'!$B:AW,48,FALSE),"N/A") -> 1 | DJ5: =IFERROR(VLOOKUP($B5,'LOD 300 - COLO2'!$B:AZ,51,FALSE),"N/A") -> 1 | DK5: =IFERROR(VLOOKUP($B5,'LOD 300 - COLO2'!$B:BC,54,FALSE),"N/A") -> 1 | DL5: =IFERROR(VLOOKUP($B5,'LOD 300 - COLO2'!$B:BF,57,FALSE),"N/A") -> 1 | DM5: =IFERROR(VLOOKUP($B5,'LOD 300 - COLO2'!$B:BI,60,FALSE),"N/A") -> 1 | DN5: =IFERROR(VLOOKUP($B5,'LOD 300 - COLO2'!$B:BL,63,FALSE),"N/A") -> 1 | DO5: =IFERROR(VLOOKUP($B5,'LOD 300 - COLO2'!$B:BO,66,FALSE),"N/A") -> 1 | DP5: =IFERROR(VLOOKUP($B5,'LOD 300 - COLO2'!$B:BR,69,FALSE),"N/A") -> 1 | DQ5: =IFERROR(VLOOKUP($B5,'LOD 300 - COLO2'!$B:BU,72,FALSE),"N/A") -> 1 | DR5: =IFERROR(VLOOKUP($B5,'LOD 300 - COLO2'!$B:BX,75,FALSE),"N/A") -> 1 | DS5: =IFERROR(VLOOKUP($B5,'LOD 300 - COLO2'!$B:CA,78,FALSE),"N/A") -> 1 | DT5: =IFERROR(VLOOKUP($B5,'LOD 300 - COLO2'!$B:CD,81,FALSE),"N/A") -> 1 | DU5: =IFERROR(VLOOKUP($B5,'LOD 300 - COLO2'!$B:CG,84,FALSE),"N/A") -> 1 | DV5: =IFERROR(VLOOKUP($B5,'LOD 300 - COLO2'!$B:CJ,87,FALSE),"N/A") -> 1 | DW5: =IFERROR(VLOOKUP($B5,'LOD 300 - COLO2'!$B:CM,90,FALSE),"N/A") -> 1 | DX5: =IFERROR(VLOOKUP($B5,'LOD 300 - COLO2'!$B:CP,93,FALSE),"N/A") -> 1 | DY5: =IFERROR(VLOOKUP($B5,'LOD 300 - COLO2'!$B:CS,96,FALSE),"N/A") -> 1 | DZ5: =IFERROR(VLOOKUP($B5,'LOD 300 - COLO2'!$B:CV,99,FALSE),"N/A") -> 1 | EA5: =IFERROR(VLOOKUP($B5,'LOD 300 - COLO2'!$B:DB,105,FALSE),"N/A") -> 1 | EB5: =IFERROR(VLOOKUP($B5,'LOD 300 - COLO2'!$B:DB,105,FALSE),"N/A") -> 1 | EC5: =IFERROR(VLOOKUP($B5,'LOD 300 - COLO2'!$B:DE,108,FALSE),"N/A") -> 1 | ED5: =IFERROR(VLOOKUP($B5,'LOD 300 - COLO2'!$B:DH,111,FALSE),"N/A") -> 1 | EE5: =IFERROR(VLOOKUP($B5,'LOD 300 - COLO2'!$B:DK,114,FALSE),"N/A") -> 1 | EF5: =IFERROR(VLOOKUP($B5,'LOD 300 - COLO2'!$B:DN,117,FALSE),"N/A") -> 1 | EG5: =IFERROR(VLOOKUP($B5,'LOD 300 - COLO2'!$B:DQ,120,FALSE),"N/A") -> 1 | EH5: =IFERROR(__xludf.DUMMYFUNCTION("IFERROR( MAX(FILTER(CZ5:EG5, ISNUMBER(CZ5:EG5))), EG5 )"),1.0) -> 1 | EI5: =IFERROR(VLOOKUP($B5,'LOD 300 - COLO3'!$B:R,17,FALSE),"N/A") -> 0 | EJ5: =IFERROR(VLOOKUP($B5,'LOD 300 - COLO3'!$B:U,20,FALSE),"N/A") -> 0.97 | EK5: =IFERROR(VLOOKUP($B5,'LOD 300 - COLO3'!$B:X,23,FALSE),"N/A") -> NEXT ROUND | EL5: =IFERROR(VLOOKUP($B5,'LOD 300 - COLO3'!$B:AA,26,FALSE),"N/A") -> 1 | EM5: =IFERROR(VLOOKUP($B5,'LOD 300 - COLO3'!$B:AD,29,FALSE),"N/A") -> 1 | EN5: =IFERROR(VLOOKUP($B5,'LOD 300 - COLO3'!$B:AG,32,FALSE),"N/A") -> 1 | EO5: =IFERROR(VLOOKUP($B5,'LOD 300 - COLO3'!$B:AJ,35,FALSE),"N/A") -> 1 | EP5: =IFERROR(VLOOKUP($B5,'LOD 300 - COLO3'!$B:AM,38,FALSE),"N/A") -> 1 | EQ5: =IFERROR(VLOOKUP($B5,'LOD 300 - COLO3'!$B:AP,41,FALSE),"N/A") -> 1 | ER5: =IFERROR(VLOOKUP($B5,'LOD 300 - COLO3'!$B:AS,44,FALSE),"N/A") -> 1 | ES5: =IFERROR(VLOOKUP($B5,'LOD 300 - COLO3'!$B:AV,47,FALSE),"N/A") -> 1 | ET5: =IFERROR(VLOOKUP($B5,'LOD 300 - COLO3'!$B:AY,50,FALSE),"N/A") -> 1 | EU5: =IFERROR(VLOOKUP($B5,'LOD 300 - COLO3'!$B:BB,53,FALSE),"N/A") -> 1 | EV5: =IFERROR(VLOOKUP($B5,'LOD 300 - COLO3'!$B:BE,56,FALSE),"N/A") -> 1 | EW5: =IFERROR(VLOOKUP($B5,'LOD 300 - COLO3'!$B:BL,59,FALSE),"N/A") -> 1 | EX5: =IFERROR(VLOOKUP($B5,'LOD 300 - COLO3'!$B:BO,62,FALSE),"N/A") -> 1 | EY5: =IFERROR(__xludf.DUMMYFUNCTION("IFERROR( MAX(FILTER(EI5:EX5, ISNUMBER(EI5:EX5))), EX5 )"),1.0) -> 1 | EZ5: =IFERROR(VLOOKUP($B5,'LOD 300 - COLO4'!$B:BT,17,FALSE),"N/A") -> 0 | FA5: =IFERROR(__xludf.DUMMYFUNCTION("IFERROR( MAX(FILTER(EZ5, ISNUMBER(EZ5))), EZ5 )"),0.0) -> 0 | FB5: =IFERROR(VLOOKUP($B5,'LOD 300 - SITE'!$B:S,18,FALSE),"N/A") -> N/A | FC5: =IFERROR(VLOOKUP($B5,'LOD 300 - SITE'!$B:V,21,FALSE),"N/A") -> N/A | FD5: =IFERROR(VLOOKUP($B5,'LOD 300 - SITE'!$B:Y,24,FALSE),"N/A") -> N/A | FE5: =IFERROR(VLOOKUP($B5,'LOD 300 - SITE'!$B:AB,27,FALSE),"N/A") -> N/A | FF5: =IFERROR(VLOOKUP($B5,'LOD 300 - SITE'!$B:AE,30,FALSE),"N/A") -> N/A | FG5: =IFERROR(VLOOKUP($B5,'LOD 300 - SITE'!$B:AH,33,FALSE),"N/A") -> N/A | FH5: =IFERROR(VLOOKUP($B5,'LOD 300 - SITE'!$B:AK,36,FALSE),"N/A") -> N/A | FI5: =IFERROR(VLOOKUP($B5,'LOD 300 - SITE'!$B:AN,39,FALSE),"N/A") -> N/A | FJ5: =IFERROR(VLOOKUP($B5,'LOD 300 - SITE'!$B:AQ,42,FALSE),"N/A") -> N/A | FK5: =IFERROR(VLOOKUP($B5,'LOD 300 - SITE'!$B:AT,45,FALSE),"N/A") -> N/A | FL5: =IFERROR(VLOOKUP($B5,'LOD 300 - SITE'!$B:AW,48,FALSE),"N/A") -> N/A | FM5: =IFERROR(VLOOKUP($B5,'LOD 300 - SITE'!$B:AZ,51,FALSE),"N/A") -> N/A | FN5: =IFERROR(VLOOKUP($B5,'LOD 300 - SITE'!$B:BC,54,FALSE),"N/A") -> N/A | FO5: =IFERROR(VLOOKUP($B5,'LOD 300 - SITE'!$B:BF,57,FALSE),"N/A") -> N/A | FP5: =IFERROR(VLOOKUP($B5,'LOD 300 - SITE'!$B:BI,60,FALSE),"N/A") -> N/A | FQ5: =IFERROR(VLOOKUP($B5,'LOD 300 - SITE'!$B:BL,63,FALSE),"N/A") -> N/A | FR5: =IFERROR(VLOOKUP($B5,'LOD 300 - SITE'!$B:BO,66,FALSE),"N/A") -> N/A | FS5: =IFERROR(VLOOKUP($B5,'LOD 300 - SITE'!$B:BR,69,FALSE),"N/A") -> N/A | FT5: =IFERROR(VLOOKUP($B5,'LOD 300 - SITE'!$B:BU,72,FALSE),"N/A") -> N/A | FU5: =IFERROR(VLOOKUP($B5,'LOD 300 - SITE'!$B:BX,75,FALSE),"N/A") -> N/A | FV5: =IFERROR(VLOOKUP($B5,'LOD 300 - SITE'!$B:CA,78,FALSE),"N/A") -> N/A | FW5: =IFERROR(VLOOKUP($B5,'LOD 300 - SITE'!$B:CD,81,FALSE),"N/A") -> N/A | FX5: =IFERROR(VLOOKUP($B5,'LOD 300 - SITE'!$B:CG,84,FALSE),"N/A") -> N/A | FY5: =IFERROR(VLOOKUP($B5,'LOD 300 - SITE'!$B:CJ,87,FALSE),"N/A") -> N/A | FZ5: =IFERROR(VLOOKUP($B5,'LOD 300 - SITE'!$B:CM,90,FALSE),"N/A") -> N/A | GA5: =IFERROR(VLOOKUP($B5,'LOD 300 - SITE'!$B:CP,93,FALSE),"N/A") -> N/A | GB5: =IFERROR(VLOOKUP($B5,'LOD 300 - SITE'!$B:CS,96,FALSE),"N/A") -> N/A | GC5: =IFERROR(VLOOKUP($B5,'LOD 300 - SITE'!$B:CV,99,FALSE),"N/A") -> N/A | GD5: =IFERROR(VLOOKUP($B5,'LOD 300 - SITE'!$B:CY,102,FALSE),"N/A") -> N/A | GE5: =IFERROR(VLOOKUP($B5,'LOD 300 - SITE'!$B:DB,105,FALSE),"N/A") -> N/A | GF5: =IFERROR(VLOOKUP($B5,'LOD 300 - SITE'!$B:DE,108,FALSE),"N/A") -> N/A | GG5: =IFERROR(VLOOKUP($B5,'LOD 300 - SITE'!$B:DH,111,FALSE),"N/A") -> N/A | GH5: =IFERROR(VLOOKUP($B5,'LOD 300 - SITE'!$B:DK,114,FALSE),"N/A") -> N/A | GI5: =IFERROR(VLOOKUP($B5,'LOD 300 - SITE'!$B:DN,117,FALSE),"N/A") -> N/A | GJ5: =IFERROR(VLOOKUP($B5,'LOD 300 - SITE'!$B:DQ,120,FALSE),"N/A") -> N/A | GK5: =IFERROR(VLOOKUP($B5,'LOD 300 - SITE'!$B:DT,123,FALSE),"N/A") -> N/A | GL5: =IFERROR(VLOOKUP($B5,'LOD 300 - SITE'!$B:DW,126,FALSE),"N/A") -> N/A | GM5: =IFERROR(__xludf.DUMMYFUNCTION("IFERROR( MAX(FILTER(FB5:GL5, ISNUMBER(FB5:GL5))), GL5 )"),"N/A") -> N/A
A6: 3 | B6: CPQ11-ARCH-ARCH-SITE-R24.rvt | C6: CPQ11-ARCH-ARCH-SITE-R22.rvt | D6: SITE | E6: ARE ARQUITETURA | F6: 1130 | G6: ARE ARQUITETURA | H6: 1130 | I6: =IFERROR(VLOOKUP(C3:C145,'R22 RELATÓRIO ACC'!B:F,5,FALSE),"NOT PUBLISHED") -> V28 | J6: =IFERROR(VLOOKUP(C3:C145,'R22 RELATÓRIO ACC'!B:P,15,FALSE),"NOT PUBLISHED") -> 17/04/2026 | K6: =IFERROR(VLOOKUP(B3:B189,'RELATÓRIO ACC'!B:F,5,FALSE),"NOT PUBLISHED") -> V4 | L6: =IFERROR(VLOOKUP(B3:B189,'RELATÓRIO ACC'!B:P,15,FALSE),"NOT PUBLISHED") -> 15/07/2026 | M6: =IF(OR($D6="UTLS",$D6="GUAR",$D6="STIR",$D6="PUMP",$D6="SITE"), VLOOKUP($B6,'LOD 300 - SITE'!B:M,12,FALSE), VLOOKUP($B6,'LOD 300 - ADMN'!B:M,12,FALSE) ) -> V19 | N6: =IF(OR($D6="UTLS",$D6="GUAR",$D6="STIR",$D6="PUMP",$D6="SITE"), VLOOKUP($B6,'LOD 300 - SITE'!B:N,13,FALSE), VLOOKUP($B6,'LOD 300 - ADMN'!B:N,13,FALSE) ) -> 17/10/2025 | O6: =IF(OR($D6="UTLS",$D6="GUAR",$D6="STIR",$D6="PUMP",$D6="SITE"), VLOOKUP($B6,'LOD 300 - SITE'!B:O,14,FALSE), VLOOKUP($B6,'LOD 300 - ADMN'!B:O,14,FALSE) ) -> R22 | P6: =IF(OR($D6="C345",$D6="C12A",$D6="DATA"), VLOOKUP($B6,'LOD 300 - COLO3'!B:M,12,FALSE),"N/A") -> N/A | Q6: =IF(OR($D6="C345",$D6="C12A",$D6="DATA"), VLOOKUP($B6,'LOD 300 - COLO3'!B:N,13,FALSE),"N/A") -> N/A | R6: =IF(OR($D6="C345",$D6="C12A",$D6="DATA"), VLOOKUP($B6,'LOD 300 - COLO3'!B:O,14,FALSE),"N/A") -> N/A | S6: =IF(OR($D6="C345",$D6="C12A",$D6="DATA"), VLOOKUP($B6,'LOD 300 - COLO4'!B:M,12,FALSE),"N/A") -> N/A | T6: =IF(OR($D6="C345",$D6="C12A",$D6="DATA"), VLOOKUP($B6,'LOD 300 - COLO4'!B:T,13,FALSE),"N/A") -> N/A | U6: =IF(OR($D6="C345",$D6="C12A",$D6="DATA"), VLOOKUP($B6,'LOD 300 - COLO4'!B:U,17,FALSE),"N/A") -> N/A | V6: ALINNE | W6: =IFERROR(VLOOKUP($B6,'LOD 300 - ADMN'!$B:S,18,FALSE),"N/A") -> N/A | X6: =IFERROR(VLOOKUP($B6,'LOD 300 - ADMN'!$B:V,21,FALSE),"N/A") -> N/A | Y6: =IFERROR(VLOOKUP($B6,'LOD 300 - ADMN'!$B:Y,24,FALSE),"N/A") -> N/A | Z6: =IFERROR(VLOOKUP($B6,'LOD 300 - ADMN'!$B:AB,27,FALSE),"N/A") -> N/A | AA6: =IFERROR(VLOOKUP($B6,'LOD 300 - ADMN'!$B:AE,30,FALSE),"N/A") -> N/A | AB6: =IFERROR(VLOOKUP($B6,'LOD 300 - ADMN'!$B:AH,33,FALSE),"N/A") -> N/A | AC6: =IFERROR(VLOOKUP($B6,'LOD 300 - ADMN'!$B:AK,36,FALSE),"N/A") -> N/A | AD6: =IFERROR(VLOOKUP($B6,'LOD 300 - ADMN'!$B:AN,39,FALSE),"N/A") -> N/A | AE6: =IFERROR(VLOOKUP($B6,'LOD 300 - ADMN'!$B:AQ,42,FALSE),"N/A") -> N/A | AF6: =IFERROR(VLOOKUP($B6,'LOD 300 - ADMN'!$B:AT,45,FALSE),"N/A") -> N/A | AG6: =IFERROR(VLOOKUP($B6,'LOD 300 - ADMN'!$B:AW,48,FALSE),"N/A") -> N/A | AH6: =IFERROR(VLOOKUP($B6,'LOD 300 - ADMN'!$B:AZ,51,FALSE),"N/A") -> N/A | AI6: =IFERROR(VLOOKUP($B6,'LOD 300 - ADMN'!$B:BC,54,FALSE),"N/A") -> N/A | AJ6: =IFERROR(VLOOKUP($B6,'LOD 300 - ADMN'!$B:BF,57,FALSE),"N/A") -> N/A | AK6: =IFERROR(VLOOKUP($B6,'LOD 300 - ADMN'!$B:EP,60,FALSE),"N/A") -> N/A | AL6: =IFERROR(VLOOKUP($B6,'LOD 300 - ADMN'!$B:EQ,63,FALSE),"N/A") -> N/A | AM6: =IFERROR(VLOOKUP($B6,'LOD 300 - ADMN'!$B:BO,66,FALSE),"N/A") -> N/A | AN6: =IFERROR(VLOOKUP($B6,'LOD 300 - ADMN'!$B:BR,69,FALSE),"N/A") -> N/A | AO6: =IFERROR(VLOOKUP($B6,'LOD 300 - ADMN'!$B:BU,72,FALSE),"N/A") -> N/A | AP6: =IFERROR(VLOOKUP($B6,'LOD 300 - ADMN'!$B:BX,75,FALSE),"N/A") -> N/A | AQ6: =IFERROR(VLOOKUP($B6,'LOD 300 - ADMN'!$B:CA,78,FALSE),"N/A") -> N/A | AR6: =IFERROR(VLOOKUP($B6,'LOD 300 - ADMN'!$B:CD,81,FALSE),"N/A") -> N/A | AS6: =IFERROR(VLOOKUP($B6,'LOD 300 - ADMN'!$B:CG,84,FALSE),"N/A") -> N/A | AT6: =IFERROR(VLOOKUP($B6,'LOD 300 - ADMN'!$B:CJ,87,FALSE),"N/A") -> N/A | AU6: =IFERROR(VLOOKUP($B6,'LOD 300 - ADMN'!$B:CM,90,FALSE),"N/A") -> N/A | AV6: =IFERROR(VLOOKUP($B6,'LOD 300 - ADMN'!$B:CP,93,FALSE),"N/A") -> N/A | AW6: =IFERROR(VLOOKUP($B6,'LOD 300 - ADMN'!$B:CS,96,FALSE),"N/A") -> N/A | AX6: =IFERROR(VLOOKUP($B6,'LOD 300 - ADMN'!$B:CV,99,FALSE),"N/A") -> N/A | AY6: =IFERROR(VLOOKUP($B6,'LOD 300 - ADMN'!$B:CY,102,FALSE),"N/A") -> N/A | AZ6: =IFERROR(VLOOKUP($B6,'LOD 300 - ADMN'!$B:DB,105,FALSE),"N/A") -> N/A | BA6: =IFERROR(VLOOKUP($B6,'LOD 300 - ADMN'!$B:DE,108,FALSE),"N/A") -> N/A | BB6: =IFERROR(VLOOKUP($B6,'LOD 300 - ADMN'!$B:DH,111,FALSE),"N/A") -> N/A | BC6: =IFERROR(VLOOKUP($B6,'LOD 300 - ADMN'!$B:DK,114,FALSE),"N/A") -> N/A | BD6: =IFERROR(VLOOKUP($B6,'LOD 300 - ADMN'!$B:DN,117,FALSE),"N/A") -> N/A | BE6: =IFERROR(VLOOKUP($B6,'LOD 300 - ADMN'!$B:DQ,120,FALSE),"N/A") -> N/A | BF6: =IFERROR(VLOOKUP($B6,'LOD 300 - ADMN'!$B:DT,123,FALSE),"N/A") -> N/A | BG6: =IFERROR(VLOOKUP($B6,'LOD 300 - ADMN'!$B:DW,126,FALSE),"N/A") -> N/A | BH6: =IFERROR(VLOOKUP($B6,'LOD 300 - ADMN'!$B:DZ,129,FALSE),"N/A") -> N/A | BI6: =IFERROR(VLOOKUP($B6,'LOD 300 - ADMN'!$B:EC,132,FALSE),"N/A") -> N/A | BJ6: =IFERROR(__xludf.DUMMYFUNCTION("IFERROR( MAX(FILTER(X6:BI6, ISNUMBER(X6:BI6))), BI6 )"),"N/A") -> N/A | BK6: =IFERROR(VLOOKUP($B6,'LOD 300 - COLO1'!$B:S,18,FALSE),"N/A") -> N/A | BL6: =IFERROR(VLOOKUP($B6,'LOD 300 - COLO1'!$B:V,21,FALSE),"N/A") -> N/A | BM6: =IFERROR(VLOOKUP($B6,'LOD 300 - COLO1'!$B:Y,24,FALSE),"N/A") -> N/A | BN6: =IFERROR(VLOOKUP($B6,'LOD 300 - COLO1'!$B:AB,27,FALSE),"N/A") -> N/A | BO6: =IFERROR(VLOOKUP($B6,'LOD 300 - COLO1'!$B:AE,30,FALSE),"N/A") -> N/A | BP6: =IFERROR(VLOOKUP($B6,'LOD 300 - COLO1'!$B:AH,33,FALSE),"N/A") -> N/A | BQ6: =IFERROR(VLOOKUP($B6,'LOD 300 - COLO1'!$B:AK,36,FALSE),"N/A") -> N/A | BR6: =IFERROR(VLOOKUP($B6,'LOD 300 - COLO1'!$B:AN,39,FALSE),"N/A") -> N/A | BS6: =IFERROR(VLOOKUP($B6,'LOD 300 - COLO1'!$B:AQ,42,FALSE),"N/A") -> N/A | BT6: =IFERROR(VLOOKUP($B6,'LOD 300 - COLO1'!$B:AT,45,FALSE),"N/A") -> N/A | BU6: =IFERROR(VLOOKUP($B6,'LOD 300 - COLO1'!$B:AW,48,FALSE),"N/A") -> N/A | BV6: =IFERROR(VLOOKUP($B6,'LOD 300 - COLO1'!$B:AZ,51,FALSE),"N/A") -> N/A | BW6: =IFERROR(VLOOKUP($B6,'LOD 300 - COLO1'!$B:BC,54,FALSE),"N/A") -> N/A | BX6: =IFERROR(VLOOKUP($B6,'LOD 300 - COLO1'!$B:BF,57,FALSE),"N/A") -> N/A | BY6: =IFERROR(VLOOKUP($B6,'LOD 300 - COLO1'!$B:BI,60,FALSE),"N/A") -> N/A | BZ6: =IFERROR(VLOOKUP($B6,'LOD 300 - COLO1'!$B:BL,63,FALSE),"N/A") -> N/A | CA6: =IFERROR(VLOOKUP($B6,'LOD 300 - COLO1'!$B:BO,66,FALSE),"N/A") -> N/A | CB6: =IFERROR(VLOOKUP($B6,'LOD 300 - COLO1'!$B:BR,69,FALSE),"N/A") -> N/A | CC6: =IFERROR(VLOOKUP($B6,'LOD 300 - COLO1'!$B:BU,72,FALSE),"N/A") -> N/A | CD6: =IFERROR(VLOOKUP($B6,'LOD 300 - COLO1'!$B:BX,75,FALSE),"N/A") -> N/A | CE6: =IFERROR(VLOOKUP($B6,'LOD 300 - COLO1'!$B:CA,78,FALSE),"N/A") -> N/A | CF6: =IFERROR(VLOOKUP($B6,'LOD 300 - COLO1'!$B:CD,81,FALSE),"N/A") -> N/A | CG6: =IFERROR(VLOOKUP($B6,'LOD 300 - COLO1'!$B:CG,84,FALSE),"N/A") -> N/A | CH6: =IFERROR(VLOOKUP($B6,'LOD 300 - COLO1'!$B:CJ,87,FALSE),"N/A") -> N/A | CI6: =IFERROR(VLOOKUP($B6,'LOD 300 - COLO1'!$B:CM,90,FALSE),"N/A") -> N/A | CJ6: =IFERROR(VLOOKUP($B6,'LOD 300 - COLO1'!$B:CP,93,FALSE),"N/A") -> N/A | CK6: =IFERROR(VLOOKUP($B6,'LOD 300 - COLO1'!$B:CS,96,FALSE),"N/A") -> N/A | CL6: =IFERROR(VLOOKUP($B6,'LOD 300 - COLO1'!$B:CV,99,FALSE),"N/A") -> N/A | CM6: =IFERROR(VLOOKUP($B6,'LOD 300 - COLO1'!$B:CY,102,FALSE),"N/A") -> N/A | CN6: =IFERROR(VLOOKUP($B6,'LOD 300 - COLO1'!$B:DB,105,FALSE),"N/A") -> N/A | CO6: =IFERROR(VLOOKUP($B6,'LOD 300 - COLO1'!$B:EE,108,FALSE),"N/A") -> N/A | CP6: =IFERROR(VLOOKUP($B6,'LOD 300 - COLO1'!$B:EH,111,FALSE),"N/A") -> N/A | CQ6: =IFERROR(VLOOKUP($B6,'LOD 300 - COLO1'!$B:EK,114,FALSE),"N/A") -> N/A | CR6: =IFERROR(VLOOKUP($B6,'LOD 300 - COLO1'!$B:EN,117,FALSE),"N/A") -> N/A | CS6: =IFERROR(VLOOKUP($B6,'LOD 300 - COLO1'!$B:EQ,120,FALSE),"N/A") -> N/A | CT6: =IFERROR(VLOOKUP($B6,'LOD 300 - COLO1'!$B:ET,123,FALSE),"N/A") -> N/A | CU6: =IFERROR(VLOOKUP($B6,'LOD 300 - COLO1'!$B:EW,126,FALSE),"N/A") -> N/A | CV6: =IFERROR(VLOOKUP($B6,'LOD 300 - COLO1'!$B:EZ,129,FALSE),"N/A") -> N/A | CW6: =IFERROR(VLOOKUP($B6,'LOD 300 - COLO1'!$B:FC,132,FALSE),"N/A") -> N/A | CX6: =IFERROR(__xludf.DUMMYFUNCTION("IFERROR( MAX(FILTER(BK6:CW6, ISNUMBER(BK6:CW6))), CW6 )"),"N/A") -> N/A | CY6: =IFERROR(VLOOKUP($B6,'LOD 300 - COLO2'!$B:S,18,FALSE),"N/A") -> N/A | CZ6: =IFERROR(VLOOKUP($B6,'LOD 300 - COLO2'!$B:V,21,FALSE),"N/A") -> N/A | DA6: =IFERROR(VLOOKUP($B6,'LOD 300 - COLO2'!$B:Y,24,FALSE),"N/A") -> N/A | DB6: =IFERROR(VLOOKUP($B6,'LOD 300 - COLO2'!$B:AB,27,FALSE),"N/A") -> N/A | DC6: =IFERROR(VLOOKUP($B6,'LOD 300 - COLO2'!$B:AE,30,FALSE),"N/A") -> N/A | DD6: =IFERROR(VLOOKUP($B6,'LOD 300 - COLO2'!$B:AH,33,FALSE),"N/A") -> N/A | DE6: =IFERROR(VLOOKUP($B6,'LOD 300 - COLO2'!$B:AK,36,FALSE),"N/A") -> N/A | DF6: =IFERROR(VLOOKUP($B6,'LOD 300 - COLO2'!$B:AN,39,FALSE),"N/A") -> N/A | DG6: =IFERROR(VLOOKUP($B6,'LOD 300 - COLO2'!$B:AQ,42,FALSE),"N/A") -> N/A | DH6: =IFERROR(VLOOKUP($B6,'LOD 300 - COLO2'!$B:AT,45,FALSE),"N/A") -> N/A | DI6: =IFERROR(VLOOKUP($B6,'LOD 300 - COLO2'!$B:AW,48,FALSE),"N/A") -> N/A | DJ6: =IFERROR(VLOOKUP($B6,'LOD 300 - COLO2'!$B:AZ,51,FALSE),"N/A") -> N/A | DK6: =IFERROR(VLOOKUP($B6,'LOD 300 - COLO2'!$B:BC,54,FALSE),"N/A") -> N/A | DL6: =IFERROR(VLOOKUP($B6,'LOD 300 - COLO2'!$B:BF,57,FALSE),"N/A") -> N/A | DM6: =IFERROR(VLOOKUP($B6,'LOD 300 - COLO2'!$B:BI,60,FALSE),"N/A") -> N/A | DN6: =IFERROR(VLOOKUP($B6,'LOD 300 - COLO2'!$B:BL,63,FALSE),"N/A") -> N/A | DO6: =IFERROR(VLOOKUP($B6,'LOD 300 - COLO2'!$B:BO,66,FALSE),"N/A") -> N/A | DP6: =IFERROR(VLOOKUP($B6,'LOD 300 - COLO2'!$B:BR,69,FALSE),"N/A") -> N/A | DQ6: =IFERROR(VLOOKUP($B6,'LOD 300 - COLO2'!$B:BU,72,FALSE),"N/A") -> N/A | DR6: =IFERROR(VLOOKUP($B6,'LOD 300 - COLO2'!$B:BX,75,FALSE),"N/A") -> N/A | DS6: =IFERROR(VLOOKUP($B6,'LOD 300 - COLO2'!$B:CA,78,FALSE),"N/A") -> N/A | DT6: =IFERROR(VLOOKUP($B6,'LOD 300 - COLO2'!$B:CD,81,FALSE),"N/A") -> N/A | DU6: =IFERROR(VLOOKUP($B6,'LOD 300 - COLO2'!$B:CG,84,FALSE),"N/A") -> N/A | DV6: =IFERROR(VLOOKUP($B6,'LOD 300 - COLO2'!$B:CJ,87,FALSE),"N/A") -> N/A | DW6: =IFERROR(VLOOKUP($B6,'LOD 300 - COLO2'!$B:CM,90,FALSE),"N/A") -> N/A | DX6: =IFERROR(VLOOKUP($B6,'LOD 300 - COLO2'!$B:CP,93,FALSE),"N/A") -> N/A | DY6: =IFERROR(VLOOKUP($B6,'LOD 300 - COLO2'!$B:CS,96,FALSE),"N/A") -> N/A | DZ6: =IFERROR(VLOOKUP($B6,'LOD 300 - COLO2'!$B:CV,99,FALSE),"N/A") -> N/A | EA6: =IFERROR(VLOOKUP($B6,'LOD 300 - COLO2'!$B:DB,105,FALSE),"N/A") -> N/A | EB6: =IFERROR(VLOOKUP($B6,'LOD 300 - COLO2'!$B:DB,105,FALSE),"N/A") -> N/A | EC6: =IFERROR(VLOOKUP($B6,'LOD 300 - COLO2'!$B:DE,108,FALSE),"N/A") -> N/A | ED6: =IFERROR(VLOOKUP($B6,'LOD 300 - COLO2'!$B:DH,111,FALSE),"N/A") -> N/A | EE6: =IFERROR(VLOOKUP($B6,'LOD 300 - COLO2'!$B:DK,114,FALSE),"N/A") -> N/A | EF6: =IFERROR(VLOOKUP($B6,'LOD 300 - COLO2'!$B:DN,117,FALSE),"N/A") -> N/A | EG6: =IFERROR(VLOOKUP($B6,'LOD 300 - COLO2'!$B:DQ,120,FALSE),"N/A") -> N/A | EH6: =IFERROR(__xludf.DUMMYFUNCTION("IFERROR( MAX(FILTER(CZ6:EG6, ISNUMBER(CZ6:EG6))), EG6 )"),"N/A") -> N/A | EI6: =IFERROR(VLOOKUP($B6,'LOD 300 - COLO3'!$B:R,17,FALSE),"N/A") -> N/A | EJ6: =IFERROR(VLOOKUP($B6,'LOD 300 - COLO3'!$B:U,20,FALSE),"N/A") -> N/A | EK6: =IFERROR(VLOOKUP($B6,'LOD 300 - COLO3'!$B:X,23,FALSE),"N/A") -> N/A | EL6: =IFERROR(VLOOKUP($B6,'LOD 300 - COLO3'!$B:AA,26,FALSE),"N/A") -> N/A | EM6: =IFERROR(VLOOKUP($B6,'LOD 300 - COLO3'!$B:AD,29,FALSE),"N/A") -> N/A | EN6: =IFERROR(VLOOKUP($B6,'LOD 300 - COLO3'!$B:AG,32,FALSE),"N/A") -> N/A | EO6: =IFERROR(VLOOKUP($B6,'LOD 300 - COLO3'!$B:AJ,35,FALSE),"N/A") -> N/A | EP6: =IFERROR(VLOOKUP($B6,'LOD 300 - COLO3'!$B:AM,38,FALSE),"N/A") -> N/A | EQ6: =IFERROR(VLOOKUP($B6,'LOD 300 - COLO3'!$B:AP,41,FALSE),"N/A") -> N/A | ER6: =IFERROR(VLOOKUP($B6,'LOD 300 - COLO3'!$B:AS,44,FALSE),"N/A") -> N/A | ES6: =IFERROR(VLOOKUP($B6,'LOD 300 - COLO3'!$B:AV,47,FALSE),"N/A") -> N/A | ET6: =IFERROR(VLOOKUP($B6,'LOD 300 - COLO3'!$B:AY,50,FALSE),"N/A") -> N/A | EU6: =IFERROR(VLOOKUP($B6,'LOD 300 - COLO3'!$B:BB,53,FALSE),"N/A") -> N/A | EV6: =IFERROR(VLOOKUP($B6,'LOD 300 - COLO3'!$B:BE,56,FALSE),"N/A") -> N/A | EW6: =IFERROR(VLOOKUP($B6,'LOD 300 - COLO3'!$B:BL,59,FALSE),"N/A") -> N/A | EX6: =IFERROR(VLOOKUP($B6,'LOD 300 - COLO3'!$B:BO,62,FALSE),"N/A") -> N/A | EY6: =IFERROR(__xludf.DUMMYFUNCTION("IFERROR( MAX(FILTER(EI6:EX6, ISNUMBER(EI6:EX6))), EX6 )"),"N/A") -> N/A | EZ6: =IFERROR(VLOOKUP($B6,'LOD 300 - COLO4'!$B:BT,17,FALSE),"N/A") -> N/A | FA6: =IFERROR(__xludf.DUMMYFUNCTION("IFERROR( MAX(FILTER(EZ6, ISNUMBER(EZ6))), EZ6 )"),"N/A") -> N/A | FB6: =IFERROR(VLOOKUP($B6,'LOD 300 - SITE'!$B:S,18,FALSE),"N/A") -> 0.78 | FC6: =IFERROR(VLOOKUP($B6,'LOD 300 - SITE'!$B:V,21,FALSE),"N/A") -> 0.84 | FD6: =IFERROR(VLOOKUP($B6,'LOD 300 - SITE'!$B:Y,24,FALSE),"N/A") -> 0.94 | FE6: =IFERROR(VLOOKUP($B6,'LOD 300 - SITE'!$B:AB,27,FALSE),"N/A") -> OUTDATED MODEL | FF6: =IFERROR(VLOOKUP($B6,'LOD 300 - SITE'!$B:AE,30,FALSE),"N/A") -> OUTDATED MODEL | FG6: =IFERROR(VLOOKUP($B6,'LOD 300 - SITE'!$B:AH,33,FALSE),"N/A") -> 0.98 | FH6: =IFERROR(VLOOKUP($B6,'LOD 300 - SITE'!$B:AK,36,FALSE),"N/A") -> 1 | FI6: =IFERROR(VLOOKUP($B6,'LOD 300 - SITE'!$B:AN,39,FALSE),"N/A") -> 1 | FJ6: =IFERROR(VLOOKUP($B6,'LOD 300 - SITE'!$B:AQ,42,FALSE),"N/A") -> 1 | FK6: =IFERROR(VLOOKUP($B6,'LOD 300 - SITE'!$B:AT,45,FALSE),"N/A") -> 1 | FL6: =IFERROR(VLOOKUP($B6,'LOD 300 - SITE'!$B:AW,48,FALSE),"N/A") -> 1 | FM6: =IFERROR(VLOOKUP($B6,'LOD 300 - SITE'!$B:AZ,51,FALSE),"N/A") -> 1 | FN6: =IFERROR(VLOOKUP($B6,'LOD 300 - SITE'!$B:BC,54,FALSE),"N/A") -> 1 | FO6: =IFERROR(VLOOKUP($B6,'LOD 300 - SITE'!$B:BF,57,FALSE),"N/A") -> 1 | FP6: =IFERROR(VLOOKUP($B6,'LOD 300 - SITE'!$B:BI,60,FALSE),"N/A") -> 1 | FQ6: =IFERROR(VLOOKUP($B6,'LOD 300 - SITE'!$B:BL,63,FALSE),"N/A") -> 1 | FR6: =IFERROR(VLOOKUP($B6,'LOD 300 - SITE'!$B:BO,66,FALSE),"N/A") -> 1 | FS6: =IFERROR(VLOOKUP($B6,'LOD 300 - SITE'!$B:BR,69,FALSE),"N/A") -> 1 | FT6: =IFERROR(VLOOKUP($B6,'LOD 300 - SITE'!$B:BU,72,FALSE),"N/A") -> 1 | FU6: =IFERROR(VLOOKUP($B6,'LOD 300 - SITE'!$B:BX,75,FALSE),"N/A") -> 1 | FV6: =IFERROR(VLOOKUP($B6,'LOD 300 - SITE'!$B:CA,78,FALSE),"N/A") -> 1 | FW6: =IFERROR(VLOOKUP($B6,'LOD 300 - SITE'!$B:CD,81,FALSE),"N/A") -> 1 | FX6: =IFERROR(VLOOKUP($B6,'LOD 300 - SITE'!$B:CG,84,FALSE),"N/A") -> 1 | FY6: =IFERROR(VLOOKUP($B6,'LOD 300 - SITE'!$B:CJ,87,FALSE),"N/A") -> 1 | FZ6: =IFERROR(VLOOKUP($B6,'LOD 300 - SITE'!$B:CM,90,FALSE),"N/A") -> 1 | GA6: =IFERROR(VLOOKUP($B6,'LOD 300 - SITE'!$B:CP,93,FALSE),"N/A") -> 1 | GB6: =IFERROR(VLOOKUP($B6,'LOD 300 - SITE'!$B:CS,96,FALSE),"N/A") -> 1 | GC6: =IFERROR(VLOOKUP($B6,'LOD 300 - SITE'!$B:CV,99,FALSE),"N/A") -> 1 | GD6: =IFERROR(VLOOKUP($B6,'LOD 300 - SITE'!$B:CY,102,FALSE),"N/A") -> 1 | GE6: =IFERROR(VLOOKUP($B6,'LOD 300 - SITE'!$B:DB,105,FALSE),"N/A") -> 1 | GF6: =IFERROR(VLOOKUP($B6,'LOD 300 - SITE'!$B:DE,108,FALSE),"N/A") -> 1 | GG6: =IFERROR(VLOOKUP($B6,'LOD 300 - SITE'!$B:DH,111,FALSE),"N/A") -> 1 | GH6: =IFERROR(VLOOKUP($B6,'LOD 300 - SITE'!$B:DK,114,FALSE),"N/A") -> 1 | GI6: =IFERROR(VLOOKUP($B6,'LOD 300 - SITE'!$B:DN,117,FALSE),"N/A") -> 1 | GJ6: =IFERROR(VLOOKUP($B6,'LOD 300 - SITE'!$B:DQ,120,FALSE),"N/A") -> 1 | GK6: =IFERROR(VLOOKUP($B6,'LOD 300 - SITE'!$B:DT,123,FALSE),"N/A") -> 1 | GL6: =IFERROR(VLOOKUP($B6,'LOD 300 - SITE'!$B:DW,126,FALSE),"N/A") -> 1 | GM6: =IFERROR(__xludf.DUMMYFUNCTION("IFERROR( MAX(FILTER(FB6:GL6, ISNUMBER(FB6:GL6))), GL6 )"),1.0) -> 1
A7: 9 | B7: CPQ11-ARCH-METL-SITE-R24.rvt | C7: CPQ11-ARCH-METL-SITE-R22.rvt | D7: SITE | E7: SERCOP | G7: ARE ARQUITETURA | I7: =IFERROR(VLOOKUP(C4:C146,'R22 RELATÓRIO ACC'!B:F,5,FALSE),"NOT PUBLISHED") -> V12 | J7: =IFERROR(VLOOKUP(C4:C146,'R22 RELATÓRIO ACC'!B:P,15,FALSE),"NOT PUBLISHED") -> 05/05/2026 | K7: =IFERROR(VLOOKUP(B7:B196,'RELATÓRIO ACC'!B:F,5,FALSE),"NOT PUBLISHED") -> V5 | L7: =IFERROR(VLOOKUP(B7:B196,'RELATÓRIO ACC'!B:P,15,FALSE),"NOT PUBLISHED") -> 22/06/2026 | M7: =IF(OR($D7="UTLS",$D7="GUAR",$D7="STIR",$D7="PUMP",$D7="SITE"), VLOOKUP($B7,'LOD 300 - SITE'!B:M,12,FALSE), VLOOKUP($B7,'LOD 300 - ADMN'!B:M,12,FALSE) ) -> V4 | N7: =IF(OR($D7="UTLS",$D7="GUAR",$D7="STIR",$D7="PUMP",$D7="SITE"), VLOOKUP($B7,'LOD 300 - SITE'!B:N,13,FALSE), VLOOKUP($B7,'LOD 300 - ADMN'!B:N,13,FALSE) ) -> 45978 | O7: =IF(OR($D7="UTLS",$D7="GUAR",$D7="STIR",$D7="PUMP",$D7="SITE"), VLOOKUP($B7,'LOD 300 - SITE'!B:O,14,FALSE), VLOOKUP($B7,'LOD 300 - ADMN'!B:O,14,FALSE) ) -> R22 | P7: =IF(OR($D7="C345",$D7="C12A",$D7="DATA"), VLOOKUP($B7,'LOD 300 - COLO3'!B:M,12,FALSE),"N/A") -> N/A | Q7: =IF(OR($D7="C345",$D7="C12A",$D7="DATA"), VLOOKUP($B7,'LOD 300 - COLO3'!B:N,13,FALSE),"N/A") -> N/A | R7: =IF(OR($D7="C345",$D7="C12A",$D7="DATA"), VLOOKUP($B7,'LOD 300 - COLO3'!B:O,14,FALSE),"N/A") -> N/A | S7: =IF(OR($D7="C345",$D7="C12A",$D7="DATA"), VLOOKUP($B7,'LOD 300 - COLO4'!B:M,12,FALSE),"N/A") -> N/A | T7: =IF(OR($D7="C345",$D7="C12A",$D7="DATA"), VLOOKUP($B7,'LOD 300 - COLO4'!B:T,13,FALSE),"N/A") -> N/A | U7: =IF(OR($D7="C345",$D7="C12A",$D7="DATA"), VLOOKUP($B7,'LOD 300 - COLO4'!B:U,17,FALSE),"N/A") -> N/A | W7: =IFERROR(VLOOKUP($B7,'LOD 300 - ADMN'!$B:S,18,FALSE),"N/A") -> N/A | X7: =IFERROR(VLOOKUP($B7,'LOD 300 - ADMN'!$B:V,21,FALSE),"N/A") -> N/A | Y7: =IFERROR(VLOOKUP($B7,'LOD 300 - ADMN'!$B:Y,24,FALSE),"N/A") -> N/A | Z7: =IFERROR(VLOOKUP($B7,'LOD 300 - ADMN'!$B:AB,27,FALSE),"N/A") -> N/A | AA7: =IFERROR(VLOOKUP($B7,'LOD 300 - ADMN'!$B:AE,30,FALSE),"N/A") -> N/A | AB7: =IFERROR(VLOOKUP($B7,'LOD 300 - ADMN'!$B:AH,33,FALSE),"N/A") -> N/A | AC7: =IFERROR(VLOOKUP($B7,'LOD 300 - ADMN'!$B:AK,36,FALSE),"N/A") -> N/A | AD7: =IFERROR(VLOOKUP($B7,'LOD 300 - ADMN'!$B:AN,39,FALSE),"N/A") -> N/A | AE7: =IFERROR(VLOOKUP($B7,'LOD 300 - ADMN'!$B:AQ,42,FALSE),"N/A") -> N/A | AF7: =IFERROR(VLOOKUP($B7,'LOD 300 - ADMN'!$B:AT,45,FALSE),"N/A") -> N/A | AG7: =IFERROR(VLOOKUP($B7,'LOD 300 - ADMN'!$B:AW,48,FALSE),"N/A") -> N/A | AH7: =IFERROR(VLOOKUP($B7,'LOD 300 - ADMN'!$B:AZ,51,FALSE),"N/A") -> N/A | AI7: =IFERROR(VLOOKUP($B7,'LOD 300 - ADMN'!$B:BC,54,FALSE),"N/A") -> N/A | AJ7: =IFERROR(VLOOKUP($B7,'LOD 300 - ADMN'!$B:BF,57,FALSE),"N/A") -> N/A | AK7: =IFERROR(VLOOKUP($B7,'LOD 300 - ADMN'!$B:EP,60,FALSE),"N/A") -> N/A | AL7: =IFERROR(VLOOKUP($B7,'LOD 300 - ADMN'!$B:EQ,63,FALSE),"N/A") -> N/A | AM7: =IFERROR(VLOOKUP($B7,'LOD 300 - ADMN'!$B:BO,66,FALSE),"N/A") -> N/A | AN7: =IFERROR(VLOOKUP($B7,'LOD 300 - ADMN'!$B:BR,69,FALSE),"N/A") -> N/A | AO7: =IFERROR(VLOOKUP($B7,'LOD 300 - ADMN'!$B:BU,72,FALSE),"N/A") -> N/A | AP7: =IFERROR(VLOOKUP($B7,'LOD 300 - ADMN'!$B:BX,75,FALSE),"N/A") -> N/A | AQ7: =IFERROR(VLOOKUP($B7,'LOD 300 - ADMN'!$B:CA,78,FALSE),"N/A") -> N/A | AR7: =IFERROR(VLOOKUP($B7,'LOD 300 - ADMN'!$B:CD,81,FALSE),"N/A") -> N/A | AS7: =IFERROR(VLOOKUP($B7,'LOD 300 - ADMN'!$B:CG,84,FALSE),"N/A") -> N/A | AT7: =IFERROR(VLOOKUP($B7,'LOD 300 - ADMN'!$B:CJ,87,FALSE),"N/A") -> N/A | AU7: =IFERROR(VLOOKUP($B7,'LOD 300 - ADMN'!$B:CM,90,FALSE),"N/A") -> N/A | AV7: =IFERROR(VLOOKUP($B7,'LOD 300 - ADMN'!$B:CP,93,FALSE),"N/A") -> N/A | AW7: =IFERROR(VLOOKUP($B7,'LOD 300 - ADMN'!$B:CS,96,FALSE),"N/A") -> N/A | AX7: =IFERROR(VLOOKUP($B7,'LOD 300 - ADMN'!$B:CV,99,FALSE),"N/A") -> N/A | AY7: =IFERROR(VLOOKUP($B7,'LOD 300 - ADMN'!$B:CY,102,FALSE),"N/A") -> N/A | AZ7: =IFERROR(VLOOKUP($B7,'LOD 300 - ADMN'!$B:DB,105,FALSE),"N/A") -> N/A | BA7: =IFERROR(VLOOKUP($B7,'LOD 300 - ADMN'!$B:DE,108,FALSE),"N/A") -> N/A | BB7: =IFERROR(VLOOKUP($B7,'LOD 300 - ADMN'!$B:DH,111,FALSE),"N/A") -> N/A | BC7: =IFERROR(VLOOKUP($B7,'LOD 300 - ADMN'!$B:DK,114,FALSE),"N/A") -> N/A | BD7: =IFERROR(VLOOKUP($B7,'LOD 300 - ADMN'!$B:DN,117,FALSE),"N/A") -> N/A | BE7: =IFERROR(VLOOKUP($B7,'LOD 300 - ADMN'!$B:DQ,120,FALSE),"N/A") -> N/A | BF7: =IFERROR(VLOOKUP($B7,'LOD 300 - ADMN'!$B:DT,123,FALSE),"N/A") -> N/A | BG7: =IFERROR(VLOOKUP($B7,'LOD 300 - ADMN'!$B:DW,126,FALSE),"N/A") -> N/A | BH7: =IFERROR(VLOOKUP($B7,'LOD 300 - ADMN'!$B:DZ,129,FALSE),"N/A") -> N/A | BI7: =IFERROR(VLOOKUP($B7,'LOD 300 - ADMN'!$B:EC,132,FALSE),"N/A") -> N/A | BJ7: =IFERROR(__xludf.DUMMYFUNCTION("IFERROR( MAX(FILTER(X7:BI7, ISNUMBER(X7:BI7))), BI7 )"),"N/A") -> N/A | BK7: =IFERROR(VLOOKUP($B7,'LOD 300 - COLO1'!$B:S,18,FALSE),"N/A") -> N/A | BL7: =IFERROR(VLOOKUP($B7,'LOD 300 - COLO1'!$B:V,21,FALSE),"N/A") -> N/A | BM7: =IFERROR(VLOOKUP($B7,'LOD 300 - COLO1'!$B:Y,24,FALSE),"N/A") -> N/A | BN7: =IFERROR(VLOOKUP($B7,'LOD 300 - COLO1'!$B:AB,27,FALSE),"N/A") -> N/A | BO7: =IFERROR(VLOOKUP($B7,'LOD 300 - COLO1'!$B:AE,30,FALSE),"N/A") -> N/A | BP7: =IFERROR(VLOOKUP($B7,'LOD 300 - COLO1'!$B:AH,33,FALSE),"N/A") -> N/A | BQ7: =IFERROR(VLOOKUP($B7,'LOD 300 - COLO1'!$B:AK,36,FALSE),"N/A") -> N/A | BR7: =IFERROR(VLOOKUP($B7,'LOD 300 - COLO1'!$B:AN,39,FALSE),"N/A") -> N/A | BS7: =IFERROR(VLOOKUP($B7,'LOD 300 - COLO1'!$B:AQ,42,FALSE),"N/A") -> N/A | BT7: =IFERROR(VLOOKUP($B7,'LOD 300 - COLO1'!$B:AT,45,FALSE),"N/A") -> N/A | BU7: =IFERROR(VLOOKUP($B7,'LOD 300 - COLO1'!$B:AW,48,FALSE),"N/A") -> N/A | BV7: =IFERROR(VLOOKUP($B7,'LOD 300 - COLO1'!$B:AZ,51,FALSE),"N/A") -> N/A | BW7: =IFERROR(VLOOKUP($B7,'LOD 300 - COLO1'!$B:BC,54,FALSE),"N/A") -> N/A | BX7: =IFERROR(VLOOKUP($B7,'LOD 300 - COLO1'!$B:BF,57,FALSE),"N/A") -> N/A | BY7: =IFERROR(VLOOKUP($B7,'LOD 300 - COLO1'!$B:BI,60,FALSE),"N/A") -> N/A | BZ7: =IFERROR(VLOOKUP($B7,'LOD 300 - COLO1'!$B:BL,63,FALSE),"N/A") -> N/A | CA7: =IFERROR(VLOOKUP($B7,'LOD 300 - COLO1'!$B:BO,66,FALSE),"N/A") -> N/A | CB7: =IFERROR(VLOOKUP($B7,'LOD 300 - COLO1'!$B:BR,69,FALSE),"N/A") -> N/A | CC7: =IFERROR(VLOOKUP($B7,'LOD 300 - COLO1'!$B:BU,72,FALSE),"N/A") -> N/A | CD7: =IFERROR(VLOOKUP($B7,'LOD 300 - COLO1'!$B:BX,75,FALSE),"N/A") -> N/A | CE7: =IFERROR(VLOOKUP($B7,'LOD 300 - COLO1'!$B:CA,78,FALSE),"N/A") -> N/A | CF7: =IFERROR(VLOOKUP($B7,'LOD 300 - COLO1'!$B:CD,81,FALSE),"N/A") -> N/A | CG7: =IFERROR(VLOOKUP($B7,'LOD 300 - COLO1'!$B:CG,84,FALSE),"N/A") -> N/A | CH7: =IFERROR(VLOOKUP($B7,'LOD 300 - COLO1'!$B:CJ,87,FALSE),"N/A") -> N/A | CI7: =IFERROR(VLOOKUP($B7,'LOD 300 - COLO1'!$B:CM,90,FALSE),"N/A") -> N/A | CJ7: =IFERROR(VLOOKUP($B7,'LOD 300 - COLO1'!$B:CP,93,FALSE),"N/A") -> N/A | CK7: =IFERROR(VLOOKUP($B7,'LOD 300 - COLO1'!$B:CS,96,FALSE),"N/A") -> N/A | CL7: =IFERROR(VLOOKUP($B7,'LOD 300 - COLO1'!$B:CV,99,FALSE),"N/A") -> N/A | CM7: =IFERROR(VLOOKUP($B7,'LOD 300 - COLO1'!$B:CY,102,FALSE),"N/A") -> N/A | CN7: =IFERROR(VLOOKUP($B7,'LOD 300 - COLO1'!$B:DB,105,FALSE),"N/A") -> N/A | CO7: =IFERROR(VLOOKUP($B7,'LOD 300 - COLO1'!$B:EE,108,FALSE),"N/A") -> N/A | CP7: =IFERROR(VLOOKUP($B7,'LOD 300 - COLO1'!$B:EH,111,FALSE),"N/A") -> N/A | CQ7: =IFERROR(VLOOKUP($B7,'LOD 300 - COLO1'!$B:EK,114,FALSE),"N/A") -> N/A | CR7: =IFERROR(VLOOKUP($B7,'LOD 300 - COLO1'!$B:EN,117,FALSE),"N/A") -> N/A | CS7: =IFERROR(VLOOKUP($B7,'LOD 300 - COLO1'!$B:EQ,120,FALSE),"N/A") -> N/A | CT7: =IFERROR(VLOOKUP($B7,'LOD 300 - COLO1'!$B:ET,123,FALSE),"N/A") -> N/A | CU7: =IFERROR(VLOOKUP($B7,'LOD 300 - COLO1'!$B:EW,126,FALSE),"N/A") -> N/A | CV7: =IFERROR(VLOOKUP($B7,'LOD 300 - COLO1'!$B:EZ,129,FALSE),"N/A") -> N/A | CW7: =IFERROR(VLOOKUP($B7,'LOD 300 - COLO1'!$B:FC,132,FALSE),"N/A") -> N/A | CX7: =IFERROR(__xludf.DUMMYFUNCTION("IFERROR( MAX(FILTER(BK7:CW7, ISNUMBER(BK7:CW7))), CW7 )"),"N/A") -> N/A | CY7: =IFERROR(VLOOKUP($B7,'LOD 300 - COLO2'!$B:S,18,FALSE),"N/A") -> N/A | CZ7: =IFERROR(VLOOKUP($B7,'LOD 300 - COLO2'!$B:V,21,FALSE),"N/A") -> N/A | DA7: =IFERROR(VLOOKUP($B7,'LOD 300 - COLO2'!$B:Y,24,FALSE),"N/A") -> N/A | DB7: =IFERROR(VLOOKUP($B7,'LOD 300 - COLO2'!$B:AB,27,FALSE),"N/A") -> N/A | DC7: =IFERROR(VLOOKUP($B7,'LOD 300 - COLO2'!$B:AE,30,FALSE),"N/A") -> N/A | DD7: =IFERROR(VLOOKUP($B7,'LOD 300 - COLO2'!$B:AH,33,FALSE),"N/A") -> N/A | DE7: =IFERROR(VLOOKUP($B7,'LOD 300 - COLO2'!$B:AK,36,FALSE),"N/A") -> N/A | DF7: =IFERROR(VLOOKUP($B7,'LOD 300 - COLO2'!$B:AN,39,FALSE),"N/A") -> N/A | DG7: =IFERROR(VLOOKUP($B7,'LOD 300 - COLO2'!$B:AQ,42,FALSE),"N/A") -> N/A | DH7: =IFERROR(VLOOKUP($B7,'LOD 300 - COLO2'!$B:AT,45,FALSE),"N/A") -> N/A | DI7: =IFERROR(VLOOKUP($B7,'LOD 300 - COLO2'!$B:AW,48,FALSE),"N/A") -> N/A | DJ7: =IFERROR(VLOOKUP($B7,'LOD 300 - COLO2'!$B:AZ,51,FALSE),"N/A") -> N/A | DK7: =IFERROR(VLOOKUP($B7,'LOD 300 - COLO2'!$B:BC,54,FALSE),"N/A") -> N/A | DL7: =IFERROR(VLOOKUP($B7,'LOD 300 - COLO2'!$B:BF,57,FALSE),"N/A") -> N/A | DM7: =IFERROR(VLOOKUP($B7,'LOD 300 - COLO2'!$B:BI,60,FALSE),"N/A") -> N/A | DN7: =IFERROR(VLOOKUP($B7,'LOD 300 - COLO2'!$B:BL,63,FALSE),"N/A") -> N/A | DO7: =IFERROR(VLOOKUP($B7,'LOD 300 - COLO2'!$B:BO,66,FALSE),"N/A") -> N/A | DP7: =IFERROR(VLOOKUP($B7,'LOD 300 - COLO2'!$B:BR,69,FALSE),"N/A") -> N/A | DQ7: =IFERROR(VLOOKUP($B7,'LOD 300 - COLO2'!$B:BU,72,FALSE),"N/A") -> N/A | DR7: =IFERROR(VLOOKUP($B7,'LOD 300 - COLO2'!$B:BX,75,FALSE),"N/A") -> N/A | DS7: =IFERROR(VLOOKUP($B7,'LOD 300 - COLO2'!$B:CA,78,FALSE),"N/A") -> N/A | DT7: =IFERROR(VLOOKUP($B7,'LOD 300 - COLO2'!$B:CD,81,FALSE),"N/A") -> N/A | DU7: =IFERROR(VLOOKUP($B7,'LOD 300 - COLO2'!$B:CG,84,FALSE),"N/A") -> N/A | DV7: =IFERROR(VLOOKUP($B7,'LOD 300 - COLO2'!$B:CJ,87,FALSE),"N/A") -> N/A | DW7: =IFERROR(VLOOKUP($B7,'LOD 300 - COLO2'!$B:CM,90,FALSE),"N/A") -> N/A | DX7: =IFERROR(VLOOKUP($B7,'LOD 300 - COLO2'!$B:CP,93,FALSE),"N/A") -> N/A | DY7: =IFERROR(VLOOKUP($B7,'LOD 300 - COLO2'!$B:CS,96,FALSE),"N/A") -> N/A | DZ7: =IFERROR(VLOOKUP($B7,'LOD 300 - COLO2'!$B:CV,99,FALSE),"N/A") -> N/A | EA7: =IFERROR(VLOOKUP($B7,'LOD 300 - COLO2'!$B:DB,105,FALSE),"N/A") -> N/A | EB7: =IFERROR(VLOOKUP($B7,'LOD 300 - COLO2'!$B:DB,105,FALSE),"N/A") -> N/A | EC7: =IFERROR(VLOOKUP($B7,'LOD 300 - COLO2'!$B:DE,108,FALSE),"N/A") -> N/A | ED7: =IFERROR(VLOOKUP($B7,'LOD 300 - COLO2'!$B:DH,111,FALSE),"N/A") -> N/A | EE7: =IFERROR(VLOOKUP($B7,'LOD 300 - COLO2'!$B:DK,114,FALSE),"N/A") -> N/A | EF7: =IFERROR(VLOOKUP($B7,'LOD 300 - COLO2'!$B:DN,117,FALSE),"N/A") -> N/A | EG7: =IFERROR(VLOOKUP($B7,'LOD 300 - COLO2'!$B:DQ,120,FALSE),"N/A") -> N/A | EH7: =IFERROR(__xludf.DUMMYFUNCTION("IFERROR( MAX(FILTER(CZ7:EG7, ISNUMBER(CZ7:EG7))), EG7 )"),"N/A") -> N/A | EI7: =IFERROR(VLOOKUP($B7,'LOD 300 - COLO3'!$B:R,17,FALSE),"N/A") -> N/A | EJ7: =IFERROR(VLOOKUP($B7,'LOD 300 - COLO3'!$B:U,20,FALSE),"N/A") -> N/A | EK7: =IFERROR(VLOOKUP($B7,'LOD 300 - COLO3'!$B:X,23,FALSE),"N/A") -> N/A | EL7: =IFERROR(VLOOKUP($B7,'LOD 300 - COLO3'!$B:AA,26,FALSE),"N/A") -> N/A | EM7: =IFERROR(VLOOKUP($B7,'LOD 300 - COLO3'!$B:AD,29,FALSE),"N/A") -> N/A | EN7: =IFERROR(VLOOKUP($B7,'LOD 300 - COLO3'!$B:AG,32,FALSE),"N/A") -> N/A | EO7: =IFERROR(VLOOKUP($B7,'LOD 300 - COLO3'!$B:AJ,35,FALSE),"N/A") -> N/A | EP7: =IFERROR(VLOOKUP($B7,'LOD 300 - COLO3'!$B:AM,38,FALSE),"N/A") -> N/A | EQ7: =IFERROR(VLOOKUP($B7,'LOD 300 - COLO3'!$B:AP,41,FALSE),"N/A") -> N/A | ER7: =IFERROR(VLOOKUP($B7,'LOD 300 - COLO3'!$B:AS,44,FALSE),"N/A") -> N/A | ES7: =IFERROR(VLOOKUP($B7,'LOD 300 - COLO3'!$B:AV,47,FALSE),"N/A") -> N/A | ET7: =IFERROR(VLOOKUP($B7,'LOD 300 - COLO3'!$B:AY,50,FALSE),"N/A") -> N/A | EU7: =IFERROR(VLOOKUP($B7,'LOD 300 - COLO3'!$B:BB,53,FALSE),"N/A") -> N/A | EV7: =IFERROR(VLOOKUP($B7,'LOD 300 - COLO3'!$B:BE,56,FALSE),"N/A") -> N/A | EW7: =IFERROR(VLOOKUP($B7,'LOD 300 - COLO3'!$B:BL,59,FALSE),"N/A") -> N/A | EX7: =IFERROR(VLOOKUP($B7,'LOD 300 - COLO3'!$B:BO,62,FALSE),"N/A") -> N/A | EY7: =IFERROR(__xludf.DUMMYFUNCTION("IFERROR( MAX(FILTER(EI7:EX7, ISNUMBER(EI7:EX7))), EX7 )"),"N/A") -> N/A | EZ7: =IFERROR(VLOOKUP($B7,'LOD 300 - COLO4'!$B:BT,17,FALSE),"N/A") -> N/A | FA7: =IFERROR(__xludf.DUMMYFUNCTION("IFERROR( MAX(FILTER(EZ7, ISNUMBER(EZ7))), EZ7 )"),"N/A") -> N/A | FB7: =IFERROR(VLOOKUP($B7,'LOD 300 - SITE'!$B:S,18,FALSE),"N/A") -> NOT PUBLISHED | FC7: =IFERROR(VLOOKUP($B7,'LOD 300 - SITE'!$B:V,21,FALSE),"N/A") -> NOT PUBLISHED | FD7: =IFERROR(VLOOKUP($B7,'LOD 300 - SITE'!$B:Y,24,FALSE),"N/A") -> NOT PUBLISHED | FE7: =IFERROR(VLOOKUP($B7,'LOD 300 - SITE'!$B:AB,27,FALSE),"N/A") -> NOT PUBLISHED | FF7: =IFERROR(VLOOKUP($B7,'LOD 300 - SITE'!$B:AE,30,FALSE),"N/A") -> 0.51 | FG7: =IFERROR(VLOOKUP($B7,'LOD 300 - SITE'!$B:AH,33,FALSE),"N/A") -> OUTDATED MODEL | FH7: =IFERROR(VLOOKUP($B7,'LOD 300 - SITE'!$B:AK,36,FALSE),"N/A") -> IMPROPER | FI7: =IFERROR(VLOOKUP($B7,'LOD 300 - SITE'!$B:AN,39,FALSE),"N/A") -> 0.88 | FJ7: =IFERROR(VLOOKUP($B7,'LOD 300 - SITE'!$B:AQ,42,FALSE),"N/A") -> 1 | FK7: =IFERROR(VLOOKUP($B7,'LOD 300 - SITE'!$B:AT,45,FALSE),"N/A") -> 1 | FL7: =IFERROR(VLOOKUP($B7,'LOD 300 - SITE'!$B:AW,48,FALSE),"N/A") -> 1 | FM7: =IFERROR(VLOOKUP($B7,'LOD 300 - SITE'!$B:AZ,51,FALSE),"N/A") -> 1 | FN7: =IFERROR(VLOOKUP($B7,'LOD 300 - SITE'!$B:BC,54,FALSE),"N/A") -> 1 | FO7: =IFERROR(VLOOKUP($B7,'LOD 300 - SITE'!$B:BF,57,FALSE),"N/A") -> 1 | FP7: =IFERROR(VLOOKUP($B7,'LOD 300 - SITE'!$B:BI,60,FALSE),"N/A") -> 1 | FQ7: =IFERROR(VLOOKUP($B7,'LOD 300 - SITE'!$B:BL,63,FALSE),"N/A") -> 1 | FR7: =IFERROR(VLOOKUP($B7,'LOD 300 - SITE'!$B:BO,66,FALSE),"N/A") -> 1 | FS7: =IFERROR(VLOOKUP($B7,'LOD 300 - SITE'!$B:BR,69,FALSE),"N/A") -> 1 | FT7: =IFERROR(VLOOKUP($B7,'LOD 300 - SITE'!$B:BU,72,FALSE),"N/A") -> 1 | FU7: =IFERROR(VLOOKUP($B7,'LOD 300 - SITE'!$B:BX,75,FALSE),"N/A") -> 1 | FV7: =IFERROR(VLOOKUP($B7,'LOD 300 - SITE'!$B:CA,78,FALSE),"N/A") -> 1 | FW7: =IFERROR(VLOOKUP($B7,'LOD 300 - SITE'!$B:CD,81,FALSE),"N/A") -> 1 | FX7: =IFERROR(VLOOKUP($B7,'LOD 300 - SITE'!$B:CG,84,FALSE),"N/A") -> 1 | FY7: =IFERROR(VLOOKUP($B7,'LOD 300 - SITE'!$B:CJ,87,FALSE),"N/A") -> 1 | FZ7: =IFERROR(VLOOKUP($B7,'LOD 300 - SITE'!$B:CM,90,FALSE),"N/A") -> 1 | GA7: =IFERROR(VLOOKUP($B7,'LOD 300 - SITE'!$B:CP,93,FALSE),"N/A") -> 1 | GB7: =IFERROR(VLOOKUP($B7,'LOD 300 - SITE'!$B:CS,96,FALSE),"N/A") -> 1 | GC7: =IFERROR(VLOOKUP($B7,'LOD 300 - SITE'!$B:CV,99,FALSE),"N/A") -> 1 | GD7: =IFERROR(VLOOKUP($B7,'LOD 300 - SITE'!$B:CY,102,FALSE),"N/A") -> 1 | GE7: =IFERROR(VLOOKUP($B7,'LOD 300 - SITE'!$B:DB,105,FALSE),"N/A") -> 1 | GF7: =IFERROR(VLOOKUP($B7,'LOD 300 - SITE'!$B:DE,108,FALSE),"N/A") -> 1 | GG7: =IFERROR(VLOOKUP($B7,'LOD 300 - SITE'!$B:DH,111,FALSE),"N/A") -> 1 | GH7: =IFERROR(VLOOKUP($B7,'LOD 300 - SITE'!$B:DK,114,FALSE),"N/A") -> 1 | GI7: =IFERROR(VLOOKUP($B7,'LOD 300 - SITE'!$B:DN,117,FALSE),"N/A") -> 1 | GJ7: =IFERROR(VLOOKUP($B7,'LOD 300 - SITE'!$B:DQ,120,FALSE),"N/A") -> 1 | GK7: =IFERROR(VLOOKUP($B7,'LOD 300 - SITE'!$B:DT,123,FALSE),"N/A") -> 1 | GL7: =IFERROR(VLOOKUP($B7,'LOD 300 - SITE'!$B:DW,126,FALSE),"N/A") -> 1 | GM7: =IFERROR(__xludf.DUMMYFUNCTION("IFERROR( MAX(FILTER(FB7:GL7, ISNUMBER(FB7:GL7))), GL7 )"),1.0) -> 1
