Workbook
Name HT: 'LOD 400 - CONTROL'!$HF$74

Sheet LOD 400 - CONTROL
D1: SPECIFIC AUDIT CONTROL | LOD 400
B2: META DO DIA 17/07 | Y2: ADMN | BH2: COLO1 | CQ2: COLO2 | DZ2: COLO3 | EQ2: COLO4 | ES2: SITE | GA2: UTLS
B3: FILE NAME (R24) | C3: FILE NAME (R22) | D3: AREA | E3: TRADE COMPANY | F3: CODE | G3: BIM COMPANY | H3: CODE | I3: ACC VERSION (R22) | J3: ACC FILE DATE (R22) | K3: ACC VERSION (R24) | L3: ACC FILE DATE (R24) | M3: VERSION ADMN/COL1/COL2/ SITE | N3: FILE DATE ADMN/COL1/COL2/SITE | O3: RVT TYPE APROVAL (ADMN/COL1/COL2/SITE) | P3: VERSION COL3 | Q3: FILE DATE COL3 | R3: RVT TYPE APROVAL (COL3) | S3: VERSION COL4 | T3: FILE DATE COL4 | U3: RVT TYPE APROVAL (COL3) | V3: UTLS VERSION | W3: UTLS FILE DATE | X3: RVT TYPE APROVAL (UTLS) | Y3: R1 - APPROVAL (%) | Z3: R2 - APPROVAL (%) | AA3: R3 - APPROVAL (%) | AB3: R4 - APPROVAL (%) | AC3: R5 - APPROVAL (%) | AD3: R6 - APPROVAL (%) | AE3: R7 - APPROVAL (%) | AF3: R8 - APPROVAL (%) | AG3: R9 - APPROVAL (%) | AH3: R10 - APPROVAL (%) | AI3: R11 - APPROVAL (%) | AJ3: R12 - APPROVAL (%) | AK3: R13 - APPROVAL (%) | AL3: R14 - APPROVAL (%) | AM3: R15 - APPROVAL (%) | AN3: R16 - APPROVAL (%) | AO3: R17 - APPROVAL (%) | AP3: R18 - APPROVAL (%) | AQ3: R19 - APPROVAL (%) | AR3: R20 - APPROVAL (%) | AS3: R21 - APPROVAL (%) | AT3: R22 - APPROVAL (%) | AU3: R23 - APPROVAL (%) | AV3: R24 - APPROVAL (%) | AW3: R25 - APPROVAL (%) | AX3: R26 - APPROVAL (%) | AY3: R27 - APPROVAL (%) | AZ3: R28 - APPROVAL (%) | BA3: R29 - APPROVAL (%) | BB3: R30 - APPROVAL (%) | BC3: R31 - APPROVAL (%) | BD3: R32 - APPROVAL (%) | BE3: R33 - APPROVAL (%) | BF3: R34 - APPROVAL (%) | BG3: GERAL | BH3: R1 - APPROVAL (%) | BI3: R2 - APPROVAL (%) | BJ3: R3 - APPROVAL (%) | BK3: R4 - APPROVAL (%) | BL3: R5 - APPROVAL (%) | BM3: R6 - APPROVAL (%) | BN3: R7 - APPROVAL (%) | BO3: R8 - APPROVAL (%) | BP3: R9 - APPROVAL (%) | BQ3: R10 - APPROVAL (%) | BR3: R11 - APPROVAL (%) | BS3: R12 - APPROVAL (%) | BT3: R13 - APPROVAL (%) | BU3: R14 - APPROVAL (%) | BV3: R15 - APPROVAL (%) | BW3: R16 - APPROVAL (%) | BX3: R17 - APPROVAL (%) | BY3: R18 - APPROVAL (%) | BZ3: R19 - APPROVAL (%) | CA3: R20 - APPROVAL (%) | CB3: R21 - APPROVAL (%) | CC3: R22 - APPROVAL (%) | CD3: R23 - APPROVAL (%) | CE3: R24 - APPROVAL (%) | CF3: R25 - APPROVAL (%) | CG3: R26 - APPROVAL (%) | CH3: R27 - APPROVAL (%) | CI3: R28 - APPROVAL (%) | CJ3: R29 - APPROVAL (%) | CK3: R30 - APPROVAL (%) | CL3: R31 - APPROVAL (%) | CM3: R32 - APPROVAL (%) | CN3: R33 - APPROVAL (%) | CO3: R34 - APPROVAL (%) | CP3: GERAL | CQ3: R1 - APPROVAL (%) | CR3: R2 - APPROVAL (%) | CS3: R3 - APPROVAL (%) | CT3: R4 - APPROVAL (%) | CU3: R5 - APPROVAL (%) | CV3: R6 - APPROVAL (%) | CW3: R7 - APPROVAL (%) | CX3: R8 - APPROVAL (%) | CY3: R9 - APPROVAL (%) | CZ3: R10 - APPROVAL (%) | DA3: R11 - APPROVAL (%) | DB3: R12 - APPROVAL (%) | DC3: R13 - APPROVAL (%) | DD3: R14 - APPROVAL (%) | DE3: R15 - APPROVAL (%) | DF3: R16 - APPROVAL (%) | DG3: R17 - APPROVAL (%) | DH3: R18 - APPROVAL (%) | DI3: R19 - APPROVAL (%) | DJ3: R20 - APPROVAL (%) | DK3: R21 - APPROVAL (%) | DL3: R22- APPROVAL (%) | DM3: R23 - APPROVAL (%) | DN3: R24 - APPROVAL (%) | DO3: R25 - APPROVAL (%) | DP3: R26 - APPROVAL (%) | DQ3: R27 - APPROVAL (%) | DR3: R28 - APPROVAL (%) | DS3: R29 - APPROVAL (%) | DT3: R30 - APPROVAL (%) | DU3: R31 - APPROVAL (%) | DV3: R32 - APPROVAL (%) | DW3: R33 - APPROVAL (%) | DX3: R34 - APPROVAL (%) | DY3: GERAL | DZ3: R1 - APPROVAL (%) | EA3: R2 - APPROVAL (%) | EB3: R3 - APPROVAL (%) | EC3: R4 - APPROVAL (%) | ED3: R5 - APPROVAL (%) | EE3: R6 - APPROVAL (%) | EF3: R7 - APPROVAL (%) | EG3: R8 - APPROVAL (%) | EH3: R9 - APPROVAL (%) | EI3: R10 - APPROVAL (%) | EJ3: R11 - APPROVAL (%) | EK3: R12 - APPROVAL (%) | EL3: R13 - APPROVAL (%) | EM3: R14 - APPROVAL (%) | EN3: R15 - APPROVAL (%) | EO3: R16 - APPROVAL (%) | EP3: GERAL | EQ3: R1 - APPROVAL (%) | ER3: GERAL | ES3: R1 - APPROVAL (%) | ET3: R2 - APPROVAL (%) | EU3: R3 - APPROVAL (%) | EV3: R4 - APPROVAL (%) | EW3: R5 - APPROVAL (%) | EX3: R6 - APPROVAL (%) | EY3: R7 - APPROVAL (%) | EZ3: R8 - APPROVAL (%) | FA3: R9 - APPROVAL (%) | FB3: R10 - APPROVAL (%) | FC3: R11 - APPROVAL (%) | FD3: R12 - APPROVAL (%) | FE3: R13 - APPROVAL (%) | FF3: R14 - APPROVAL (%) | FG3: R15 - APPROVAL (%) | FH3: R16 - APPROVAL (%) | FI3: R17 - APPROVAL (%) | FJ3: R18 - APPROVAL (%) | FK3: R19 - APPROVAL (%) | FL3: R20 - APPROVAL (%) | FM3: R21 - APPROVAL (%) | FN3: R22 - APPROVAL (%) | FO3: R23 - APPROVAL (%) | FP3: R24 - APPROVAL (%) | FQ3: R25 - APPROVAL (%) | FR3: R26 - APPROVAL (%) | FS3: R27 - APPROVAL (%) | FT3: R28 - APPROVAL (%) | FU3: R29 - APPROVAL (%) | FV3: R30 - APPROVAL (%) | FW3: R31 - APPROVAL (%) | FX3: R32 - APPROVAL (%) | FY3: R33 - APPROVAL (%) | FZ3: GERAL | GA3: R1 - APPROVAL (%) | GB3: R2 - APPROVAL (%) | GC3: R3 - APPROVAL (%) | GD3: R4 - APPROVAL (%) | GE3: R5 - APPROVAL (%) | GF3: R6 - APPROVAL (%) | GG3: R7 - APPROVAL (%) | GH3: R8 - APPROVAL (%) | GI3: R9 - APPROVAL (%) | GJ3: R10 - APPROVAL (%) | GK3: R11 - APPROVAL (%) | GL3: R12 - APPROVAL (%) | GM3: R13 - APPROVAL (%) | GN3: R14 - APPROVAL (%) | GO3: R15 - APPROVAL (%) | GP3: R16 - APPROVAL (%) | GQ3: R17 - APPROVAL (%) | GR3: R18 - APPROVAL (%) | GS3: R19- APPROVAL (%) | GT3: R20- APPROVAL (%) | GU3: R21- APPROVAL (%) | GV3: R22- APPROVAL (%) | GW3: R23- APPROVAL (%) | GX3: R24- APPROVAL (%) | GY3: R25- APPROVAL (%) | GZ3: R26- APPROVAL (%) | HA3: R27- APPROVAL (%) | HB3: R28- APPROVAL (%) | HC3: R29- APPROVAL (%) | HD3: R30- APPROVAL (%) | HE3: GERAL
A4: 1 | B4: ARCH | ARCHITECTURE
A5: 2 | B5: CPQ11-ARCH-ARCH-DATA-R24.rvt | C5: CPQ11-ARCH-ARCH-DATA-R22.rvt | D5: =MID(B5,17,4) -> DATA | E5: ARE ARQUITETURA | F5: 1130 | G5: ARE ARQUITETURA | H5: 1130 | I5: =IFERROR(VLOOKUP($C2:C108,'R22 RELATÓRIO ACC'!B:F,5,FALSE),"NOT PUBLISHED") -> V29 | J5: =IFERROR(VLOOKUP($C2:C108,'R22 RELATÓRIO ACC'!B:P,15,FALSE),"NOT PUBLISHED") -> 13/04/2026 | K5: =IFERROR(VLOOKUP($B2:B108,'RELATÓRIO ACC'!B:F,5,FALSE),"NOT PUBLISHED") -> V3 | L5: =IFERROR(VLOOKUP($B2:B108,'RELATÓRIO ACC'!B:P,15,FALSE),"NOT PUBLISHED") -> 03/06/2026 | M5: =IF(OR($D5="UTLS",$D5="GUAR",$D5="STIR",$D5="PUMP",$D5="SITE"), VLOOKUP($B5,'LOD 400 - SITE'!B:M,12,FALSE), VLOOKUP($B5,'LOD 400 - ADMN'!B:M,12,FALSE) ) -> V3 | N5: =IF(OR($D5="UTLS",$D5="GUAR",$D5="STIR",$D5="PUMP",$D5="SITE"), VLOOKUP($B5,'LOD 400 - SITE'!B:N,13,FALSE), VLOOKUP($B5,'LOD 400 - ADMN'!B:N,13,FALSE) ) -> 46176 | O5: =IF(OR($D5="UTLS",$D5="GUAR",$D5="STIR",$D5="PUMP",$D5="SITE"), VLOOKUP($B5,'LOD 400 - SITE'!B:O,14,FALSE), VLOOKUP($B5,'LOD 400 - ADMN'!B:O,14,FALSE) ) -> R24 | P5: =IF(OR($D5="C345",$D5="C12A",$D5="DATA"), VLOOKUP($B5,'LOD 400 - COLO3'!B:M,12,FALSE),"N/A") -> V3 | Q5: =IF(OR($D5="C345",$D5="C12A",$D5="DATA"), VLOOKUP($B5,'LOD 400 - COLO3'!B:N,13,FALSE),"N/A") -> 46176 | R5: =IF(OR($D5="C345",$D5="C12A",$D5="DATA"), VLOOKUP($B5,'LOD 400 - COLO3'!B:O,14,FALSE),"N/A") -> R24 | S5: =IF(OR($D5="C345",$D5="C12A",$D5="DATA"), VLOOKUP($B5,'LOD 400 - COLO4'!B:N,12,FALSE),"N/A") -> N/A | T5: =IF(OR($D5="C345",$D5="C12A",$D5="DATA"), VLOOKUP($B5,'LOD 400 - COLO4'!B:N,13,FALSE),"N/A") -> N/A | U5: =IF(OR($D5="C345",$D5="C12A",$D5="DATA"), VLOOKUP($B5,'LOD 400 - COLO4'!B:N,13,FALSE),"N/A") -> N/A | V5: =IF(OR($D5="UTLS",$D5="GUAR",$D5="STIR",$D5="PUMP",$D5="SITE"), VLOOKUP($B5,'LOD 400 - UTLS'!B:M,12,FALSE),"N/A") -> N/A | W5: =IF(OR($D5="UTLS",$D5="GUAR",$D5="STIR",$D5="PUMP",$D5="SITE"), VLOOKUP($B5,'LOD 400 - UTLS'!B:N,13,FALSE),"N/A") -> N/A | X5: =IF(OR($D5="UTLS",$D5="GUAR",$D5="STIR",$D5="PUMP",$D5="SITE"), VLOOKUP($B5,'LOD 400 - UTLS'!B:O,14,FALSE),"N/A") -> N/A | Y5: =IFERROR(VLOOKUP($B5,'LOD 400 - ADMN'!B:S,18,FALSE),"N/A") -> OUTDATED | Z5: =IFERROR(VLOOKUP($B5,'LOD 400 - ADMN'!B:V,21,FALSE),"N/A") -> OUTDATED | AA5: =IFERROR(VLOOKUP($B5,'LOD 400 - ADMN'!$B:Y,24,FALSE),"N/A") -> 0.08 | AB5: =IFERROR(VLOOKUP($B5,'LOD 400 - ADMN'!$B:AB,27,FALSE),"N/A") -> OUTDATED | AC5: =IFERROR(VLOOKUP($B5,'LOD 400 - ADMN'!$B:AE,30,FALSE),"N/A") -> NEXT ROUND | AD5: =IFERROR(VLOOKUP($B5,'LOD 400 - ADMN'!$B:AH,33,FALSE),"N/A") -> 0.56 | AE5: =IFERROR(VLOOKUP($B5,'LOD 400 - ADMN'!$B:AK,36,FALSE),"N/A") -> OUTDATED | AF5: =IFERROR(VLOOKUP($B5,'LOD 400 - ADMN'!$B:AN,39,FALSE),"N/A") -> NEXT ROUND | AG5: =IFERROR(VLOOKUP($B5,'LOD 400 - ADMN'!$B:AQ,42,FALSE),"N/A") -> 0.74 | AH5: =IFERROR(VLOOKUP($B5,'LOD 400 - ADMN'!$B:AT,45,FALSE),"N/A") -> NEXT ROUND | AI5: =IFERROR(VLOOKUP($B5,'LOD 400 - ADMN'!$B:AW,48,FALSE),"N/A") -> IMPROPER | AJ5: =IFERROR(VLOOKUP($B5,'LOD 400 - ADMN'!$B:AZ,51,FALSE),"N/A") -> IMPROPER | AK5: =IFERROR(VLOOKUP($B5,'LOD 400 - ADMN'!$B:BC,54,FALSE),"N/A") -> NEXT ROUND | AL5: =IFERROR(VLOOKUP($B5,'LOD 400 - ADMN'!$B:BF,57,FALSE),"N/A") -> IMPROPER | AM5: =IFERROR(VLOOKUP($B5,'LOD 400 - ADMN'!$B:BI,60,FALSE),"N/A") -> OUTDATED | AN5: =IFERROR(VLOOKUP($B5,'LOD 400 - ADMN'!$B:BL,63,FALSE),"N/A") -> OUTDATED | AO5: =IFERROR(VLOOKUP($B5,'LOD 400 - ADMN'!$B:BO,66,FALSE),"N/A") -> OUTDATED | AP5: =IFERROR(VLOOKUP($B5,'LOD 400 - ADMN'!$B:BR,69,FALSE),"N/A") -> 0.72 | AQ5: =IFERROR(VLOOKUP($B5,'LOD 400 - ADMN'!$B:BU,72,FALSE),"N/A") -> OUTDATED | AR5: =IFERROR(VLOOKUP($B5,'LOD 400 - ADMN'!$B:BX,75,FALSE),"N/A") -> OUTDATED | AS5: =IFERROR(VLOOKUP($B5,'LOD 400 - ADMN'!$B:CA,78,FALSE),"N/A") -> 0.64 | AT5: =IFERROR(VLOOKUP($B5,'LOD 400 - ADMN'!$B:CD,81,FALSE),"N/A") -> OUTDATED | AU5: =IFERROR(VLOOKUP($B5,'LOD 400 - ADMN'!$B:CG,84,FALSE),"N/A") -> OUTDATED | AV5: =IFERROR(VLOOKUP($B5,'LOD 400 - ADMN'!$B:CJ,87,FALSE),"N/A") -> OUTDATED | AW5: =IFERROR(VLOOKUP($B5,'LOD 400 - ADMN'!$B:CM,90,FALSE),"N/A") -> OUTDATED | AX5: =IFERROR(VLOOKUP($B5,'LOD 400 - ADMN'!$B:CP,93,FALSE),"N/A") -> NEXT ROUND | AY5: =IFERROR(VLOOKUP($B5,'LOD 400 - ADMN'!$B:CS,96,FALSE),"N/A") -> NEXT ROUND | AZ5: =IFERROR(VLOOKUP($B5,'LOD 400 - ADMN'!$B:CV,99,FALSE),"N/A") -> 0.81 | BA5: =IFERROR(VLOOKUP($B5,'LOD 400 - ADMN'!$B:CY,102,FALSE),"N/A") -> OUTDATED | BB5: =IFERROR(VLOOKUP($B5,'LOD 400 - ADMN'!$B:DB,105,FALSE),"N/A") -> OUTDATED | BC5: =IFERROR(VLOOKUP($B5,'LOD 400 - ADMN'!$B:DE,108,FALSE),"N/A") -> OUTDATED | BD5: =IFERROR(VLOOKUP($B5,'LOD 400 - ADMN'!$B:DH,111,FALSE),"N/A") -> OUTDATED | BE5: =IFERROR(VLOOKUP($B5,'LOD 400 - ADMN'!$B:DK,114,FALSE),"N/A") -> OUTDATED | BF5: =IFERROR(VLOOKUP($B5,'LOD 400 - ADMN'!$B:DN,117,FALSE),"N/A") -> OUTDATED | BG5: =IFERROR(__xludf.DUMMYFUNCTION("IFERROR( MAX(FILTER(Y5:BF5, ISNUMBER(Y5:BF5))), BF5 )"),0.81) -> 0.81 | BH5: =IFERROR(VLOOKUP($B5,'LOD 400 - COLO1'!B:S,18,FALSE),"N/A") -> OUTDATED | BI5: =IFERROR(VLOOKUP($B5,'LOD 400 - COLO1'!B:V,21,FALSE),"N/A") -> OUTDATED | BJ5: =IFERROR(VLOOKUP($B5,'LOD 400 - COLO1'!$B:Y,24,FALSE),"N/A") -> 0.62 | BK5: =IFERROR(VLOOKUP($B5,'LOD 400 - COLO1'!$B:AB,27,FALSE),"N/A") -> OUTDATED | BL5: =IFERROR(VLOOKUP($B5,'LOD 400 - COLO1'!$B:AE,30,FALSE),"N/A") -> NEXT ROUND | BM5: =IFERROR(VLOOKUP($B5,'LOD 400 - COLO1'!$B:AH,33,FALSE),"N/A") -> 0.81 | BN5: =IFERROR(VLOOKUP($B5,'LOD 400 - COLO1'!$B:AK,36,FALSE),"N/A") -> OUTDATED | BO5: =IFERROR(VLOOKUP($B5,'LOD 400 - COLO1'!$B:AN,39,FALSE),"N/A") -> NEXT ROUND | BP5: =IFERROR(VLOOKUP($B5,'LOD 400 - COLO1'!$B:AQ,42,FALSE),"N/A") -> 0.9 | BQ5: =IFERROR(VLOOKUP($B5,'LOD 400 - COLO1'!$B:AT,45,FALSE),"N/A") -> NEXT ROUND | BR5: =IFERROR(VLOOKUP($B5,'LOD 400 - COLO1'!$B:AW,48,FALSE),"N/A") -> IMPROPER | BS5: =IFERROR(VLOOKUP($B5,'LOD 400 - COLO1'!$B:AZ,51,FALSE),"N/A") -> IMPROPER | BT5: =IFERROR(VLOOKUP($B5,'LOD 400 - COLO1'!$B:BC,54,FALSE),"N/A") -> NEXT ROUND | BU5: =IFERROR(VLOOKUP($B5,'LOD 400 - COLO1'!$B:BF,57,FALSE),"N/A") -> IMPROPER | BV5: =IFERROR(VLOOKUP($B5,'LOD 400 - COLO1'!$B:BI,60,FALSE),"N/A") -> OUTDATED | BW5: =IFERROR(VLOOKUP($B5,'LOD 400 - COLO1'!$B:BL,63,FALSE),"N/A") -> OUTDATED | BX5: =IFERROR(VLOOKUP($B5,'LOD 400 - COLO1'!$B:BO,66,FALSE),"N/A") -> OUTDATED | BY5: =IFERROR(VLOOKUP($B5,'LOD 400 - COLO1'!$B:BR,69,FALSE),"N/A") -> 0.87 | BZ5: =IFERROR(VLOOKUP($B5,'LOD 400 - COLO1'!$B:BU,72,FALSE),"N/A") -> OUTDATED | CA5: =IFERROR(VLOOKUP($B5,'LOD 400 - COLO1'!$B:BX,75,FALSE),"N/A") -> OUTDATED | CB5: =IFERROR(VLOOKUP($B5,'LOD 400 - COLO1'!$B:CA,78,FALSE),"N/A") -> 0.77 | CC5: =IFERROR(VLOOKUP($B5,'LOD 400 - COLO1'!$B:CD,81,FALSE),"N/A") -> OUTDATED | CD5: =IFERROR(VLOOKUP($B5,'LOD 400 - COLO1'!$B:CG,84,FALSE),"N/A") -> OUTDATED | CE5: =IFERROR(VLOOKUP($B5,'LOD 400 - COLO1'!$B:CJ,87,FALSE),"N/A") -> OUTDATED | CF5: =IFERROR(VLOOKUP($B5,'LOD 400 - COLO1'!$B:CM,90,FALSE),"N/A") -> OUTDATED | CG5: =IFERROR(VLOOKUP($B5,'LOD 400 - COLO1'!$B:CP,93,FALSE),"N/A") -> NEXT ROUND | CH5: =IFERROR(VLOOKUP($B5,'LOD 400 - COLO1'!$B:CS,96,FALSE),"N/A") -> NEXT ROUND | CI5: =IFERROR(VLOOKUP($B5,'LOD 400 - COLO1'!$B:CV,99,FALSE),"N/A") -> 1 | CJ5: =IFERROR(VLOOKUP($B5,'LOD 400 - COLO1'!$B:CY,102,FALSE),"N/A") -> 1 | CK5: =IFERROR(VLOOKUP($B5,'LOD 400 - COLO1'!$B:DB,105,FALSE),"N/A") -> 1 | CL5: =IFERROR(VLOOKUP($B5,'LOD 400 - COLO1'!$B:DE,108,FALSE),"N/A") -> 1 | CM5: =IFERROR(VLOOKUP($B5,'LOD 400 - COLO1'!$B:DH,111,FALSE),"N/A") -> 1 | CN5: =IFERROR(VLOOKUP($B5,'LOD 400 - COLO1'!$B:DK,114,FALSE),"N/A") -> 1 | CO5: =IFERROR(VLOOKUP($B5,'LOD 400 - COLO1'!$B:DN,117,FALSE),"N/A") -> 1 | CP5: =IFERROR(__xludf.DUMMYFUNCTION("IFERROR( MAX(FILTER(BH5:CO5, ISNUMBER(BH5:CO5))), CO5 )"),1.0) -> 1 | CQ5: =IFERROR(VLOOKUP($B5,'LOD 400 - COLO2'!B:S,18,FALSE),"N/A") -> OUTDATED | CR5: =IFERROR(VLOOKUP($B5,'LOD 400 - COLO2'!B:V,21,FALSE),"N/A") -> OUTDATED | CS5: =IFERROR(VLOOKUP($B5,'LOD 400 - COLO2'!$B:Y,24,FALSE),"N/A") -> 0.43 | CT5: =IFERROR(VLOOKUP($B5,'LOD 400 - COLO2'!$B:DQ,27,FALSE),"N/A") -> OUTDATED | CU5: =IFERROR(VLOOKUP($B5,'LOD 400 - COLO2'!$B:AE,30,FALSE),"N/A") -> NEXT ROUND | CV5: =IFERROR(VLOOKUP($B5,'LOD 400 - COLO2'!$B:AH,33,FALSE),"N/A") -> 0.69 | CW5: =IFERROR(VLOOKUP($B5,'LOD 400 - COLO2'!$B:AK,36,FALSE),"N/A") -> OUTDATED | CX5: =IFERROR(VLOOKUP($B5,'LOD 400 - COLO2'!$B:AN,39,FALSE),"N/A") -> NEXT ROUND | CY5: =IFERROR(VLOOKUP($B5,'LOD 400 - COLO2'!$B:AQ,42,FALSE),"N/A") -> 0.86 | CZ5: =IFERROR(VLOOKUP($B5,'LOD 400 - COLO2'!$B:AT,45,FALSE),"N/A") -> NEXT ROUND | DA5: =IFERROR(VLOOKUP($B5,'LOD 400 - COLO2'!$B:AW,48,FALSE),"N/A") -> IMPROPER | DB5: =IFERROR(VLOOKUP($B5,'LOD 400 - COLO2'!$B:AZ,51,FALSE),"N/A") -> IMPROPER | DC5: =IFERROR(VLOOKUP($B5,'LOD 400 - COLO2'!$B:BC,54,FALSE),"N/A") -> NEXT ROUND | DD5: =IFERROR(VLOOKUP($B5,'LOD 400 - COLO2'!$B:BF,57,FALSE),"N/A") -> IMPROPER | DE5: =IFERROR(VLOOKUP($B5,'LOD 400 - COLO2'!$B:BI,60,FALSE),"N/A") -> OUTDATED | DF5: =IFERROR(VLOOKUP($B5,'LOD 400 - COLO2'!$B:BL,63,FALSE),"N/A") -> OUTDATED | DG5: =IFERROR(VLOOKUP($B5,'LOD 400 - COLO2'!$B:BO,66,FALSE),"N/A") -> OUTDATED | DH5: =IFERROR(VLOOKUP($B5,'LOD 400 - COLO2'!$B:BR,69,FALSE),"N/A") -> NEXT ROUND | DI5: =IFERROR(VLOOKUP($B5,'LOD 400 - COLO2'!$B:BU,72,FALSE),"N/A") -> 0.81 | DJ5: =IFERROR(VLOOKUP($B5,'LOD 400 - COLO2'!$B:BX,75,FALSE),"N/A") -> OUTDATED | DK5: =IFERROR(VLOOKUP($B5,'LOD 400 - COLO2'!$B:CA,78,FALSE),"N/A") -> 0.74 | DL5: =IFERROR(VLOOKUP($B5,'LOD 400 - COLO2'!$B:CD,81,FALSE),"N/A") -> OUTDATED | DM5: =IFERROR(VLOOKUP($B5,'LOD 400 - COLO2'!$B:CG,84,FALSE),"N/A") -> OUTDATED | DN5: =IFERROR(VLOOKUP($B5,'LOD 400 - COLO2'!$B:CJ,87,FALSE),"N/A") -> OUTDATED | DO5: =IFERROR(VLOOKUP($B5,'LOD 400 - COLO2'!$B:CM,90,FALSE),"N/A") -> OUTDATED | DP5: =IFERROR(VLOOKUP($B5,'LOD 400 - COLO2'!$B:CP,93,FALSE),"N/A") -> NEXT ROUND | DQ5: =IFERROR(VLOOKUP($B5,'LOD 400 - COLO2'!$B:CS,96,FALSE),"N/A") -> NEXT ROUND | DR5: =IFERROR(VLOOKUP($B5,'LOD 400 - COLO2'!$B:CV,99,FALSE),"N/A") -> NEXT ROUND | DS5: =IFERROR(VLOOKUP($B5,'LOD 400 - COLO2'!$B:CY,102,FALSE),"N/A") -> 1 | DT5: =IFERROR(VLOOKUP($B5,'LOD 400 - COLO2'!$B:DB,105,FALSE),"N/A") -> 1 | DU5: =IFERROR(VLOOKUP($B5,'LOD 400 - COLO2'!$B:DE,108,FALSE),"N/A") -> 1 | DV5: =IFERROR(VLOOKUP($B5,'LOD 400 - COLO2'!$B:DH,111,FALSE),"N/A") -> 1 | DW5: =IFERROR(VLOOKUP($B5,'LOD 400 - COLO2'!$B:DK,114,FALSE),"N/A") -> 1 | DX5: =IFERROR(VLOOKUP($B5,'LOD 400 - COLO2'!$B:DN,117,FALSE),"N/A") -> 1 | DY5: =IFERROR(__xludf.DUMMYFUNCTION("IFERROR( MAX(FILTER(CQ5:DW5, ISNUMBER(CQ5:DW5))), DW5 )"),1.0) -> 1 | DZ5: =IFERROR(VLOOKUP($B5,'LOD 400 - COLO3'!B:S,18,FALSE),"N/A") -> 0 | EA5: =IFERROR(VLOOKUP($B5,'LOD 400 - COLO3'!B:V,21,FALSE),"N/A") -> 0.74 | EB5: =IFERROR(VLOOKUP($B5,'LOD 400 - COLO3'!B:Y,24,FALSE),"N/A") -> 0.79 | EC5: =IFERROR(VLOOKUP($B5,'LOD 400 - COLO3'!B:AB,27,FALSE),"N/A") -> OUTDATED | ED5: =IFERROR(VLOOKUP($B5,'LOD 400 - COLO3'!B:AE,30,FALSE),"N/A") -> OUTDATED | EE5: =IFERROR(VLOOKUP($B5,'LOD 400 - COLO3'!B:AH,33,FALSE),"N/A") -> OUTDATED | EF5: =IFERROR(VLOOKUP($B5,'LOD 400 - COLO3'!B:AK,36,FALSE),"N/A") -> OUTDATED | EG5: =IFERROR(VLOOKUP($B5,'LOD 400 - COLO3'!B:AN,39,FALSE),"N/A") -> NEXT ROUND | EH5: =IFERROR(VLOOKUP($B5,'LOD 400 - COLO3'!B:AQ,42,FALSE),"N/A") -> NEXT ROUND | EI5: =IFERROR(VLOOKUP($B5,'LOD 400 - COLO3'!B:AT,45,FALSE),"N/A") -> NEXT ROUND | EJ5: =IFERROR(VLOOKUP($B5,'LOD 400 - COLO3'!B:AW,48,FALSE),"N/A") -> 1 | EK5: =IFERROR(VLOOKUP($B5,'LOD 400 - COLO3'!B:AZ,51,FALSE),"N/A") -> 1 | EL5: =IFERROR(VLOOKUP($B5,'LOD 400 - COLO3'!B:BC,54,FALSE),"N/A") -> 1 | EM5: =IFERROR(VLOOKUP($B5,'LOD 400 - COLO3'!B:BF,57,FALSE),"N/A") -> 1 | EN5: =IFERROR(VLOOKUP($B5,'LOD 400 - COLO3'!B:BI,60,FALSE),"N/A") -> 1 | EO5: =IFERROR(VLOOKUP($B5,'LOD 400 - COLO3'!B:BL,63,FALSE),"N/A") -> 1 | EP5: =IFERROR(__xludf.DUMMYFUNCTION("IFERROR( MAX(FILTER(DZ5:EO5, ISNUMBER(DZ5:EO5))), EO5 )"),1.0) -> 1 | EQ5: =IFERROR(VLOOKUP($B5,'LOD 400 - COLO4'!B:S,18,FALSE),"N/A") -> 0 | ER5: =IFERROR(__xludf.DUMMYFUNCTION("IFERROR( MAX(FILTER(EQ5, ISNUMBER(EQ5))), EQ5 )"),0.0) -> 0 | ES5: =IFERROR(VLOOKUP($B5,'LOD 400 - SITE'!B:S,18,FALSE),"N/A") -> N/A | ET5: =IFERROR(VLOOKUP($B5,'LOD 400 - SITE'!B:V,21,FALSE),"N/A") -> N/A | EU5: =IFERROR(VLOOKUP($B5,'LOD 400 - SITE'!$B:Y,24,FALSE),"N/A") -> N/A | EV5: =IFERROR(VLOOKUP($B5,'LOD 400 - SITE'!$B:AB,27,FALSE),"N/A") -> N/A | EW5: =IFERROR(VLOOKUP($B5,'LOD 400 - SITE'!$B:AE,30,FALSE),"N/A") -> N/A | EX5: =IFERROR(VLOOKUP($B5,'LOD 400 - SITE'!$B:AH,33,FALSE),"N/A") -> N/A | EY5: =IFERROR(VLOOKUP($B5,'LOD 400 - SITE'!$B:AK,36,FALSE),"N/A") -> N/A | EZ5: =IFERROR(VLOOKUP($B5,'LOD 400 - SITE'!$B:AN,39,FALSE),"N/A") -> N/A | FA5: =IFERROR(VLOOKUP($B5,'LOD 400 - SITE'!$B:AQ,42,FALSE),"N/A") -> N/A | FB5: =IFERROR(VLOOKUP($B5,'LOD 400 - SITE'!$B:AT,45,FALSE),"N/A") -> N/A | FC5: =IFERROR(VLOOKUP($B5,'LOD 400 - SITE'!$B:AW,48,FALSE),"N/A") -> N/A | FD5: =IFERROR(VLOOKUP($B5,'LOD 400 - SITE'!$B:AZ,51,FALSE),"N/A") -> N/A | FE5: =IFERROR(VLOOKUP($B5,'LOD 400 - SITE'!$B:BC,54,FALSE),"N/A") -> N/A | FF5: =IFERROR(VLOOKUP($B5,'LOD 400 - SITE'!$B:BF,57,FALSE),"N/A") -> N/A | FG5: =IFERROR(VLOOKUP($B5,'LOD 400 - SITE'!$B:BI,60,FALSE),"N/A") -> N/A | FH5: =IFERROR(VLOOKUP($B5,'LOD 400 - SITE'!$B:BL,63,FALSE),"N/A") -> N/A | FI5: =IFERROR(VLOOKUP($B5,'LOD 400 - SITE'!$B:BO,66,FALSE),"N/A") -> N/A | FJ5: =IFERROR(VLOOKUP($B5,'LOD 400 - SITE'!$B:BR,69,FALSE),"N/A") -> N/A | FK5: =IFERROR(VLOOKUP($B5,'LOD 400 - SITE'!$B:BU,72,FALSE),"N/A") -> N/A | FL5: =IFERROR(VLOOKUP($B5,'LOD 400 - SITE'!$B:BX,75,FALSE),"N/A") -> N/A | FM5: =IFERROR(VLOOKUP($B5,'LOD 400 - SITE'!$B:CA,78,FALSE),"N/A") -> N/A | FN5: =IFERROR(VLOOKUP($B5,'LOD 400 - SITE'!$B:CD,81,FALSE),"N/A") -> N/A | FO5: =IFERROR(VLOOKUP($B5,'LOD 400 - SITE'!$B:CG,84,FALSE),"N/A") -> N/A | FP5: =IFERROR(VLOOKUP($B5,'LOD 400 - SITE'!$B:CJ,87,FALSE),"N/A") -> N/A | FQ5: =IFERROR(VLOOKUP($B5,'LOD 400 - SITE'!$B:CM,90,FALSE),"N/A") -> N/A | FR5: =IFERROR(VLOOKUP($B5,'LOD 400 - SITE'!$B:CP,93,FALSE),"N/A") -> N/A | FS5: =IFERROR(VLOOKUP($B5,'LOD 400 - SITE'!$B:CS,96,FALSE),"N/A") -> N/A | FT5: =IFERROR(VLOOKUP($B5,'LOD 400 - SITE'!$B:CV,99,FALSE),"N/A") -> N/A | FU5: =IFERROR(VLOOKUP($B5,'LOD 400 - SITE'!$B:CY,102,FALSE),"N/A") -> N/A | FV5: =IFERROR(VLOOKUP($B5,'LOD 400 - SITE'!$B:DB,105,FALSE),"N/A") -> N/A | FW5: =IFERROR(VLOOKUP($B5,'LOD 400 - SITE'!$B:DE,108,FALSE),"N/A") -> N/A | FX5: =IFERROR(VLOOKUP($B5,'LOD 400 - SITE'!$B:DH,111,FALSE),"N/A") -> N/A | FY5: =IFERROR(VLOOKUP($B5,'LOD 400 - SITE'!$B:DK,114,FALSE),"N/A") -> N/A | FZ5: =IFERROR(__xludf.DUMMYFUNCTION("IFERROR( MAX(FILTER(ES5:FY5, ISNUMBER(ES5:FY5))), FY5 )"),"N/A") -> N/A | GA5: =IFERROR(VLOOKUP($B5,'LOD 400 - UTLS'!B:S,18,FALSE),"N/A") -> N/A | GB5: =IFERROR(VLOOKUP($B5,'LOD 400 - UTLS'!B:V,21,FALSE),"N/A") -> N/A | GC5: =IFERROR(VLOOKUP($B5,'LOD 400 - UTLS'!B:Y,24,FALSE),"N/A") -> N/A | GD5: =IFERROR(VLOOKUP($B5,'LOD 400 - UTLS'!$B:AB,27,FALSE),"N/A") -> N/A | GE5: =IFERROR(VLOOKUP($B5,'LOD 400 - UTLS'!$B:AE,30,FALSE),"N/A") -> N/A | GF5: =IFERROR(VLOOKUP($B5,'LOD 400 - UTLS'!$B:AH,33,FALSE),"N/A") -> N/A | GG5: =IFERROR(VLOOKUP($B5,'LOD 400 - UTLS'!$B:AK,36,FALSE),"N/A") -> N/A | GH5: =IFERROR(VLOOKUP($B5,'LOD 400 - UTLS'!$B:AN,39,FALSE),"N/A") -> N/A | GI5: =IFERROR(VLOOKUP($B5,'LOD 400 - UTLS'!$B:AQ,42,FALSE),"N/A") -> N/A | GJ5: =IFERROR(VLOOKUP($B5,'LOD 400 - UTLS'!$B:AT,45,FALSE),"N/A") -> N/A | GK5: =IFERROR(VLOOKUP($B5,'LOD 400 - UTLS'!$B:AW,48,FALSE),"N/A") -> N/A | GL5: =IFERROR(VLOOKUP($B5,'LOD 400 - UTLS'!$B:AZ,51,FALSE),"N/A") -> N/A | GM5: =IFERROR(VLOOKUP($B5,'LOD 400 - UTLS'!$B:BC,54,FALSE),"N/A") -> N/A | GN5: =IFERROR(VLOOKUP($B5,'LOD 400 - UTLS'!$B:BF,57,FALSE),"N/A") -> N/A | GO5: =IFERROR(VLOOKUP($B5,'LOD 400 - UTLS'!$B:BI,60,FALSE),"N/A") -> N/A | GP5: =IFERROR(VLOOKUP($B5,'LOD 400 - UTLS'!$B:BL,63,FALSE),"N/A") -> N/A | GQ5: =IFERROR(VLOOKUP($B5,'LOD 400 - UTLS'!$B:BO,66,FALSE),"N/A") -> N/A | GR5: =IFERROR(VLOOKUP($B5,'LOD 400 - UTLS'!$B:BR,69,FALSE),"N/A") -> N/A | GS5: =IFERROR(VLOOKUP($B5,'LOD 400 - UTLS'!$B:BU,72,FALSE),"N/A") -> N/A | GT5: =IFERROR(VLOOKUP($B5,'LOD 400 - UTLS'!$B:BX,75,FALSE),"N/A") -> N/A | GU5: =IFERROR(VLOOKUP($B5,'LOD 400 - UTLS'!$B:CA,78,FALSE),"N/A") -> N/A | GV5: =IFERROR(VLOOKUP($B5,'LOD 400 - UTLS'!$B:CD,81,FALSE),"N/A") -> N/A | GW5: =IFERROR(VLOOKUP($B5,'LOD 400 - UTLS'!$B:CG,84,FALSE),"N/A") -> N/A | GX5: =IFERROR(VLOOKUP($B5,'LOD 400 - UTLS'!$B:CJ,87,FALSE),"N/A") -> N/A | GY5: =IFERROR(VLOOKUP($B5,'LOD 400 - UTLS'!$B:CM,90,FALSE),"N/A") -> N/A | GZ5: =IFERROR(VLOOKUP($B5,'LOD 400 - UTLS'!$B:CP,93,FALSE),"N/A") -> N/A | HA5: =IFERROR(VLOOKUP($B5,'LOD 400 - UTLS'!$B:CS,96,FALSE),"N/A") -> N/A | HB5: =IFERROR(VLOOKUP($B5,'LOD 400 - UTLS'!$B:CV,99,FALSE),"N/A") -> N/A | HC5: =IFERROR(VLOOKUP($B5,'LOD 400 - UTLS'!$B:CY,102,FALSE),"N/A") -> N/A | HD5: =IFERROR(VLOOKUP($B5,'LOD 400 - UTLS'!$B:DB,105,FALSE),"N/A") -> N/A | HE5: =IFERROR(__xludf.DUMMYFUNCTION("IFERROR( MAX(FILTER(GA5:HD5, ISNUMBER(GA5:HD5))), HD5 )"),"N/A") -> N/A
A6: 3 | B6: CPQ11-ARCH-ARCH-SITE-R24.rvt | C6: CPQ11-ARCH-ARCH-SITE-R22.rvt | D6: =MID(B6,17,4) -> SITE | E6: ARE ARQUITETURA | F6: 1130 | G6: ARE ARQUITETURA | H6: 1130 | I6: =IFERROR(VLOOKUP($C3:C108,'R22 RELATÓRIO ACC'!B:F,5,FALSE),"NOT PUBLISHED") -> V28 | J6: =IFERROR(VLOOKUP($C3:C108,'R22 RELATÓRIO ACC'!B:P,15,FALSE),"NOT PUBLISHED") -> 17/04/2026 | K6: =IFERROR(VLOOKUP($B3:B108,'RELATÓRIO ACC'!B:F,5,FALSE),"NOT PUBLISHED") -> V4 | L6: =IFERROR(VLOOKUP($B3:B108,'RELATÓRIO ACC'!B:P,15,FALSE),"NOT PUBLISHED") -> 15/07/2026 | M6: =IF(OR($D6="UTLS",$D6="GUAR",$D6="STIR",$D6="PUMP",$D6="SITE"), VLOOKUP($B6,'LOD 400 - SITE'!B:M,12,FALSE), VLOOKUP($B6,'LOD 400 - ADMN'!B:M,12,FALSE) ) -> V4 | N6: =IF(OR($D6="UTLS",$D6="GUAR",$D6="STIR",$D6="PUMP",$D6="SITE"), VLOOKUP($B6,'LOD 400 - SITE'!B:N,13,FALSE), VLOOKUP($B6,'LOD 400 - ADMN'!B:N,13,FALSE) ) -> 46218 | O6: =IF(OR($D6="UTLS",$D6="GUAR",$D6="STIR",$D6="PUMP",$D6="SITE"), VLOOKUP($B6,'LOD 400 - SITE'!B:O,14,FALSE), VLOOKUP($B6,'LOD 400 - ADMN'!B:O,14,FALSE) ) -> R24 | P6: =IF(OR($D6="C345",$D6="C12A",$D6="DATA"), VLOOKUP($B6,'LOD 400 - COLO3'!B:M,12,FALSE),"N/A") -> N/A | Q6: =IF(OR($D6="C345",$D6="C12A",$D6="DATA"), VLOOKUP($B6,'LOD 400 - COLO3'!B:N,13,FALSE),"N/A") -> N/A | R6: =IF(OR($D6="C345",$D6="C12A",$D6="DATA"), VLOOKUP($B6,'LOD 400 - COLO3'!B:O,14,FALSE),"N/A") -> N/A | S6: =IF(OR($D6="C345",$D6="C12A",$D6="DATA"), VLOOKUP($B6,'LOD 400 - COLO4'!B:N,12,FALSE),"N/A") -> N/A | T6: =IF(OR($D6="C345",$D6="C12A",$D6="DATA"), VLOOKUP($B6,'LOD 400 - COLO4'!B:N,13,FALSE),"N/A") -> N/A | U6: =IF(OR($D6="C345",$D6="C12A",$D6="DATA"), VLOOKUP($B6,'LOD 400 - COLO4'!B:N,13,FALSE),"N/A") -> N/A | V6: =IF(OR($D6="UTLS",$D6="GUAR",$D6="STIR",$D6="PUMP",$D6="SITE"), VLOOKUP($B6,'LOD 400 - UTLS'!B:M,12,FALSE),"N/A") -> V3 | W6: =IF(OR($D6="UTLS",$D6="GUAR",$D6="STIR",$D6="PUMP",$D6="SITE"), VLOOKUP($B6,'LOD 400 - UTLS'!B:N,13,FALSE),"N/A") -> 46176 | X6: =IF(OR($D6="UTLS",$D6="GUAR",$D6="STIR",$D6="PUMP",$D6="SITE"), VLOOKUP($B6,'LOD 400 - UTLS'!B:O,14,FALSE),"N/A") -> R24 | Y6: =IFERROR(VLOOKUP($B6,'LOD 400 - ADMN'!B:S,18,FALSE),"N/A") -> N/A | Z6: =IFERROR(VLOOKUP($B6,'LOD 400 - ADMN'!B:V,21,FALSE),"N/A") -> N/A | AA6: =IFERROR(VLOOKUP($B6,'LOD 400 - ADMN'!$B:Y,24,FALSE),"N/A") -> N/A | AB6: =IFERROR(VLOOKUP($B6,'LOD 400 - ADMN'!$B:AB,27,FALSE),"N/A") -> N/A | AC6: =IFERROR(VLOOKUP($B6,'LOD 400 - ADMN'!$B:AE,30,FALSE),"N/A") -> N/A | AD6: =IFERROR(VLOOKUP($B6,'LOD 400 - ADMN'!$B:AH,33,FALSE),"N/A") -> N/A | AE6: =IFERROR(VLOOKUP($B6,'LOD 400 - ADMN'!$B:AK,36,FALSE),"N/A") -> N/A | AF6: =IFERROR(VLOOKUP($B6,'LOD 400 - ADMN'!$B:AN,39,FALSE),"N/A") -> N/A | AG6: =IFERROR(VLOOKUP($B6,'LOD 400 - ADMN'!$B:AQ,42,FALSE),"N/A") -> N/A | AH6: =IFERROR(VLOOKUP($B6,'LOD 400 - ADMN'!$B:AT,45,FALSE),"N/A") -> N/A | AI6: =IFERROR(VLOOKUP($B6,'LOD 400 - ADMN'!$B:AW,48,FALSE),"N/A") -> N/A | AJ6: =IFERROR(VLOOKUP($B6,'LOD 400 - ADMN'!$B:AZ,51,FALSE),"N/A") -> N/A | AK6: =IFERROR(VLOOKUP($B6,'LOD 400 - ADMN'!$B:BC,54,FALSE),"N/A") -> N/A | AL6: =IFERROR(VLOOKUP($B6,'LOD 400 - ADMN'!$B:BF,57,FALSE),"N/A") -> N/A | AM6: =IFERROR(VLOOKUP($B6,'LOD 400 - ADMN'!$B:BI,60,FALSE),"N/A") -> N/A | AN6: =IFERROR(VLOOKUP($B6,'LOD 400 - ADMN'!$B:BL,63,FALSE),"N/A") -> N/A | AO6: =IFERROR(VLOOKUP($B6,'LOD 400 - ADMN'!$B:BO,66,FALSE),"N/A") -> N/A | AP6: =IFERROR(VLOOKUP($B6,'LOD 400 - ADMN'!$B:BR,69,FALSE),"N/A") -> N/A | AQ6: =IFERROR(VLOOKUP($B6,'LOD 400 - ADMN'!$B:BU,72,FALSE),"N/A") -> N/A | AR6: =IFERROR(VLOOKUP($B6,'LOD 400 - ADMN'!$B:BX,75,FALSE),"N/A") -> N/A | AS6: =IFERROR(VLOOKUP($B6,'LOD 400 - ADMN'!$B:CA,78,FALSE),"N/A") -> N/A | AT6: =IFERROR(VLOOKUP($B6,'LOD 400 - ADMN'!$B:CD,81,FALSE),"N/A") -> N/A | AU6: =IFERROR(VLOOKUP($B6,'LOD 400 - ADMN'!$B:CG,84,FALSE),"N/A") -> N/A | AV6: =IFERROR(VLOOKUP($B6,'LOD 400 - ADMN'!$B:CJ,87,FALSE),"N/A") -> N/A | AW6: =IFERROR(VLOOKUP($B6,'LOD 400 - ADMN'!$B:CM,90,FALSE),"N/A") -> N/A | AX6: =IFERROR(VLOOKUP($B6,'LOD 400 - ADMN'!$B:CP,93,FALSE),"N/A") -> N/A | AY6: =IFERROR(VLOOKUP($B6,'LOD 400 - ADMN'!$B:CS,96,FALSE),"N/A") -> N/A | AZ6: =IFERROR(VLOOKUP($B6,'LOD 400 - ADMN'!$B:CV,99,FALSE),"N/A") -> N/A | BA6: =IFERROR(VLOOKUP($B6,'LOD 400 - ADMN'!$B:CY,102,FALSE),"N/A") -> N/A | BB6: =IFERROR(VLOOKUP($B6,'LOD 400 - ADMN'!$B:DB,105,FALSE),"N/A") -> N/A | BC6: =IFERROR(VLOOKUP($B6,'LOD 400 - ADMN'!$B:DE,108,FALSE),"N/A") -> N/A | BD6: =IFERROR(VLOOKUP($B6,'LOD 400 - ADMN'!$B:DH,111,FALSE),"N/A") -> N/A | BE6: =IFERROR(VLOOKUP($B6,'LOD 400 - ADMN'!$B:DK,114,FALSE),"N/A") -> N/A | BF6: =IFERROR(VLOOKUP($B6,'LOD 400 - ADMN'!$B:DN,117,FALSE),"N/A") -> N/A | BG6: =IFERROR(__xludf.DUMMYFUNCTION("IFERROR( MAX(FILTER(Y6:BF6, ISNUMBER(Y6:BF6))), BF6 )"),"N/A") -> N/A | BH6: =IFERROR(VLOOKUP($B6,'LOD 400 - COLO1'!B:S,18,FALSE),"N/A") -> N/A | BI6: =IFERROR(VLOOKUP($B6,'LOD 400 - COLO1'!B:V,21,FALSE),"N/A") -> N/A | BJ6: =IFERROR(VLOOKUP($B6,'LOD 400 - COLO1'!$B:Y,24,FALSE),"N/A") -> N/A | BK6: =IFERROR(VLOOKUP($B6,'LOD 400 - COLO1'!$B:AB,27,FALSE),"N/A") -> N/A | BL6: =IFERROR(VLOOKUP($B6,'LOD 400 - COLO1'!$B:AE,30,FALSE),"N/A") -> N/A | BM6: =IFERROR(VLOOKUP($B6,'LOD 400 - COLO1'!$B:AH,33,FALSE),"N/A") -> N/A | BN6: =IFERROR(VLOOKUP($B6,'LOD 400 - COLO1'!$B:AK,36,FALSE),"N/A") -> N/A | BO6: =IFERROR(VLOOKUP($B6,'LOD 400 - COLO1'!$B:AN,39,FALSE),"N/A") -> N/A | BP6: =IFERROR(VLOOKUP($B6,'LOD 400 - COLO1'!$B:AQ,42,FALSE),"N/A") -> N/A | BQ6: =IFERROR(VLOOKUP($B6,'LOD 400 - COLO1'!$B:AT,45,FALSE),"N/A") -> N/A | BR6: =IFERROR(VLOOKUP($B6,'LOD 400 - COLO1'!$B:AW,48,FALSE),"N/A") -> N/A | BS6: =IFERROR(VLOOKUP($B6,'LOD 400 - COLO1'!$B:AZ,51,FALSE),"N/A") -> N/A | BT6: =IFERROR(VLOOKUP($B6,'LOD 400 - COLO1'!$B:BC,54,FALSE),"N/A") -> N/A | BU6: =IFERROR(VLOOKUP($B6,'LOD 400 - COLO1'!$B:BF,57,FALSE),"N/A") -> N/A | BV6: =IFERROR(VLOOKUP($B6,'LOD 400 - COLO1'!$B:BI,60,FALSE),"N/A") -> N/A | BW6: =IFERROR(VLOOKUP($B6,'LOD 400 - COLO1'!$B:BL,63,FALSE),"N/A") -> N/A | BX6: =IFERROR(VLOOKUP($B6,'LOD 400 - COLO1'!$B:BO,66,FALSE),"N/A") -> N/A | BY6: =IFERROR(VLOOKUP($B6,'LOD 400 - COLO1'!$B:BR,69,FALSE),"N/A") -> N/A | BZ6: =IFERROR(VLOOKUP($B6,'LOD 400 - COLO1'!$B:BU,72,FALSE),"N/A") -> N/A | CA6: =IFERROR(VLOOKUP($B6,'LOD 400 - COLO1'!$B:BX,75,FALSE),"N/A") -> N/A | CB6: =IFERROR(VLOOKUP($B6,'LOD 400 - COLO1'!$B:CA,78,FALSE),"N/A") -> N/A | CC6: =IFERROR(VLOOKUP($B6,'LOD 400 - COLO1'!$B:CD,81,FALSE),"N/A") -> N/A | CD6: =IFERROR(VLOOKUP($B6,'LOD 400 - COLO1'!$B:CG,84,FALSE),"N/A") -> N/A | CE6: =IFERROR(VLOOKUP($B6,'LOD 400 - COLO1'!$B:CJ,87,FALSE),"N/A") -> N/A | CF6: =IFERROR(VLOOKUP($B6,'LOD 400 - COLO1'!$B:CM,90,FALSE),"N/A") -> N/A | CG6: =IFERROR(VLOOKUP($B6,'LOD 400 - COLO1'!$B:CP,93,FALSE),"N/A") -> N/A | CH6: =IFERROR(VLOOKUP($B6,'LOD 400 - COLO1'!$B:CS,96,FALSE),"N/A") -> N/A | CI6: =IFERROR(VLOOKUP($B6,'LOD 400 - COLO1'!$B:CV,99,FALSE),"N/A") -> N/A | CJ6: =IFERROR(VLOOKUP($B6,'LOD 400 - COLO1'!$B:CY,102,FALSE),"N/A") -> N/A | CK6: =IFERROR(VLOOKUP($B6,'LOD 400 - COLO1'!$B:DB,105,FALSE),"N/A") -> N/A | CL6: =IFERROR(VLOOKUP($B6,'LOD 400 - COLO1'!$B:DE,108,FALSE),"N/A") -> N/A | CM6: =IFERROR(VLOOKUP($B6,'LOD 400 - COLO1'!$B:DH,111,FALSE),"N/A") -> N/A | CN6: =IFERROR(VLOOKUP($B6,'LOD 400 - COLO1'!$B:DK,114,FALSE),"N/A") -> N/A | CO6: =IFERROR(VLOOKUP($B6,'LOD 400 - COLO1'!$B:DN,117,FALSE),"N/A") -> N/A | CP6: =IFERROR(__xludf.DUMMYFUNCTION("IFERROR( MAX(FILTER(BH6:CO6, ISNUMBER(BH6:CO6))), CO6 )"),"N/A") -> N/A | CQ6: =IFERROR(VLOOKUP($B6,'LOD 400 - COLO2'!B:S,18,FALSE),"N/A") -> N/A | CR6: =IFERROR(VLOOKUP($B6,'LOD 400 - COLO2'!B:V,21,FALSE),"N/A") -> N/A | CS6: =IFERROR(VLOOKUP($B6,'LOD 400 - COLO2'!$B:Y,24,FALSE),"N/A") -> N/A | CT6: =IFERROR(VLOOKUP($B6,'LOD 400 - COLO2'!$B:DQ,27,FALSE),"N/A") -> N/A | CU6: =IFERROR(VLOOKUP($B6,'LOD 400 - COLO2'!$B:AE,30,FALSE),"N/A") -> N/A | CV6: =IFERROR(VLOOKUP($B6,'LOD 400 - COLO2'!$B:AH,33,FALSE),"N/A") -> N/A | CW6: =IFERROR(VLOOKUP($B6,'LOD 400 - COLO2'!$B:AK,36,FALSE),"N/A") -> N/A | CX6: =IFERROR(VLOOKUP($B6,'LOD 400 - COLO2'!$B:AN,39,FALSE),"N/A") -> N/A | CY6: =IFERROR(VLOOKUP($B6,'LOD 400 - COLO2'!$B:AQ,42,FALSE),"N/A") -> N/A | CZ6: =IFERROR(VLOOKUP($B6,'LOD 400 - COLO2'!$B:AT,45,FALSE),"N/A") -> N/A | DA6: =IFERROR(VLOOKUP($B6,'LOD 400 - COLO2'!$B:AW,48,FALSE),"N/A") -> N/A | DB6: =IFERROR(VLOOKUP($B6,'LOD 400 - COLO2'!$B:AZ,51,FALSE),"N/A") -> N/A | DC6: =IFERROR(VLOOKUP($B6,'LOD 400 - COLO2'!$B:BC,54,FALSE),"N/A") -> N/A | DD6: =IFERROR(VLOOKUP($B6,'LOD 400 - COLO2'!$B:BF,57,FALSE),"N/A") -> N/A | DE6: =IFERROR(VLOOKUP($B6,'LOD 400 - COLO2'!$B:BI,60,FALSE),"N/A") -> N/A | DF6: =IFERROR(VLOOKUP($B6,'LOD 400 - COLO2'!$B:BL,63,FALSE),"N/A") -> N/A | DG6: =IFERROR(VLOOKUP($B6,'LOD 400 - COLO2'!$B:BO,66,FALSE),"N/A") -> N/A | DH6: =IFERROR(VLOOKUP($B6,'LOD 400 - COLO2'!$B:BR,69,FALSE),"N/A") -> N/A | DI6: =IFERROR(VLOOKUP($B6,'LOD 400 - COLO2'!$B:BU,72,FALSE),"N/A") -> N/A | DJ6: =IFERROR(VLOOKUP($B6,'LOD 400 - COLO2'!$B:BX,75,FALSE),"N/A") -> N/A | DK6: =IFERROR(VLOOKUP($B6,'LOD 400 - COLO2'!$B:CA,78,FALSE),"N/A") -> N/A | DL6: =IFERROR(VLOOKUP($B6,'LOD 400 - COLO2'!$B:CD,81,FALSE),"N/A") -> N/A | DM6: =IFERROR(VLOOKUP($B6,'LOD 400 - COLO2'!$B:CG,84,FALSE),"N/A") -> N/A | DN6: =IFERROR(VLOOKUP($B6,'LOD 400 - COLO2'!$B:CJ,87,FALSE),"N/A") -> N/A | DO6: =IFERROR(VLOOKUP($B6,'LOD 400 - COLO2'!$B:CM,90,FALSE),"N/A") -> N/A | DP6: =IFERROR(VLOOKUP($B6,'LOD 400 - COLO2'!$B:CP,93,FALSE),"N/A") -> N/A | DQ6: =IFERROR(VLOOKUP($B6,'LOD 400 - COLO2'!$B:CS,96,FALSE),"N/A") -> N/A | DR6: =IFERROR(VLOOKUP($B6,'LOD 400 - COLO2'!$B:CV,99,FALSE),"N/A") -> N/A | DS6: =IFERROR(VLOOKUP($B6,'LOD 400 - COLO2'!$B:CY,102,FALSE),"N/A") -> N/A | DT6: =IFERROR(VLOOKUP($B6,'LOD 400 - COLO2'!$B:DB,105,FALSE),"N/A") -> N/A | DU6: =IFERROR(VLOOKUP($B6,'LOD 400 - COLO2'!$B:DE,108,FALSE),"N/A") -> N/A | DV6: =IFERROR(VLOOKUP($B6,'LOD 400 - COLO2'!$B:DH,111,FALSE),"N/A") -> N/A | DW6: =IFERROR(VLOOKUP($B6,'LOD 400 - COLO2'!$B:DK,114,FALSE),"N/A") -> N/A | DX6: =IFERROR(VLOOKUP($B6,'LOD 400 - COLO2'!$B:DN,117,FALSE),"N/A") -> N/A | DY6: =IFERROR(__xludf.DUMMYFUNCTION("IFERROR( MAX(FILTER(CQ6:DW6, ISNUMBER(CQ6:DW6))), DW6 )"),"N/A") -> N/A | DZ6: =IFERROR(VLOOKUP($B6,'LOD 400 - COLO3'!B:S,18,FALSE),"N/A") -> N/A | EA6: =IFERROR(VLOOKUP($B6,'LOD 400 - COLO3'!B:V,21,FALSE),"N/A") -> N/A | EB6: =IFERROR(VLOOKUP($B6,'LOD 400 - COLO3'!B:Y,24,FALSE),"N/A") -> N/A | EC6: =IFERROR(VLOOKUP($B6,'LOD 400 - COLO3'!B:AB,27,FALSE),"N/A") -> N/A | ED6: =IFERROR(VLOOKUP($B6,'LOD 400 - COLO3'!B:AE,30,FALSE),"N/A") -> N/A | EE6: =IFERROR(VLOOKUP($B6,'LOD 400 - COLO3'!B:AH,33,FALSE),"N/A") -> N/A | EF6: =IFERROR(VLOOKUP($B6,'LOD 400 - COLO3'!B:AK,36,FALSE),"N/A") -> N/A | EG6: =IFERROR(VLOOKUP($B6,'LOD 400 - COLO3'!B:AN,39,FALSE),"N/A") -> N/A | EH6: =IFERROR(VLOOKUP($B6,'LOD 400 - COLO3'!B:AQ,42,FALSE),"N/A") -> N/A | EI6: =IFERROR(VLOOKUP($B6,'LOD 400 - COLO3'!B:AT,45,FALSE),"N/A") -> N/A | EJ6: =IFERROR(VLOOKUP($B6,'LOD 400 - COLO3'!B:AW,48,FALSE),"N/A") -> N/A | EK6: =IFERROR(VLOOKUP($B6,'LOD 400 - COLO3'!B:AZ,51,FALSE),"N/A") -> N/A | EL6: =IFERROR(VLOOKUP($B6,'LOD 400 - COLO3'!B:BC,54,FALSE),"N/A") -> N/A | EM6: =IFERROR(VLOOKUP($B6,'LOD 400 - COLO3'!B:BF,57,FALSE),"N/A") -> N/A | EN6: =IFERROR(VLOOKUP($B6,'LOD 400 - COLO3'!B:BI,60,FALSE),"N/A") -> N/A | EO6: =IFERROR(VLOOKUP($B6,'LOD 400 - COLO3'!B:BL,63,FALSE),"N/A") -> N/A | EP6: =IFERROR(__xludf.DUMMYFUNCTION("IFERROR( MAX(FILTER(DZ6:EO6, ISNUMBER(DZ6:EO6))), EO6 )"),"N/A") -> N/A | EQ6: =IFERROR(VLOOKUP($B6,'LOD 400 - COLO4'!B:S,18,FALSE),"N/A") -> N/A | ER6: =IFERROR(__xludf.DUMMYFUNCTION("IFERROR( MAX(FILTER(EQ6, ISNUMBER(EQ6))), EQ6 )"),"N/A") -> N/A | ES6: =IFERROR(VLOOKUP($B6,'LOD 400 - SITE'!B:S,18,FALSE),"N/A") -> OUTDATED | ET6: =IFERROR(VLOOKUP($B6,'LOD 400 - SITE'!B:V,21,FALSE),"N/A") -> OUTDATED | EU6: =IFERROR(VLOOKUP($B6,'LOD 400 - SITE'!$B:Y,24,FALSE),"N/A") -> 0.13 | EV6: =IFERROR(VLOOKUP($B6,'LOD 400 - SITE'!$B:AB,27,FALSE),"N/A") -> IMPROPER | EW6: =IFERROR(VLOOKUP($B6,'LOD 400 - SITE'!$B:AE,30,FALSE),"N/A") -> NEXT ROUND | EX6: =IFERROR(VLOOKUP($B6,'LOD 400 - SITE'!$B:AH,33,FALSE),"N/A") -> 0.31 | EY6: =IFERROR(VLOOKUP($B6,'LOD 400 - SITE'!$B:AK,36,FALSE),"N/A") -> OUTDATED | EZ6: =IFERROR(VLOOKUP($B6,'LOD 400 - SITE'!$B:AN,39,FALSE),"N/A") -> OUTDATED | FA6: =IFERROR(VLOOKUP($B6,'LOD 400 - SITE'!$B:AQ,42,FALSE),"N/A") -> NEXT ROUND | FB6: =IFERROR(VLOOKUP($B6,'LOD 400 - SITE'!$B:AT,45,FALSE),"N/A") -> IMPROPER | FC6: =IFERROR(VLOOKUP($B6,'LOD 400 - SITE'!$B:AW,48,FALSE),"N/A") -> IMPROPER | FD6: =IFERROR(VLOOKUP($B6,'LOD 400 - SITE'!$B:AZ,51,FALSE),"N/A") -> NEXT ROUND | FE6: =IFERROR(VLOOKUP($B6,'LOD 400 - SITE'!$B:BC,54,FALSE),"N/A") -> IMPROPER | FF6: =IFERROR(VLOOKUP($B6,'LOD 400 - SITE'!$B:BF,57,FALSE),"N/A") -> OUTDATED | FG6: =IFERROR(VLOOKUP($B6,'LOD 400 - SITE'!$B:BI,60,FALSE),"N/A") -> NEXT ROUND | FH6: =IFERROR(VLOOKUP($B6,'LOD 400 - SITE'!$B:BL,63,FALSE),"N/A") -> NEXT ROUND | FI6: =IFERROR(VLOOKUP($B6,'LOD 400 - SITE'!$B:BO,66,FALSE),"N/A") -> NEXT ROUND | FJ6: =IFERROR(VLOOKUP($B6,'LOD 400 - SITE'!$B:BR,69,FALSE),"N/A") -> NEXT ROUND | FK6: =IFERROR(VLOOKUP($B6,'LOD 400 - SITE'!$B:BU,72,FALSE),"N/A") -> NEXT ROUND | FL6: =IFERROR(VLOOKUP($B6,'LOD 400 - SITE'!$B:BX,75,FALSE),"N/A") -> 0.34 | FM6: =IFERROR(VLOOKUP($B6,'LOD 400 - SITE'!$B:CA,78,FALSE),"N/A") -> 0.34 | FN6: =IFERROR(VLOOKUP($B6,'LOD 400 - SITE'!$B:CD,81,FALSE),"N/A") -> OUTDATED | FO6: =IFERROR(VLOOKUP($B6,'LOD 400 - SITE'!$B:CG,84,FALSE),"N/A") -> OUTDATED | FP6: =IFERROR(VLOOKUP($B6,'LOD 400 - SITE'!$B:CJ,87,FALSE),"N/A") -> OUTDATED | FQ6: =IFERROR(VLOOKUP($B6,'LOD 400 - SITE'!$B:CM,90,FALSE),"N/A") -> NEXT ROUND | FR6: =IFERROR(VLOOKUP($B6,'LOD 400 - SITE'!$B:CP,93,FALSE),"N/A") -> NEXT ROUND | FS6: =IFERROR(VLOOKUP($B6,'LOD 400 - SITE'!$B:CS,96,FALSE),"N/A") -> 0.98 | FT6: =IFERROR(VLOOKUP($B6,'LOD 400 - SITE'!$B:CV,99,FALSE),"N/A") -> OUTDATED | FU6: =IFERROR(VLOOKUP($B6,'LOD 400 - SITE'!$B:CY,102,FALSE),"N/A") -> OUTDATED | FV6: =IFERROR(VLOOKUP($B6,'LOD 400 - SITE'!$B:DB,105,FALSE),"N/A") -> OUTDATED | FW6: =IFERROR(VLOOKUP($B6,'LOD 400 - SITE'!$B:DE,108,FALSE),"N/A") -> OUTDATED | FX6: =IFERROR(VLOOKUP($B6,'LOD 400 - SITE'!$B:DH,111,FALSE),"N/A") -> OUTDATED | FY6: =IFERROR(VLOOKUP($B6,'LOD 400 - SITE'!$B:DK,114,FALSE),"N/A") -> 1 | FZ6: =IFERROR(__xludf.DUMMYFUNCTION("IFERROR( MAX(FILTER(ES6:FY6, ISNUMBER(ES6:FY6))), FY6 )"),1.0) -> 1 | GA6: =IFERROR(VLOOKUP($B6,'LOD 400 - UTLS'!B:S,18,FALSE),"N/A") -> 0.17 | GB6: =IFERROR(VLOOKUP($B6,'LOD 400 - UTLS'!B:V,21,FALSE),"N/A") -> IMPROPER | GC6: =IFERROR(VLOOKUP($B6,'LOD 400 - UTLS'!B:Y,24,FALSE),"N/A") -> 0.4 | GD6: =IFERROR(VLOOKUP($B6,'LOD 400 - UTLS'!$B:AB,27,FALSE),"N/A") -> OUTDATED | GE6: =IFERROR(VLOOKUP($B6,'LOD 400 - UTLS'!$B:AE,30,FALSE),"N/A") -> OUTDATED | GF6: =IFERROR(VLOOKUP($B6,'LOD 400 - UTLS'!$B:AH,33,FALSE),"N/A") -> NEXT ROUND | GG6: =IFERROR(VLOOKUP($B6,'LOD 400 - UTLS'!$B:AK,36,FALSE),"N/A") -> IMPROPER | GH6: =IFERROR(VLOOKUP($B6,'LOD 400 - UTLS'!$B:AN,39,FALSE),"N/A") -> IMPROPER | GI6: =IFERROR(VLOOKUP($B6,'LOD 400 - UTLS'!$B:AQ,42,FALSE),"N/A") -> NEXT ROUND | GJ6: =IFERROR(VLOOKUP($B6,'LOD 400 - UTLS'!$B:AT,45,FALSE),"N/A") -> IMPROPER | GK6: =IFERROR(VLOOKUP($B6,'LOD 400 - UTLS'!$B:AW,48,FALSE),"N/A") -> OUTDATED | GL6: =IFERROR(VLOOKUP($B6,'LOD 400 - UTLS'!$B:AZ,51,FALSE),"N/A") -> NEXT ROUND | GM6: =IFERROR(VLOOKUP($B6,'LOD 400 - UTLS'!$B:BC,54,FALSE),"N/A") -> NEXT ROUND | GN6: =IFERROR(VLOOKUP($B6,'LOD 400 - UTLS'!$B:BF,57,FALSE),"N/A") -> NEXT ROUND | GO6: =IFERROR(VLOOKUP($B6,'LOD 400 - UTLS'!$B:BI,60,FALSE),"N/A") -> NEXT ROUND | GP6: =IFERROR(VLOOKUP($B6,'LOD 400 - UTLS'!$B:BL,63,FALSE),"N/A") -> NEXT ROUND | GQ6: =IFERROR(VLOOKUP($B6,'LOD 400 - UTLS'!$B:BO,66,FALSE),"N/A") -> NEXT ROUND | GR6: =IFERROR(VLOOKUP($B6,'LOD 400 - UTLS'!$B:BR,69,FALSE),"N/A") -> 0.4 | GS6: =IFERROR(VLOOKUP($B6,'LOD 400 - UTLS'!$B:BU,72,FALSE),"N/A") -> OUTDATED | GT6: =IFERROR(VLOOKUP($B6,'LOD 400 - UTLS'!$B:BX,75,FALSE),"N/A") -> OUTDATED | GU6: =IFERROR(VLOOKUP($B6,'LOD 400 - UTLS'!$B:CA,78,FALSE),"N/A") -> OUTDATED | GV6: =IFERROR(VLOOKUP($B6,'LOD 400 - UTLS'!$B:CD,81,FALSE),"N/A") -> NEXT ROUND | GW6: =IFERROR(VLOOKUP($B6,'LOD 400 - UTLS'!$B:CG,84,FALSE),"N/A") -> NEXT ROUND | GX6: =IFERROR(VLOOKUP($B6,'LOD 400 - UTLS'!$B:CJ,87,FALSE),"N/A") -> 0.43 | GY6: =IFERROR(VLOOKUP($B6,'LOD 400 - UTLS'!$B:CM,90,FALSE),"N/A") -> 1 | GZ6: =IFERROR(VLOOKUP($B6,'LOD 400 - UTLS'!$B:CP,93,FALSE),"N/A") -> 1 | HA6: =IFERROR(VLOOKUP($B6,'LOD 400 - UTLS'!$B:CS,96,FALSE),"N/A") -> 1 | HB6: =IFERROR(VLOOKUP($B6,'LOD 400 - UTLS'!$B:CV,99,FALSE),"N/A") -> 1 | HC6: =IFERROR(VLOOKUP($B6,'LOD 400 - UTLS'!$B:CY,102,FALSE),"N/A") -> 1 | HD6: =IFERROR(VLOOKUP($B6,'LOD 400 - UTLS'!$B:DB,105,FALSE),"N/A") -> 1 | HE6: =IFERROR(__xludf.DUMMYFUNCTION("IFERROR( MAX(FILTER(GA6:HD6, ISNUMBER(GA6:HD6))), HD6 )"),1.0) -> 1
A7: 9 | B7: CPQ11-ARCH-METL-SITE-R24.rvt | C7: CPQ11-ARCH-METL-SITE-R22.rvt | D7: =MID(B7,17,4) -> SITE | E7: SERCOP | F7: SERCOP | G7: ARE ARQUITETURA | I7: =IFERROR(VLOOKUP($C4:C108,'R22 RELATÓRIO ACC'!B:F,5,FALSE),"NOT PUBLISHED") -> V12 | J7: =IFERROR(VLOOKUP($C4:C108,'R22 RELATÓRIO ACC'!B:P,15,FALSE),"NOT PUBLISHED") -> 05/05/2026 | K7: =IFERROR(VLOOKUP($B7:B108,'RELATÓRIO ACC'!B:F,5,FALSE),"NOT PUBLISHED") -> V5 | L7: =IFERROR(VLOOKUP($B7:B108,'RELATÓRIO ACC'!B:P,15,FALSE),"NOT PUBLISHED") -> 22/06/2026 | M7: =IF(OR($D7="UTLS",$D7="GUAR",$D7="STIR",$D7="PUMP",$D7="SITE"), VLOOKUP($B7,'LOD 400 - SITE'!B:M,12,FALSE), VLOOKUP($B7,'LOD 400 - ADMN'!B:M,12,FALSE) ) -> V4 | N7: =IF(OR($D7="UTLS",$D7="GUAR",$D7="STIR",$D7="PUMP",$D7="SITE"), VLOOKUP($B7,'LOD 400 - SITE'!B:N,13,FALSE), VLOOKUP($B7,'LOD 400 - ADMN'!B:N,13,FALSE) ) -> 46185 | O7: =IF(OR($D7="UTLS",$D7="GUAR",$D7="STIR",$D7="PUMP",$D7="SITE"), VLOOKUP($B7,'LOD 400 - SITE'!B:O,14,FALSE), VLOOKUP($B7,'LOD 400 - ADMN'!B:O,14,FALSE) ) -> R24 | P7: =IF(OR($D7="C345",$D7="C12A",$D7="DATA"), VLOOKUP($B7,'LOD 400 - COLO3'!B:M,12,FALSE),"N/A") -> N/A | Q7: =IF(OR($D7="C345",$D7="C12A",$D7="DATA"), VLOOKUP($B7,'LOD 400 - COLO3'!B:N,13,FALSE),"N/A") -> N/A | R7: =IF(OR($D7="C345",$D7="C12A",$D7="DATA"), VLOOKUP($B7,'LOD 400 - COLO3'!B:O,14,FALSE),"N/A") -> N/A | S7: =IF(OR($D7="C345",$D7="C12A",$D7="DATA"), VLOOKUP($B7,'LOD 400 - COLO4'!B:N,12,FALSE),"N/A") -> N/A | T7: =IF(OR($D7="C345",$D7="C12A",$D7="DATA"), VLOOKUP($B7,'LOD 400 - COLO4'!B:N,13,FALSE),"N/A") -> N/A | U7: =IF(OR($D7="C345",$D7="C12A",$D7="DATA"), VLOOKUP($B7,'LOD 400 - COLO4'!B:N,13,FALSE),"N/A") -> N/A | V7: =IF(OR($D7="UTLS",$D7="GUAR",$D7="STIR",$D7="PUMP",$D7="SITE"), VLOOKUP($B7,'LOD 400 - UTLS'!B:M,12,FALSE),"N/A") -> V5 | W7: =IF(OR($D7="UTLS",$D7="GUAR",$D7="STIR",$D7="PUMP",$D7="SITE"), VLOOKUP($B7,'LOD 400 - UTLS'!B:N,13,FALSE),"N/A") -> 46195 | X7: =IF(OR($D7="UTLS",$D7="GUAR",$D7="STIR",$D7="PUMP",$D7="SITE"), VLOOKUP($B7,'LOD 400 - UTLS'!B:O,14,FALSE),"N/A") -> R24 | Y7: =IFERROR(VLOOKUP($B7,'LOD 400 - ADMN'!B:S,18,FALSE),"N/A") -> N/A | Z7: =IFERROR(VLOOKUP($B7,'LOD 400 - ADMN'!B:V,21,FALSE),"N/A") -> N/A | AA7: =IFERROR(VLOOKUP($B7,'LOD 400 - ADMN'!$B:Y,24,FALSE),"N/A") -> N/A | AB7: =IFERROR(VLOOKUP($B7,'LOD 400 - ADMN'!$B:AB,27,FALSE),"N/A") -> N/A | AC7: =IFERROR(VLOOKUP($B7,'LOD 400 - ADMN'!$B:AE,30,FALSE),"N/A") -> N/A | AD7: =IFERROR(VLOOKUP($B7,'LOD 400 - ADMN'!$B:AH,33,FALSE),"N/A") -> N/A | AE7: =IFERROR(VLOOKUP($B7,'LOD 400 - ADMN'!$B:AK,36,FALSE),"N/A") -> N/A | AF7: =IFERROR(VLOOKUP($B7,'LOD 400 - ADMN'!$B:AN,39,FALSE),"N/A") -> N/A | AG7: =IFERROR(VLOOKUP($B7,'LOD 400 - ADMN'!$B:AQ,42,FALSE),"N/A") -> N/A | AH7: =IFERROR(VLOOKUP($B7,'LOD 400 - ADMN'!$B:AT,45,FALSE),"N/A") -> N/A | AI7: =IFERROR(VLOOKUP($B7,'LOD 400 - ADMN'!$B:AW,48,FALSE),"N/A") -> N/A | AJ7: =IFERROR(VLOOKUP($B7,'LOD 400 - ADMN'!$B:AZ,51,FALSE),"N/A") -> N/A | AK7: =IFERROR(VLOOKUP($B7,'LOD 400 - ADMN'!$B:BC,54,FALSE),"N/A") -> N/A | AL7: =IFERROR(VLOOKUP($B7,'LOD 400 - ADMN'!$B:BF,57,FALSE),"N/A") -> N/A | AM7: =IFERROR(VLOOKUP($B7,'LOD 400 - ADMN'!$B:BI,60,FALSE),"N/A") -> N/A | AN7: =IFERROR(VLOOKUP($B7,'LOD 400 - ADMN'!$B:BL,63,FALSE),"N/A") -> N/A | AO7: =IFERROR(VLOOKUP($B7,'LOD 400 - ADMN'!$B:BO,66,FALSE),"N/A") -> N/A | AP7: =IFERROR(VLOOKUP($B7,'LOD 400 - ADMN'!$B:BR,69,FALSE),"N/A") -> N/A | AQ7: =IFERROR(VLOOKUP($B7,'LOD 400 - ADMN'!$B:BU,72,FALSE),"N/A") -> N/A | AR7: =IFERROR(VLOOKUP($B7,'LOD 400 - ADMN'!$B:BX,75,FALSE),"N/A") -> N/A | AS7: =IFERROR(VLOOKUP($B7,'LOD 400 - ADMN'!$B:CA,78,FALSE),"N/A") -> N/A | AT7: =IFERROR(VLOOKUP($B7,'LOD 400 - ADMN'!$B:CD,81,FALSE),"N/A") -> N/A | AU7: =IFERROR(VLOOKUP($B7,'LOD 400 - ADMN'!$B:CG,84,FALSE),"N/A") -> N/A | AV7: =IFERROR(VLOOKUP($B7,'LOD 400 - ADMN'!$B:CJ,87,FALSE),"N/A") -> N/A | AW7: =IFERROR(VLOOKUP($B7,'LOD 400 - ADMN'!$B:CM,90,FALSE),"N/A") -> N/A | AX7: =IFERROR(VLOOKUP($B7,'LOD 400 - ADMN'!$B:CP,93,FALSE),"N/A") -> N/A | AY7: =IFERROR(VLOOKUP($B7,'LOD 400 - ADMN'!$B:CS,96,FALSE),"N/A") -> N/A | AZ7: =IFERROR(VLOOKUP($B7,'LOD 400 - ADMN'!$B:CV,99,FALSE),"N/A") -> N/A | BA7: =IFERROR(VLOOKUP($B7,'LOD 400 - ADMN'!$B:CY,102,FALSE),"N/A") -> N/A | BB7: =IFERROR(VLOOKUP($B7,'LOD 400 - ADMN'!$B:DB,105,FALSE),"N/A") -> N/A | BC7: =IFERROR(VLOOKUP($B7,'LOD 400 - ADMN'!$B:DE,108,FALSE),"N/A") -> N/A | BD7: =IFERROR(VLOOKUP($B7,'LOD 400 - ADMN'!$B:DH,111,FALSE),"N/A") -> N/A | BE7: =IFERROR(VLOOKUP($B7,'LOD 400 - ADMN'!$B:DK,114,FALSE),"N/A") -> N/A | BF7: =IFERROR(VLOOKUP($B7,'LOD 400 - ADMN'!$B:DN,117,FALSE),"N/A") -> N/A | BG7: =IFERROR(__xludf.DUMMYFUNCTION("IFERROR( MAX(FILTER(Y7:BF7, ISNUMBER(Y7:BF7))), BF7 )"),"N/A") -> N/A | BH7: =IFERROR(VLOOKUP($B7,'LOD 400 - COLO1'!B:S,18,FALSE),"N/A") -> N/A | BI7: =IFERROR(VLOOKUP($B7,'LOD 400 - COLO1'!B:V,21,FALSE),"N/A") -> N/A | BJ7: =IFERROR(VLOOKUP($B7,'LOD 400 - COLO1'!$B:Y,24,FALSE),"N/A") -> N/A | BK7: =IFERROR(VLOOKUP($B7,'LOD 400 - COLO1'!$B:AB,27,FALSE),"N/A") -> N/A | BL7: =IFERROR(VLOOKUP($B7,'LOD 400 - COLO1'!$B:AE,30,FALSE),"N/A") -> N/A | BM7: =IFERROR(VLOOKUP($B7,'LOD 400 - COLO1'!$B:AH,33,FALSE),"N/A") -> N/A | BN7: =IFERROR(VLOOKUP($B7,'LOD 400 - COLO1'!$B:AK,36,FALSE),"N/A") -> N/A | BO7: =IFERROR(VLOOKUP($B7,'LOD 400 - COLO1'!$B:AN,39,FALSE),"N/A") -> N/A | BP7: =IFERROR(VLOOKUP($B7,'LOD 400 - COLO1'!$B:AQ,42,FALSE),"N/A") -> N/A | BQ7: =IFERROR(VLOOKUP($B7,'LOD 400 - COLO1'!$B:AT,45,FALSE),"N/A") -> N/A | BR7: =IFERROR(VLOOKUP($B7,'LOD 400 - COLO1'!$B:AW,48,FALSE),"N/A") -> N/A | BS7: =IFERROR(VLOOKUP($B7,'LOD 400 - COLO1'!$B:AZ,51,FALSE),"N/A") -> N/A | BT7: =IFERROR(VLOOKUP($B7,'LOD 400 - COLO1'!$B:BC,54,FALSE),"N/A") -> N/A | BU7: =IFERROR(VLOOKUP($B7,'LOD 400 - COLO1'!$B:BF,57,FALSE),"N/A") -> N/A | BV7: =IFERROR(VLOOKUP($B7,'LOD 400 - COLO1'!$B:BI,60,FALSE),"N/A") -> N/A | BW7: =IFERROR(VLOOKUP($B7,'LOD 400 - COLO1'!$B:BL,63,FALSE),"N/A") -> N/A | BX7: =IFERROR(VLOOKUP($B7,'LOD 400 - COLO1'!$B:BO,66,FALSE),"N/A") -> N/A | BY7: =IFERROR(VLOOKUP($B7,'LOD 400 - COLO1'!$B:BR,69,FALSE),"N/A") -> N/A | BZ7: =IFERROR(VLOOKUP($B7,'LOD 400 - COLO1'!$B:BU,72,FALSE),"N/A") -> N/A | CA7: =IFERROR(VLOOKUP($B7,'LOD 400 - COLO1'!$B:BX,75,FALSE),"N/A") -> N/A | CB7: =IFERROR(VLOOKUP($B7,'LOD 400 - COLO1'!$B:CA,78,FALSE),"N/A") -> N/A | CC7: =IFERROR(VLOOKUP($B7,'LOD 400 - COLO1'!$B:CD,81,FALSE),"N/A") -> N/A | CD7: =IFERROR(VLOOKUP($B7,'LOD 400 - COLO1'!$B:CG,84,FALSE),"N/A") -> N/A | CE7: =IFERROR(VLOOKUP($B7,'LOD 400 - COLO1'!$B:CJ,87,FALSE),"N/A") -> N/A | CF7: =IFERROR(VLOOKUP($B7,'LOD 400 - COLO1'!$B:CM,90,FALSE),"N/A") -> N/A | CG7: =IFERROR(VLOOKUP($B7,'LOD 400 - COLO1'!$B:CP,93,FALSE),"N/A") -> N/A | CH7: =IFERROR(VLOOKUP($B7,'LOD 400 - COLO1'!$B:CS,96,FALSE),"N/A") -> N/A | CI7: =IFERROR(VLOOKUP($B7,'LOD 400 - COLO1'!$B:CV,99,FALSE),"N/A") -> N/A | CJ7: =IFERROR(VLOOKUP($B7,'LOD 400 - COLO1'!$B:CY,102,FALSE),"N/A") -> N/A | CK7: =IFERROR(VLOOKUP($B7,'LOD 400 - COLO1'!$B:DB,105,FALSE),"N/A") -> N/A | CL7: =IFERROR(VLOOKUP($B7,'LOD 400 - COLO1'!$B:DE,108,FALSE),"N/A") -> N/A | CM7: =IFERROR(VLOOKUP($B7,'LOD 400 - COLO1'!$B:DH,111,FALSE),"N/A") -> N/A | CN7: =IFERROR(VLOOKUP($B7,'LOD 400 - COLO1'!$B:DK,114,FALSE),"N/A") -> N/A | CO7: =IFERROR(VLOOKUP($B7,'LOD 400 - COLO1'!$B:DN,117,FALSE),"N/A") -> N/A | CP7: =IFERROR(__xludf.DUMMYFUNCTION("IFERROR( MAX(FILTER(BH7:CO7, ISNUMBER(BH7:CO7))), CO7 )"),"N/A") -> N/A | CQ7: =IFERROR(VLOOKUP($B7,'LOD 400 - COLO2'!B:S,18,FALSE),"N/A") -> N/A | CR7: =IFERROR(VLOOKUP($B7,'LOD 400 - COLO2'!B:V,21,FALSE),"N/A") -> N/A | CS7: =IFERROR(VLOOKUP($B7,'LOD 400 - COLO2'!$B:Y,24,FALSE),"N/A") -> N/A | CT7: =IFERROR(VLOOKUP($B7,'LOD 400 - COLO2'!$B:DQ,27,FALSE),"N/A") -> N/A | CU7: =IFERROR(VLOOKUP($B7,'LOD 400 - COLO2'!$B:AE,30,FALSE),"N/A") -> N/A | CV7: =IFERROR(VLOOKUP($B7,'LOD 400 - COLO2'!$B:AH,33,FALSE),"N/A") -> N/A | CW7: =IFERROR(VLOOKUP($B7,'LOD 400 - COLO2'!$B:AK,36,FALSE),"N/A") -> N/A | CX7: =IFERROR(VLOOKUP($B7,'LOD 400 - COLO2'!$B:AN,39,FALSE),"N/A") -> N/A | CY7: =IFERROR(VLOOKUP($B7,'LOD 400 - COLO2'!$B:AQ,42,FALSE),"N/A") -> N/A | CZ7: =IFERROR(VLOOKUP($B7,'LOD 400 - COLO2'!$B:AT,45,FALSE),"N/A") -> N/A | DA7: =IFERROR(VLOOKUP($B7,'LOD 400 - COLO2'!$B:AW,48,FALSE),"N/A") -> N/A | DB7: =IFERROR(VLOOKUP($B7,'LOD 400 - COLO2'!$B:AZ,51,FALSE),"N/A") -> N/A | DC7: =IFERROR(VLOOKUP($B7,'LOD 400 - COLO2'!$B:BC,54,FALSE),"N/A") -> N/A | DD7: =IFERROR(VLOOKUP($B7,'LOD 400 - COLO2'!$B:BF,57,FALSE),"N/A") -> N/A | DE7: =IFERROR(VLOOKUP($B7,'LOD 400 - COLO2'!$B:BI,60,FALSE),"N/A") -> N/A | DF7: =IFERROR(VLOOKUP($B7,'LOD 400 - COLO2'!$B:BL,63,FALSE),"N/A") -> N/A | DG7: =IFERROR(VLOOKUP($B7,'LOD 400 - COLO2'!$B:BO,66,FALSE),"N/A") -> N/A | DH7: =IFERROR(VLOOKUP($B7,'LOD 400 - COLO2'!$B:BR,69,FALSE),"N/A") -> N/A | DI7: =IFERROR(VLOOKUP($B7,'LOD 400 - COLO2'!$B:BU,72,FALSE),"N/A") -> N/A | DJ7: =IFERROR(VLOOKUP($B7,'LOD 400 - COLO2'!$B:BX,75,FALSE),"N/A") -> N/A | DK7: =IFERROR(VLOOKUP($B7,'LOD 400 - COLO2'!$B:CA,78,FALSE),"N/A") -> N/A | DL7: =IFERROR(VLOOKUP($B7,'LOD 400 - COLO2'!$B:CD,81,FALSE),"N/A") -> N/A | DM7: =IFERROR(VLOOKUP($B7,'LOD 400 - COLO2'!$B:CG,84,FALSE),"N/A") -> N/A | DN7: =IFERROR(VLOOKUP($B7,'LOD 400 - COLO2'!$B:CJ,87,FALSE),"N/A") -> N/A | DO7: =IFERROR(VLOOKUP($B7,'LOD 400 - COLO2'!$B:CM,90,FALSE),"N/A") -> N/A | DP7: =IFERROR(VLOOKUP($B7,'LOD 400 - COLO2'!$B:CP,93,FALSE),"N/A") -> N/A | DQ7: =IFERROR(VLOOKUP($B7,'LOD 400 - COLO2'!$B:CS,96,FALSE),"N/A") -> N/A | DR7: =IFERROR(VLOOKUP($B7,'LOD 400 - COLO2'!$B:CV,99,FALSE),"N/A") -> N/A | DS7: =IFERROR(VLOOKUP($B7,'LOD 400 - COLO2'!$B:CY,102,FALSE),"N/A") -> N/A | DT7: =IFERROR(VLOOKUP($B7,'LOD 400 - COLO2'!$B:DB,105,FALSE),"N/A") -> N/A | DU7: =IFERROR(VLOOKUP($B7,'LOD 400 - COLO2'!$B:DE,108,FALSE),"N/A") -> N/A | DV7: =IFERROR(VLOOKUP($B7,'LOD 400 - COLO2'!$B:DH,111,FALSE),"N/A") -> N/A | DW7: =IFERROR(VLOOKUP($B7,'LOD 400 - COLO2'!$B:DK,114,FALSE),"N/A") -> N/A | DX7: =IFERROR(VLOOKUP($B7,'LOD 400 - COLO2'!$B:DN,117,FALSE),"N/A") -> N/A | DY7: =IFERROR(__xludf.DUMMYFUNCTION("IFERROR( MAX(FILTER(CQ7:DW7, ISNUMBER(CQ7:DW7))), DW7 )"),"N/A") -> N/A | DZ7: =IFERROR(VLOOKUP($B7,'LOD 400 - COLO3'!B:S,18,FALSE),"N/A") -> N/A | EA7: =IFERROR(VLOOKUP($B7,'LOD 400 - COLO3'!B:V,21,FALSE),"N/A") -> N/A | EB7: =IFERROR(VLOOKUP($B7,'LOD 400 - COLO3'!B:Y,24,FALSE),"N/A") -> N/A | EC7: =IFERROR(VLOOKUP($B7,'LOD 400 - COLO3'!B:AB,27,FALSE),"N/A") -> N/A | ED7: =IFERROR(VLOOKUP($B7,'LOD 400 - COLO3'!B:AE,30,FALSE),"N/A") -> N/A | EE7: =IFERROR(VLOOKUP($B7,'LOD 400 - COLO3'!B:AH,33,FALSE),"N/A") -> N/A | EF7: =IFERROR(VLOOKUP($B7,'LOD 400 - COLO3'!B:AK,36,FALSE),"N/A") -> N/A | EG7: =IFERROR(VLOOKUP($B7,'LOD 400 - COLO3'!B:AN,39,FALSE),"N/A") -> N/A | EH7: =IFERROR(VLOOKUP($B7,'LOD 400 - COLO3'!B:AQ,42,FALSE),"N/A") -> N/A | EI7: =IFERROR(VLOOKUP($B7,'LOD 400 - COLO3'!B:AT,45,FALSE),"N/A") -> N/A | EJ7: =IFERROR(VLOOKUP($B7,'LOD 400 - COLO3'!B:AW,48,FALSE),"N/A") -> N/A | EK7: =IFERROR(VLOOKUP($B7,'LOD 400 - COLO3'!B:AZ,51,FALSE),"N/A") -> N/A | EL7: =IFERROR(VLOOKUP($B7,'LOD 400 - COLO3'!B:BC,54,FALSE),"N/A") -> N/A | EM7: =IFERROR(VLOOKUP($B7,'LOD 400 - COLO3'!B:BF,57,FALSE),"N/A") -> N/A | EN7: =IFERROR(VLOOKUP($B7,'LOD 400 - COLO3'!B:BI,60,FALSE),"N/A") -> N/A | EO7: =IFERROR(VLOOKUP($B7,'LOD 400 - COLO3'!B:BL,63,FALSE),"N/A") -> N/A | EP7: =IFERROR(__xludf.DUMMYFUNCTION("IFERROR( MAX(FILTER(DZ7:EO7, ISNUMBER(DZ7:EO7))), EO7 )"),"N/A") -> N/A | EQ7: =IFERROR(VLOOKUP($B7,'LOD 400 - COLO4'!B:S,18,FALSE),"N/A") -> N/A | ER7: =IFERROR(__xludf.DUMMYFUNCTION("IFERROR( MAX(FILTER(EQ7, ISNUMBER(EQ7))), EQ7 )"),"N/A") -> N/A | ES7: =IFERROR(VLOOKUP($B7,'LOD 400 - SITE'!B:S,18,FALSE),"N/A") -> NOT PUBLISHED | ET7: =IFERROR(VLOOKUP($B7,'LOD 400 - SITE'!B:V,21,FALSE),"N/A") -> 0.05 | EU7: =IFERROR(VLOOKUP($B7,'LOD 400 - SITE'!$B:Y,24,FALSE),"N/A") -> OUTDATED | EV7: =IFERROR(VLOOKUP($B7,'LOD 400 - SITE'!$B:AB,27,FALSE),"N/A") -> IMPROPER | EW7: =IFERROR(VLOOKUP($B7,'LOD 400 - SITE'!$B:AE,30,FALSE),"N/A") -> 0.13 | EX7: =IFERROR(VLOOKUP($B7,'LOD 400 - SITE'!$B:AH,33,FALSE),"N/A") -> 0.46 | EY7: =IFERROR(VLOOKUP($B7,'LOD 400 - SITE'!$B:AK,36,FALSE),"N/A") -> IMPROPER | EZ7: =IFERROR(VLOOKUP($B7,'LOD 400 - SITE'!$B:AN,39,FALSE),"N/A") -> OUTDATED | FA7: =IFERROR(VLOOKUP($B7,'LOD 400 - SITE'!$B:AQ,42,FALSE),"N/A") -> IMPROPER | FB7: =IFERROR(VLOOKUP($B7,'LOD 400 - SITE'!$B:AT,45,FALSE),"N/A") -> IMPROPER | FC7: =IFERROR(VLOOKUP($B7,'LOD 400 - SITE'!$B:AW,48,FALSE),"N/A") -> OUTDATED | FD7: =IFERROR(VLOOKUP($B7,'LOD 400 - SITE'!$B:AZ,51,FALSE),"N/A") -> OUTDATED | FE7: =IFERROR(VLOOKUP($B7,'LOD 400 - SITE'!$B:BC,54,FALSE),"N/A") -> IMPROPER | FF7: =IFERROR(VLOOKUP($B7,'LOD 400 - SITE'!$B:BF,57,FALSE),"N/A") -> OUTDATED | FG7: =IFERROR(VLOOKUP($B7,'LOD 400 - SITE'!$B:BI,60,FALSE),"N/A") -> OUTDATED | FH7: =IFERROR(VLOOKUP($B7,'LOD 400 - SITE'!$B:BL,63,FALSE),"N/A") -> OUTDATED | FI7: =IFERROR(VLOOKUP($B7,'LOD 400 - SITE'!$B:BO,66,FALSE),"N/A") -> OUTDATED | FJ7: =IFERROR(VLOOKUP($B7,'LOD 400 - SITE'!$B:BR,69,FALSE),"N/A") -> 0.56 | FK7: =IFERROR(VLOOKUP($B7,'LOD 400 - SITE'!$B:BU,72,FALSE),"N/A") -> NEXT ROUND | FL7: =IFERROR(VLOOKUP($B7,'LOD 400 - SITE'!$B:BX,75,FALSE),"N/A") -> 0.64 | FM7: =IFERROR(VLOOKUP($B7,'LOD 400 - SITE'!$B:CA,78,FALSE),"N/A") -> 0.85 | FN7: =IFERROR(VLOOKUP($B7,'LOD 400 - SITE'!$B:CD,81,FALSE),"N/A") -> OUTDATED | FO7: =IFERROR(VLOOKUP($B7,'LOD 400 - SITE'!$B:CG,84,FALSE),"N/A") -> NEXT ROUND | FP7: =IFERROR(VLOOKUP($B7,'LOD 400 - SITE'!$B:CJ,87,FALSE),"N/A") -> NEXT ROUND | FQ7: =IFERROR(VLOOKUP($B7,'LOD 400 - SITE'!$B:CM,90,FALSE),"N/A") -> 0.69 | FR7: =IFERROR(VLOOKUP($B7,'LOD 400 - SITE'!$B:CP,93,FALSE),"N/A") -> NEXT ROUND | FS7: =IFERROR(VLOOKUP($B7,'LOD 400 - SITE'!$B:CS,96,FALSE),"N/A") -> 0.69 | FT7: =IFERROR(VLOOKUP($B7,'LOD 400 - SITE'!$B:CV,99,FALSE),"N/A") -> NEXT ROUND | FU7: =IFERROR(VLOOKUP($B7,'LOD 400 - SITE'!$B:CY,102,FALSE),"N/A") -> NEXT ROUND | FV7: =IFERROR(VLOOKUP($B7,'LOD 400 - SITE'!$B:DB,105,FALSE),"N/A") -> 1 | FW7: =IFERROR(VLOOKUP($B7,'LOD 400 - SITE'!$B:DE,108,FALSE),"N/A") -> 1 | FX7: =IFERROR(VLOOKUP($B7,'LOD 400 - SITE'!$B:DH,111,FALSE),"N/A") -> 1 | FY7: =IFERROR(VLOOKUP($B7,'LOD 400 - SITE'!$B:DK,114,FALSE),"N/A") -> 1 | FZ7: =IFERROR(__xludf.DUMMYFUNCTION("IFERROR( MAX(FILTER(ES7:FY7, ISNUMBER(ES7:FY7))), FY7 )"),1.0) -> 1 | GA7: =IFERROR(VLOOKUP($B7,'LOD 400 - UTLS'!B:S,18,FALSE),"N/A") -> 0.08 | GB7: =IFERROR(VLOOKUP($B7,'LOD 400 - UTLS'!B:V,21,FALSE),"N/A") -> IMPROPER | GC7: =IFERROR(VLOOKUP($B7,'LOD 400 - UTLS'!B:Y,24,FALSE),"N/A") -> 0.19 | GD7: =IFERROR(VLOOKUP($B7,'LOD 400 - UTLS'!$B:AB,27,FALSE),"N/A") -> IMPROPER | GE7: =IFERROR(VLOOKUP($B7,'LOD 400 - UTLS'!$B:AE,30,FALSE),"N/A") -> OUTDATED | GF7: =IFERROR(VLOOKUP($B7,'LOD 400 - UTLS'!$B:AH,33,FALSE),"N/A") -> IMPROPER | GG7: =IFERROR(VLOOKUP($B7,'LOD 400 - UTLS'!$B:AK,36,FALSE),"N/A") -> IMPROPER | GH7: =IFERROR(VLOOKUP($B7,'LOD 400 - UTLS'!$B:AN,39,FALSE),"N/A") -> IMPROPER | GI7: =IFERROR(VLOOKUP($B7,'LOD 400 - UTLS'!$B:AQ,42,FALSE),"N/A") -> OUTDATED | GJ7: =IFERROR(VLOOKUP($B7,'LOD 400 - UTLS'!$B:AT,45,FALSE),"N/A") -> IMPROPER | GK7: =IFERROR(VLOOKUP($B7,'LOD 400 - UTLS'!$B:AW,48,FALSE),"N/A") -> OUTDATED | GL7: =IFERROR(VLOOKUP($B7,'LOD 400 - UTLS'!$B:AZ,51,FALSE),"N/A") -> OUTDATED | GM7: =IFERROR(VLOOKUP($B7,'LOD 400 - UTLS'!$B:BC,54,FALSE),"N/A") -> OUTDATED | GN7: =IFERROR(VLOOKUP($B7,'LOD 400 - UTLS'!$B:BF,57,FALSE),"N/A") -> OUTDATED | GO7: =IFERROR(VLOOKUP($B7,'LOD 400 - UTLS'!$B:BI,60,FALSE),"N/A") -> 0.56 | GP7: =IFERROR(VLOOKUP($B7,'LOD 400 - UTLS'!$B:BL,63,FALSE),"N/A") -> NEXT ROUND | GQ7: =IFERROR(VLOOKUP($B7,'LOD 400 - UTLS'!$B:BO,66,FALSE),"N/A") -> 0.69 | GR7: =IFERROR(VLOOKUP($B7,'LOD 400 - UTLS'!$B:BR,69,FALSE),"N/A") -> 0.72 | GS7: =IFERROR(VLOOKUP($B7,'LOD 400 - UTLS'!$B:BU,72,FALSE),"N/A") -> OUTDATED | GT7: =IFERROR(VLOOKUP($B7,'LOD 400 - UTLS'!$B:BX,75,FALSE),"N/A") -> NEXT ROUND | GU7: =IFERROR(VLOOKUP($B7,'LOD 400 - UTLS'!$B:CA,78,FALSE),"N/A") -> NEXT ROUND | GV7: =IFERROR(VLOOKUP($B7,'LOD 400 - UTLS'!$B:CD,81,FALSE),"N/A") -> NEXT ROUND | GW7: =IFERROR(VLOOKUP($B7,'LOD 400 - UTLS'!$B:CG,84,FALSE),"N/A") -> NEXT ROUND | GX7: =IFERROR(VLOOKUP($B7,'LOD 400 - UTLS'!$B:CJ,87,FALSE),"N/A") -> 0.85 | GY7: =IFERROR(VLOOKUP($B7,'LOD 400 - UTLS'!$B:CM,90,FALSE),"N/A") -> 0.85 | GZ7: =IFERROR(VLOOKUP($B7,'LOD 400 - UTLS'!$B:CP,93,FALSE),"N/A") -> NEXT ROUND | HA7: =IFERROR(VLOOKUP($B7,'LOD 400 - UTLS'!$B:CS,96,FALSE),"N/A") -> IMPROPER | HB7: =IFERROR(VLOOKUP($B7,'LOD 400 - UTLS'!$B:CV,99,FALSE),"N/A") -> OUTDATED | HC7: =IFERROR(VLOOKUP($B7,'LOD 400 - UTLS'!$B:CY,102,FALSE),"N/A") -> OUTDATED | HD7: =IFERROR(VLOOKUP($B7,'LOD 400 - UTLS'!$B:DB,105,FALSE),"N/A") -> OUTDATED | HE7: =IFERROR(__xludf.DUMMYFUNCTION("IFERROR( MAX(FILTER(GA7:HD7, ISNUMBER(GA7:HD7))), HD7 )"),0.85) -> 0.85
